Workbook

Sheet 通报
A1: =N6&"日10086投诉一级督办单占比通报" -> 19日10086投诉一级督办单占比通报 | S1: 每日新增 | X1: 无重复投诉（重点客户、网课） | AC1: 7天内重复投诉 | AH1: 大于7天小于30天
A2: 序号 | B2: 区县 | C2: =TEXT(NOW()-1,"dd")&"日新增" -> 19日新增 | J2: 累计一级督办单 | K2: 累计一级督办单占比 | L2: 区县 | S2: =_xlfn.TEXTJOIN(",",1,V3:V14) | V2: 前3 | X2: =_xlfn.TEXTJOIN(",",1,AA3:AA14) | AA2: 前3 | AC2: =_xlfn.TEXTJOIN(",",1,AF3:AF14) | AF2: 前3 | AH2: =_xlfn.TEXTJOIN(",",1,AK3:AK14) | AK2: 前3
C3: 重复投诉时间段 | H3: 一级督办单新增 | I3: 一级督办单占比新增 | V3: =VLOOKUP(1,$S$6:$T$17,2,0) | W3: 1 | AA3: =VLOOKUP(1,$X$6:$Y$17,2,0) | AB3: 1 | AF3: =VLOOKUP(1,$AC$6:$AD$17,2,0) | AG3: 1 | AK3: =VLOOKUP(1,$AH$6:$AI$17,2,0) | AL3: 1
C4: 无重复投诉（网课、重点客户） | D4: 7天内重复投诉 | E4: 7-30天以内重复投诉 | F4: 30-60天以内重复投诉 | G4: 60-90天以内重复投诉 | V4: =VLOOKUP(2,$S$6:$T$17,2,0) | W4: 2 | AA4: =VLOOKUP(2,$X$6:$Y$17,2,0) | AB4: 2 | AF4: =VLOOKUP(2,$AC$6:$AD$17,2,0) | AG4: 2 | AK4: =VLOOKUP(2,$AH$6:$AI$17,2,0) | AL4: 2
O5: 对比列 | P5: =VLOOKUP(1,O6:P17,2,0)&","&VLOOKUP(2,O6:P17,2,0)&","&VLOOKUP(3,O6:P17,2,0) -> 坊子(9.86%),潍城(9.34%),安丘(8.95%) | Q5: 对比列 | R5: =VLOOKUP(1,Q6:R17,2,0)&","&VLOOKUP(2,Q6:R17,2,0)&","&VLOOKUP(3,Q6:R17,2,0) -> #N/A | V5: =VLOOKUP(3,$S$6:$T$17,2,0) | W5: 3 | AA5: =VLOOKUP(3,$X$6:$Y$17,2,0) | AB5: 3 | AF5: =VLOOKUP(3,$AC$6:$AD$17,2,0) | AG5: 3 | AK5: =VLOOKUP(3,$AH$6:$AI$17,2,0) | AL5: 3
A6: 1 | B6: 坊子 | C6: =COUNTIFS(督办单!L:L,B:B,督办单!M:M,$M$6,督办单!P:P,"无",督办单!C:C,"*一级*") -> 0 | D6: =COUNTIFS(督办单!L:L,B:B,督办单!M:M,$M$6,督办单!P:P,"7天内",督办单!C:C,"*一级*") -> 0 | E6: =COUNTIFS(督办单!L:L,B:B,督办单!M:M,$M$6,督办单!P:P,"30天内",督办单!C:C,"*一级*") -> 0 | F6: =COUNTIFS(督办单!L:L,B:B,督办单!M:M,$M$6,督办单!P:P,"60天内",督办单!C:C,"*一级*") -> 0 | G6: =COUNTIFS(督办单!L:L,B:B,督办单!M:M,$M$6,督办单!P:P,"90天内",督办单!C:C,"*一级*") -> 0 | H6: =COUNTIFS(督办单!L:L,B:B,督办单!C:C,"*一级*",督办单!M:M,$M$6) -> 0 | I6: =COUNTIFS(督办单!L:L,B:B,督办单!C:C,"*一级*",督办单!M:M,$M$6)/(COUNTIFS(累计派单!R:R,B:B,累计派单!S:S,$M$6)-COUNTIFS(累计派单!R:R,B:B,累计派单!I:I,"*业务受理*",累计派单!S:S,$M$6)) -> #DIV/0! | J6: =COUNTIFS(督办单!L:L,B:B,督办单!C:C,"*一级*") -> 35 | K6: =J6/(COUNTIFS(累计派单!R:R,B:B)-COUNTIFS(累计派单!R:R,B:B,累计派单!I:I,"*业务受理*")-COUNTIFS(累计派单!I:I,"*客户咨询*")) -> 0.098591549 | L6: 坊子 | M6: =TEXT(TODAY()-1,"mmdd") -> 0119 | N6: =TEXT(NOW()-1,"dd") -> 19 | O6: =_xlfn.RANK.EQ(K6,$K$6:$K$17,0)+COUNTIF($K$6:$K6,K6)-1 -> 1 | P6: =B6&"("&ROUND(K6*100,2)&"%)" -> 坊子(9.86%) | Q6: =_xlfn.RANK.EQ(I6,$I$6:$I$17,0)+COUNTIF($I$6:$I6,I6)-1 -> #DIV/0! | R6: =B6&"("&ROUND(I6*100,2)&"%)" -> #DIV/0! | S6: =_xlfn.RANK.EQ(H6,$H$6:$H$17,0)+COUNTIF($H$6:$H6,H6)-1 -> 1 | T6: =IF(H6=0,"",B6&H6&"件") | U6: =H6 -> 0 | V6: =IF(V5="","",IF(VLOOKUP(W5,$S$6:$U$17,3,0)=VLOOKUP(W6,$S$6:$U$17,3,0),VLOOKUP(W6,$S$6:$U$17,2,0),"")) | W6: 4 | X6: =_xlfn.RANK.EQ(C6,$C$6:$C$17,0)+COUNTIF($C$6:$C6,C6)-1 -> 1 | Y6: =IF(Z6=0,"",B6&C6&"件") | Z6: =C6 -> 0 | AA6: =IF(AA5="","",IF(VLOOKUP(AB5,$AC$6:$AE$17,3,0)=VLOOKUP(AB6,$AC$6:$AE$17,3,0),VLOOKUP(AB6,$AC$6:$AE$17,2,0),"")) | AB6: 4 | AC6: =_xlfn.RANK.EQ(D6,$D$6:$D$17,0)+COUNTIF($D$6:$D6,D6)-1 -> 1 | AD6: =IF(AE6=0,"",B6&D6&"件") | AE6: =D6 -> 0 | AF6: =IF(AF5="","",IF(VLOOKUP(AG5,$AC$6:$AE$17,3,0)=VLOOKUP(AG6,$AC$6:$AE$17,3,0),VLOOKUP(AG6,$AC$6:$AE$17,2,0),"")) | AG6: 4 | AH6: =_xlfn.RANK.EQ(E6,$E$6:$E$17,0)+COUNTIF($E$6:$E6,E6)-1 -> 1 | AI6: =IF(AJ6=0,"",B6&E6&"件") | AJ6: =E6 -> 0 | AK6: =IF(AK5="","",IF(VLOOKUP(AL5,$AH$6:$AJ$17,3,0)=VLOOKUP(AL6,$AH$6:$AJ$17,3,0),VLOOKUP(AL6,$AH$6:$AJ$17,2,0),"")) | AL6: 4
A7: 2 | B7: 潍城 | C7: =COUNTIFS(督办单!L:L,B:B,督办单!M:M,$M$6,督办单!P:P,"无",督办单!C:C,"*一级*") -> 0 | D7: =COUNTIFS(督办单!L:L,B:B,督办单!M:M,$M$6,督办单!P:P,"7天内",督办单!C:C,"*一级*") -> 0 | E7: =COUNTIFS(督办单!L:L,B:B,督办单!M:M,$M$6,督办单!P:P,"30天内",督办单!C:C,"*一级*") -> 0 | F7: =COUNTIFS(督办单!L:L,B:B,督办单!M:M,$M$6,督办单!P:P,"60天内",督办单!C:C,"*一级*") -> 0 | G7: =COUNTIFS(督办单!L:L,B:B,督办单!M:M,$M$6,督办单!P:P,"90天内",督办单!C:C,"*一级*") -> 0 | H7: =COUNTIFS(督办单!L:L,B:B,督办单!C:C,"*一级*",督办单!M:M,$M$6) -> 0 | I7: =COUNTIFS(督办单!L:L,B:B,督办单!C:C,"*一级*",督办单!M:M,$M$6)/(COUNTIFS(累计派单!R:R,B:B,累计派单!S:S,$M$6)-COUNTIFS(累计派单!R:R,B:B,累计派单!I:I,"*业务受理*",累计派单!S:S,$M$6)) -> #DIV/0! | J7: =COUNTIFS(督办单!L:L,B:B,督办单!C:C,"*一级*") -> 58 | K7: =J7/(COUNTIFS(累计派单!R:R,B:B)-COUNTIFS(累计派单!R:R,B:B,累计派单!I:I,"*业务受理*")-COUNTIFS(累计派单!I:I,"*客户咨询*")) -> 0.093397746 | L7: 潍城 | O7: =_xlfn.RANK.EQ(K7,$K$6:$K$17,0)+COUNTIF($K$6:$K7,K7)-1 -> 2 | P7: =B7&"("&ROUND(K7*100,2)&"%)" -> 潍城(9.34%) | Q7: =_xlfn.RANK.EQ(I7,$I$6:$I$17,0)+COUNTIF($I$6:$I7,I7)-1 -> #DIV/0! | R7: =B7&"("&ROUND(I7*100,2)&"%)" -> #DIV/0! | S7: =_xlfn.RANK.EQ(H7,$H$6:$H$17,0)+COUNTIF($H$6:$H7,H7)-1 -> 2 | T7: =IF(H7=0,"",B7&H7&"件") | U7: =H7 -> 0 | V7: =IF(V6="","",IF(VLOOKUP(W6,$S$6:$U$17,3,0)=VLOOKUP(W7,$S$6:$U$17,3,0),VLOOKUP(W7,$S$6:$U$17,2,0),"")) | W7: 5 | X7: =_xlfn.RANK.EQ(C7,$C$6:$C$17,0)+COUNTIF($C$6:$C7,C7)-1 -> 2 | Y7: =IF(Z7=0,"",B7&C7&"件") | Z7: =C7 -> 0 | AA7: =IF(AA6="","",IF(VLOOKUP(AB6,$AC$6:$AE$17,3,0)=VLOOKUP(AB7,$AC$6:$AE$17,3,0),VLOOKUP(AB7,$AC$6:$AE$17,2,0),"")) | AB7: 5 | AC7: =_xlfn.RANK.EQ(D7,$D$6:$D$17,0)+COUNTIF($D$6:$D7,D7)-1 -> 2 | AD7: =IF(AE7=0,"",B7&D7&"件") | AE7: =D7 -> 0 | AF7: =IF(AF6="","",IF(VLOOKUP(AG6,$AC$6:$AE$17,3,0)=VLOOKUP(AG7,$AC$6:$AE$17,3,0),VLOOKUP(AG7,$AC$6:$AE$17,2,0),"")) | AG7: 5 | AH7: =_xlfn.RANK.EQ(E7,$E$6:$E$17,0)+COUNTIF($E$6:$E7,E7)-1 -> 2 | AI7: =IF(AJ7=0,"",B7&E7&"件") | AJ7: =E7 -> 0 | AK7: =IF(AK6="","",IF(VLOOKUP(AL6,$AH$6:$AJ$17,3,0)=VLOOKUP(AL7,$AH$6:$AJ$17,3,0),VLOOKUP(AL7,$AH$6:$AJ$17,2,0),"")) | AL7: 5
A8: 3 | B8: 奎文 | C8: =COUNTIFS(督办单!L:L,B:B,督办单!M:M,$M$6,督办单!P:P,"无",督办单!C:C,"*一级*") -> 0 | D8: =COUNTIFS(督办单!L:L,B:B,督办单!M:M,$M$6,督办单!P:P,"7天内",督办单!C:C,"*一级*") -> 0 | E8: =COUNTIFS(督办单!L:L,B:B,督办单!M:M,$M$6,督办单!P:P,"30天内",督办单!C:C,"*一级*") -> 0 | F8: =COUNTIFS(督办单!L:L,B:B,督办单!M:M,$M$6,督办单!P:P,"60天内",督办单!C:C,"*一级*") -> 0 | G8: =COUNTIFS(督办单!L:L,B:B,督办单!M:M,$M$6,督办单!P:P,"90天内",督办单!C:C,"*一级*") -> 0 | H8: =COUNTIFS(督办单!L:L,B:B,督办单!C:C,"*一级*",督办单!M:M,$M$6) -> 0 | I8: =COUNTIFS(督办单!L:L,B:B,督办单!C:C,"*一级*",督办单!M:M,$M$6)/(COUNTIFS(累计派单!R:R,B:B,累计派单!S:S,$M$6)-COUNTIFS(累计派单!R:R,B:B,累计派单!I:I,"*业务受理*",累计派单!S:S,$M$6)) -> #DIV/0! | J8: =COUNTIFS(督办单!L:L,B:B,督办单!C:C,"*一级*") -> 102 | K8: =J8/(COUNTIFS(累计派单!R:R,B:B)-COUNTIFS(累计派单!R:R,B:B,累计派单!I:I,"*业务受理*")-COUNTIFS(累计派单!I:I,"*客户咨询*")) -> 0.086587436 | L8: 奎文 | O8: =_xlfn.RANK.EQ(K8,$K$6:$K$17,0)+COUNTIF($K$6:$K8,K8)-1 -> 4 | P8: =B8&"("&ROUND(K8*100,2)&"%)" -> 奎文(8.66%) | Q8: =_xlfn.RANK.EQ(I8,$I$6:$I$17,0)+COUNTIF($I$6:$I8,I8)-1 -> #DIV/0! | R8: =B8&"("&ROUND(I8*100,2)&"%)" -> #DIV/0! | S8: =_xlfn.RANK.EQ(H8,$H$6:$H$17,0)+COUNTIF($H$6:$H8,H8)-1 -> 3 | T8: =IF(H8=0,"",B8&H8&"件") | U8: =H8 -> 0 | V8: =IF(V7="","",IF(VLOOKUP(W7,$S$6:$U$17,3,0)=VLOOKUP(W8,$S$6:$U$17,3,0),VLOOKUP(W8,$S$6:$U$17,2,0),"")) | W8: 6 | X8: =_xlfn.RANK.EQ(C8,$C$6:$C$17,0)+COUNTIF($C$6:$C8,C8)-1 -> 3 | Y8: =IF(Z8=0,"",B8&C8&"件") | Z8: =C8 -> 0 | AA8: =IF(AA7="","",IF(VLOOKUP(AB7,$AC$6:$AE$17,3,0)=VLOOKUP(AB8,$AC$6:$AE$17,3,0),VLOOKUP(AB8,$AC$6:$AE$17,2,0),"")) | AB8: 6 | AC8: =_xlfn.RANK.EQ(D8,$D$6:$D$17,0)+COUNTIF($D$6:$D8,D8)-1 -> 3 | AD8: =IF(AE8=0,"",B8&D8&"件") | AE8: =D8 -> 0 | AF8: =IF(AF7="","",IF(VLOOKUP(AG7,$AC$6:$AE$17,3,0)=VLOOKUP(AG8,$AC$6:$AE$17,3,0),VLOOKUP(AG8,$AC$6:$AE$17,2,0),"")) | AG8: 6 | AH8: =_xlfn.RANK.EQ(E8,$E$6:$E$17,0)+COUNTIF($E$6:$E8,E8)-1 -> 3 | AI8: =IF(AJ8=0,"",B8&E8&"件") | AJ8: =E8 -> 0 | AK8: =IF(AK7="","",IF(VLOOKUP(AL7,$AH$6:$AJ$17,3,0)=VLOOKUP(AL8,$AH$6:$AJ$17,3,0),VLOOKUP(AL8,$AH$6:$AJ$17,2,0),"")) | AL8: 6
A9: 4 | B9: 安丘 | C9: =COUNTIFS(督办单!L:L,B:B,督办单!M:M,$M$6,督办单!P:P,"无",督办单!C:C,"*一级*") -> 0 | D9: =COUNTIFS(督办单!L:L,B:B,督办单!M:M,$M$6,督办单!P:P,"7天内",督办单!C:C,"*一级*") -> 0 | E9: =COUNTIFS(督办单!L:L,B:B,督办单!M:M,$M$6,督办单!P:P,"30天内",督办单!C:C,"*一级*") -> 0 | F9: =COUNTIFS(督办单!L:L,B:B,督办单!M:M,$M$6,督办单!P:P,"60天内",督办单!C:C,"*一级*") -> 0 | G9: =COUNTIFS(督办单!L:L,B:B,督办单!M:M,$M$6,督办单!P:P,"90天内",督办单!C:C,"*一级*") -> 0 | H9: =COUNTIFS(督办单!L:L,B:B,督办单!C:C,"*一级*",督办单!M:M,$M$6) -> 0 | I9: =COUNTIFS(督办单!L:L,B:B,督办单!C:C,"*一级*",督办单!M:M,$M$6)/(COUNTIFS(累计派单!R:R,B:B,累计派单!S:S,$M$6)-COUNTIFS(累计派单!R:R,B:B,累计派单!I:I,"*业务受理*",累计派单!S:S,$M$6)) -> #DIV/0! | J9: =COUNTIFS(督办单!L:L,B:B,督办单!C:C,"*一级*") -> 67 | K9: =J9/(COUNTIFS(累计派单!R:R,B:B)-COUNTIFS(累计派单!R:R,B:B,累计派单!I:I,"*业务受理*")-COUNTIFS(累计派单!I:I,"*客户咨询*")) -> 0.089452603 | L9: 安丘 | O9: =_xlfn.RANK.EQ(K9,$K$6:$K$17,0)+COUNTIF($K$6:$K9,K9)-1 -> 3 | P9: =B9&"("&ROUND(K9*100,2)&"%)" -> 安丘(8.95%) | Q9: =_xlfn.RANK.EQ(I9,$I$6:$I$17,0)+COUNTIF($I$6:$I9,I9)-1 -> #DIV/0! | R9: =B9&"("&ROUND(I9*100,2)&"%)" -> #DIV/0! | S9: =_xlfn.RANK.EQ(H9,$H$6:$H$17,0)+COUNTIF($H$6:$H9,H9)-1 -> 4 | T9: =IF(H9=0,"",B9&H9&"件") | U9: =H9 -> 0 | V9: =IF(V8="","",IF(VLOOKUP(W8,$S$6:$U$17,3,0)=VLOOKUP(W9,$S$6:$U$17,3,0),VLOOKUP(W9,$S$6:$U$17,2,0),"")) | W9: 7 | X9: =_xlfn.RANK.EQ(C9,$C$6:$C$17,0)+COUNTIF($C$6:$C9,C9)-1 -> 4 | Y9: =IF(Z9=0,"",B9&C9&"件") | Z9: =C9 -> 0 | AA9: =IF(AA8="","",IF(VLOOKUP(AB8,$AC$6:$AE$17,3,0)=VLOOKUP(AB9,$AC$6:$AE$17,3,0),VLOOKUP(AB9,$AC$6:$AE$17,2,0),"")) | AB9: 7 | AC9: =_xlfn.RANK.EQ(D9,$D$6:$D$17,0)+COUNTIF($D$6:$D9,D9)-1 -> 4 | AD9: =IF(AE9=0,"",B9&D9&"件") | AE9: =D9 -> 0 | AF9: =IF(AF8="","",IF(VLOOKUP(AG8,$AC$6:$AE$17,3,0)=VLOOKUP(AG9,$AC$6:$AE$17,3,0),VLOOKUP(AG9,$AC$6:$AE$17,2,0),"")) | AG9: 7 | AH9: =_xlfn.RANK.EQ(E9,$E$6:$E$17,0)+COUNTIF($E$6:$E9,E9)-1 -> 4 | AI9: =IF(AJ9=0,"",B9&E9&"件") | AJ9: =E9 -> 0 | AK9: =IF(AK8="","",IF(VLOOKUP(AL8,$AH$6:$AJ$17,3,0)=VLOOKUP(AL9,$AH$6:$AJ$17,3,0),VLOOKUP(AL9,$AH$6:$AJ$17,2,0),"")) | AL9: 7
A10: 5 | B10: 寿光 | C10: =COUNTIFS(督办单!L:L,B:B,督办单!M:M,$M$6,督办单!P:P,"无",督办单!C:C,"*一级*") -> 0 | D10: =COUNTIFS(督办单!L:L,B:B,督办单!M:M,$M$6,督办单!P:P,"7天内",督办单!C:C,"*一级*") -> 0 | E10: =COUNTIFS(督办单!L:L,B:B,督办单!M:M,$M$6,督办单!P:P,"30天内",督办单!C:C,"*一级*") -> 0 | F10: =COUNTIFS(督办单!L:L,B:B,督办单!M:M,$M$6,督办单!P:P,"60天内",督办单!C:C,"*一级*") -> 0 | G10: =COUNTIFS(督办单!L:L,B:B,督办单!M:M,$M$6,督办单!P:P,"90天内",督办单!C:C,"*一级*") -> 0 | H10: =COUNTIFS(督办单!L:L,B:B,督办单!C:C,"*一级*",督办单!M:M,$M$6) -> 0 | I10: =COUNTIFS(督办单!L:L,B:B,督办单!C:C,"*一级*",督办单!M:M,$M$6)/(COUNTIFS(累计派单!R:R,B:B,累计派单!S:S,$M$6)-COUNTIFS(累计派单!R:R,B:B,累计派单!I:I,"*业务受理*",累计派单!S:S,$M$6)) -> #DIV/0! | J10: =COUNTIFS(督办单!L:L,B:B,督办单!C:C,"*一级*") -> 98 | K10: =J10/(COUNTIFS(累计派单!R:R,B:B)-COUNTIFS(累计派单!R:R,B:B,累计派单!I:I,"*业务受理*")-COUNTIFS(累计派单!I:I,"*客户咨询*")) -> 0.083050847 | L10: 寿光 | O10: =_xlfn.RANK.EQ(K10,$K$6:$K$17,0)+COUNTIF($K$6:$K10,K10)-1 -> 5 | P10: =B10&"("&ROUND(K10*100,2)&"%)" -> 寿光(8.31%) | Q10: =_xlfn.RANK.EQ(I10,$I$6:$I$17,0)+COUNTIF($I$6:$I10,I10)-1 -> #DIV/0! | R10: =B10&"("&ROUND(I10*100,2)&"%)" -> #DIV/0! | S10: =_xlfn.RANK.EQ(H10,$H$6:$H$17,0)+COUNTIF($H$6:$H10,H10)-1 -> 5 | T10: =IF(H10=0,"",B10&H10&"件") | U10: =H10 -> 0 | V10: =IF(V9="","",IF(VLOOKUP(W9,$S$6:$U$17,3,0)=VLOOKUP(W10,$S$6:$U$17,3,0),VLOOKUP(W10,$S$6:$U$17,2,0),"")) | W10: 8 | X10: =_xlfn.RANK.EQ(C10,$C$6:$C$17,0)+COUNTIF($C$6:$C10,C10)-1 -> 5 | Y10: =IF(Z10=0,"",B10&C10&"件") | Z10: =C10 -> 0 | AA10: =IF(AA9="","",IF(VLOOKUP(AB9,$AC$6:$AE$17,3,0)=VLOOKUP(AB10,$AC$6:$AE$17,3,0),VLOOKUP(AB10,$AC$6:$AE$17,2,0),"")) | AB10: 8 | AC10: =_xlfn.RANK.EQ(D10,$D$6:$D$17,0)+COUNTIF($D$6:$D10,D10)-1 -> 5 | AD10: =IF(AE10=0,"",B10&D10&"件") | AE10: =D10 -> 0 | AF10: =IF(AF9="","",IF(VLOOKUP(AG9,$AC$6:$AE$17,3,0)=VLOOKUP(AG10,$AC$6:$AE$17,3,0),VLOOKUP(AG10,$AC$6:$AE$17,2,0),"")) | AG10: 8 | AH10: =_xlfn.RANK.EQ(E10,$E$6:$E$17,0)+COUNTIF($E$6:$E10,E10)-1 -> 5 | AI10: =IF(AJ10=0,"",B10&E10&"件") | AJ10: =E10 -> 0 | AK10: =IF(AK9="","",IF(VLOOKUP(AL9,$AH$6:$AJ$17,3,0)=VLOOKUP(AL10,$AH$6:$AJ$17,3,0),VLOOKUP(AL10,$AH$6:$AJ$17,2,0),"")) | AL10: 8
A11: 6 | B11: 昌邑 | C11: =COUNTIFS(督办单!L:L,B:B,督办单!M:M,$M$6,督办单!P:P,"无",督办单!C:C,"*一级*") -> 0 | D11: =COUNTIFS(督办单!L:L,B:B,督办单!M:M,$M$6,督办单!P:P,"7天内",督办单!C:C,"*一级*") -> 0 | E11: =COUNTIFS(督办单!L:L,B:B,督办单!M:M,$M$6,督办单!P:P,"30天内",督办单!C:C,"*一级*") -> 0 | F11: =COUNTIFS(督办单!L:L,B:B,督办单!M:M,$M$6,督办单!P:P,"60天内",督办单!C:C,"*一级*") -> 0 | G11: =COUNTIFS(督办单!L:L,B:B,督办单!M:M,$M$6,督办单!P:P,"90天内",督办单!C:C,"*一级*") -> 0 | H11: =COUNTIFS(督办单!L:L,B:B,督办单!C:C,"*一级*",督办单!M:M,$M$6) -> 0 | I11: =COUNTIFS(督办单!L:L,B:B,督办单!C:C,"*一级*",督办单!M:M,$M$6)/(COUNTIFS(累计派单!R:R,B:B,累计派单!S:S,$M$6)-COUNTIFS(累计派单!R:R,B:B,累计派单!I:I,"*业务受理*",累计派单!S:S,$M$6)) -> #DIV/0! | J11: =COUNTIFS(督办单!L:L,B:B,督办单!C:C,"*一级*") -> 33 | K11: =J11/(COUNTIFS(累计派单!R:R,B:B)-COUNTIFS(累计派单!R:R,B:B,累计派单!I:I,"*业务受理*")-COUNTIFS(累计派单!I:I,"*客户咨询*")) -> 0.075514874 | L11: 昌邑 | O11: =_xlfn.RANK.EQ(K11,$K$6:$K$17,0)+COUNTIF($K$6:$K11,K11)-1 -> 7 | P11: =B11&"("&ROUND(K11*100,2)&"%)" -> 昌邑(7.55%) | Q11: =_xlfn.RANK.EQ(I11,$I$6:$I$17,0)+COUNTIF($I$6:$I11,I11)-1 -> #DIV/0! | R11: =B11&"("&ROUND(I11*100,2)&"%)" -> #DIV/0! | S11: =_xlfn.RANK.EQ(H11,$H$6:$H$17,0)+COUNTIF($H$6:$H11,H11)-1 -> 6 | T11: =IF(H11=0,"",B11&H11&"件") | U11: =H11 -> 0 | V11: =IF(V10="","",IF(VLOOKUP(W10,$S$6:$U$17,3,0)=VLOOKUP(W11,$S$6:$U$17,3,0),VLOOKUP(W11,$S$6:$U$17,2,0),"")) | W11: 9 | X11: =_xlfn.RANK.EQ(C11,$C$6:$C$17,0)+COUNTIF($C$6:$C11,C11)-1 -> 6 | Y11: =IF(Z11=0,"",B11&C11&"件") | Z11: =C11 -> 0 | AA11: =IF(AA10="","",IF(VLOOKUP(AB10,$AC$6:$AE$17,3,0)=VLOOKUP(AB11,$AC$6:$AE$17,3,0),VLOOKUP(AB11,$AC$6:$AE$17,2,0),"")) | AB11: 9 | AC11: =_xlfn.RANK.EQ(D11,$D$6:$D$17,0)+COUNTIF($D$6:$D11,D11)-1 -> 6 | AD11: =IF(AE11=0,"",B11&D11&"件") | AE11: =D11 -> 0 | AF11: =IF(AF10="","",IF(VLOOKUP(AG10,$AC$6:$AE$17,3,0)=VLOOKUP(AG11,$AC$6:$AE$17,3,0),VLOOKUP(AG11,$AC$6:$AE$17,2,0),"")) | AG11: 9 | AH11: =_xlfn.RANK.EQ(E11,$E$6:$E$17,0)+COUNTIF($E$6:$E11,E11)-1 -> 6 | AI11: =IF(AJ11=0,"",B11&E11&"件") | AJ11: =E11 -> 0 | AK11: =IF(AK10="","",IF(VLOOKUP(AL10,$AH$6:$AJ$17,3,0)=VLOOKUP(AL11,$AH$6:$AJ$17,3,0),VLOOKUP(AL11,$AH$6:$AJ$17,2,0),"")) | AL11: 9
A12: 7 | B12: 寒亭 | C12: =COUNTIFS(督办单!L:L,B:B,督办单!M:M,$M$6,督办单!P:P,"无",督办单!C:C,"*一级*") -> 0 | D12: =COUNTIFS(督办单!L:L,B:B,督办单!M:M,$M$6,督办单!P:P,"7天内",督办单!C:C,"*一级*") -> 0 | E12: =COUNTIFS(督办单!L:L,B:B,督办单!M:M,$M$6,督办单!P:P,"30天内",督办单!C:C,"*一级*") -> 0 | F12: =COUNTIFS(督办单!L:L,B:B,督办单!M:M,$M$6,督办单!P:P,"60天内",督办单!C:C,"*一级*") -> 0 | G12: =COUNTIFS(督办单!L:L,B:B,督办单!M:M,$M$6,督办单!P:P,"90天内",督办单!C:C,"*一级*") -> 0 | H12: =COUNTIFS(督办单!L:L,B:B,督办单!C:C,"*一级*",督办单!M:M,$M$6) -> 0 | I12: =COUNTIFS(督办单!L:L,B:B,督办单!C:C,"*一级*",督办单!M:M,$M$6)/(COUNTIFS(累计派单!R:R,B:B,累计派单!S:S,$M$6)-COUNTIFS(累计派单!R:R,B:B,累计派单!I:I,"*业务受理*",累计派单!S:S,$M$6)) -> #DIV/0! | J12: =COUNTIFS(督办单!L:L,B:B,督办单!C:C,"*一级*") -> 37 | K12: =J12/(COUNTIFS(累计派单!R:R,B:B)-COUNTIFS(累计派单!R:R,B:B,累计派单!I:I,"*业务受理*")-COUNTIFS(累计派单!I:I,"*客户咨询*")) -> 0.077568134 | L12: 寒亭 | O12: =_xlfn.RANK.EQ(K12,$K$6:$K$17,0)+COUNTIF($K$6:$K12,K12)-1 -> 6 | P12: =B12&"("&ROUND(K12*100,2)&"%)" -> 寒亭(7.76%) | Q12: =_xlfn.RANK.EQ(I12,$I$6:$I$17,0)+COUNTIF($I$6:$I12,I12)-1 -> #DIV/0! | R12: =B12&"("&ROUND(I12*100,2)&"%)" -> #DIV/0! | S12: =_xlfn.RANK.EQ(H12,$H$6:$H$17,0)+COUNTIF($H$6:$H12,H12)-1 -> 7 | T12: =IF(H12=0,"",B12&H12&"件") | U12: =H12 -> 0 | V12: =IF(V11="","",IF(VLOOKUP(W11,$S$6:$U$17,3,0)=VLOOKUP(W12,$S$6:$U$17,3,0),VLOOKUP(W12,$S$6:$U$17,2,0),"")) | W12: 10 | X12: =_xlfn.RANK.EQ(C12,$C$6:$C$17,0)+COUNTIF($C$6:$C12,C12)-1 -> 7 | Y12: =IF(Z12=0,"",B12&C12&"件") | Z12: =C12 -> 0 | AA12: =IF(AA11="","",IF(VLOOKUP(AB11,$AC$6:$AE$17,3,0)=VLOOKUP(AB12,$AC$6:$AE$17,3,0),VLOOKUP(AB12,$AC$6:$AE$17,2,0),"")) | AB12: 10 | AC12: =_xlfn.RANK.EQ(D12,$D$6:$D$17,0)+COUNTIF($D$6:$D12,D12)-1 -> 7 | AD12: =IF(AE12=0,"",B12&D12&"件") | AE12: =D12 -> 0 | AF12: =IF(AF11="","",IF(VLOOKUP(AG11,$AC$6:$AE$17,3,0)=VLOOKUP(AG12,$AC$6:$AE$17,3,0),VLOOKUP(AG12,$AC$6:$AE$17,2,0),"")) | AG12: 10 | AH12: =_xlfn.RANK.EQ(E12,$E$6:$E$17,0)+COUNTIF($E$6:$E12,E12)-1 -> 7 | AI12: =IF(AJ12=0,"",B12&E12&"件") | AJ12: =E12 -> 0 | AK12: =IF(AK11="","",IF(VLOOKUP(AL11,$AH$6:$AJ$17,3,0)=VLOOKUP(AL12,$AH$6:$AJ$17,3,0),VLOOKUP(AL12,$AH$6:$AJ$17,2,0),"")) | AL12: 10
A13: 8 | B13: 高密 | C13: =COUNTIFS(督办单!L:L,B:B,督办单!M:M,$M$6,督办单!P:P,"无",督办单!C:C,"*一级*") -> 0 | D13: =COUNTIFS(督办单!L:L,B:B,督办单!M:M,$M$6,督办单!P:P,"7天内",督办单!C:C,"*一级*") -> 0 | E13: =COUNTIFS(督办单!L:L,B:B,督办单!M:M,$M$6,督办单!P:P,"30天内",督办单!C:C,"*一级*") -> 0 | F13: =COUNTIFS(督办单!L:L,B:B,督办单!M:M,$M$6,督办单!P:P,"60天内",督办单!C:C,"*一级*") -> 0 | G13: =COUNTIFS(督办单!L:L,B:B,督办单!M:M,$M$6,督办单!P:P,"90天内",督办单!C:C,"*一级*") -> 0 | H13: =COUNTIFS(督办单!L:L,B:B,督办单!C:C,"*一级*",督办单!M:M,$M$6) -> 0 | I13: =COUNTIFS(督办单!L:L,B:B,督办单!C:C,"*一级*",督办单!M:M,$M$6)/(COUNTIFS(累计派单!R:R,B:B,累计派单!S:S,$M$6)-COUNTIFS(累计派单!R:R,B:B,累计派单!I:I,"*业务受理*",累计派单!S:S,$M$6)) -> #DIV/0! | J13: =COUNTIFS(督办单!L:L,B:B,督办单!C:C,"*一级*") -> 38 | K13: =J13/(COUNTIFS(累计派单!R:R,B:B)-COUNTIFS(累计派单!R:R,B:B,累计派单!I:I,"*业务受理*")-COUNTIFS(累计派单!I:I,"*客户咨询*")) -> 0.0642978 | L13: 高密 | O13: =_xlfn.RANK.EQ(K13,$K$6:$K$17,0)+COUNTIF($K$6:$K13,K13)-1 -> 8 | P13: =B13&"("&ROUND(K13*100,2)&"%)" -> 高密(6.43%) | Q13: =_xlfn.RANK.EQ(I13,$I$6:$I$17,0)+COUNTIF($I$6:$I13,I13)-1 -> #DIV/0! | R13: =B13&"("&ROUND(I13*100,2)&"%)" -> #DIV/0! | S13: =_xlfn.RANK.EQ(H13,$H$6:$H$17,0)+COUNTIF($H$6:$H13,H13)-1 -> 8 | T13: =IF(H13=0,"",B13&H13&"件") | U13: =H13 -> 0 | V13: =IF(V12="","",IF(VLOOKUP(W12,$S$6:$U$17,3,0)=VLOOKUP(W13,$S$6:$U$17,3,0),VLOOKUP(W13,$S$6:$U$17,2,0),"")) | W13: 11 | X13: =_xlfn.RANK.EQ(C13,$C$6:$C$17,0)+COUNTIF($C$6:$C13,C13)-1 -> 8 | Y13: =IF(Z13=0,"",B13&C13&"件") | Z13: =C13 -> 0 | AA13: =IF(AA12="","",IF(VLOOKUP(AB12,$AC$6:$AE$17,3,0)=VLOOKUP(AB13,$AC$6:$AE$17,3,0),VLOOKUP(AB13,$AC$6:$AE$17,2,0),"")) | AB13: 11 | AC13: =_xlfn.RANK.EQ(D13,$D$6:$D$17,0)+COUNTIF($D$6:$D13,D13)-1 -> 8 | AD13: =IF(AE13=0,"",B13&D13&"件") | AE13: =D13 -> 0 | AF13: =IF(AF12="","",IF(VLOOKUP(AG12,$AC$6:$AE$17,3,0)=VLOOKUP(AG13,$AC$6:$AE$17,3,0),VLOOKUP(AG13,$AC$6:$AE$17,2,0),"")) | AG13: 11 | AH13: =_xlfn.RANK.EQ(E13,$E$6:$E$17,0)+COUNTIF($E$6:$E13,E13)-1 -> 8 | AI13: =IF(AJ13=0,"",B13&E13&"件") | AJ13: =E13 -> 0 | AK13: =IF(AK12="","",IF(VLOOKUP(AL12,$AH$6:$AJ$17,3,0)=VLOOKUP(AL13,$AH$6:$AJ$17,3,0),VLOOKUP(AL13,$AH$6:$AJ$17,2,0),"")) | AL13: 11
A14: 9 | B14: 青州 | C14: =COUNTIFS(督办单!L:L,B:B,督办单!M:M,$M$6,督办单!P:P,"无",督办单!C:C,"*一级*") -> 0 | D14: =COUNTIFS(督办单!L:L,B:B,督办单!M:M,$M$6,督办单!P:P,"7天内",督办单!C:C,"*一级*") -> 0 | E14: =COUNTIFS(督办单!L:L,B:B,督办单!M:M,$M$6,督办单!P:P,"30天内",督办单!C:C,"*一级*") -> 0 | F14: =COUNTIFS(督办单!L:L,B:B,督办单!M:M,$M$6,督办单!P:P,"60天内",督办单!C:C,"*一级*") -> 0 | G14: =COUNTIFS(督办单!L:L,B:B,督办单!M:M,$M$6,督办单!P:P,"90天内",督办单!C:C,"*一级*") -> 0 | H14: =COUNTIFS(督办单!L:L,B:B,督办单!C:C,"*一级*",督办单!M:M,$M$6) -> 0 | I14: =COUNTIFS(督办单!L:L,B:B,督办单!C:C,"*一级*",督办单!M:M,$M$6)/(COUNTIFS(累计派单!R:R,B:B,累计派单!S:S,$M$6)-COUNTIFS(累计派单!R:R,B:B,累计派单!I:I,"*业务受理*",累计派单!S:S,$M$6)) -> #DIV/0! | J14: =COUNTIFS(督办单!L:L,B:B,督办单!C:C,"*一级*") -> 43 | K14: =J14/(COUNTIFS(累计派单!R:R,B:B)-COUNTIFS(累计派单!R:R,B:B,累计派单!I:I,"*业务受理*")-COUNTIFS(累计派单!I:I,"*客户咨询*")) -> 0.057486631 | L14: 青州 | O14: =_xlfn.RANK.EQ(K14,$K$6:$K$17,0)+COUNTIF($K$6:$K14,K14)-1 -> 9 | P14: =B14&"("&ROUND(K14*100,2)&"%)" -> 青州(5.75%) | Q14: =_xlfn.RANK.EQ(I14,$I$6:$I$17,0)+COUNTIF($I$6:$I14,I14)-1 -> #DIV/0! | R14: =B14&"("&ROUND(I14*100,2)&"%)" -> #DIV/0! | S14: =_xlfn.RANK.EQ(H14,$H$6:$H$17,0)+COUNTIF($H$6:$H14,H14)-1 -> 9 | T14: =IF(H14=0,"",B14&H14&"件") | U14: =H14 -> 0 | V14: =IF(V13="","",IF(VLOOKUP(W13,$S$6:$U$17,3,0)=VLOOKUP(W14,$S$6:$U$17,3,0),VLOOKUP(W14,$S$6:$U$17,2,0),"")) | W14: 12 | X14: =_xlfn.RANK.EQ(C14,$C$6:$C$17,0)+COUNTIF($C$6:$C14,C14)-1 -> 9 | Y14: =IF(Z14=0,"",B14&C14&"件") | Z14: =C14 -> 0 | AA14: =IF(AA13="","",IF(VLOOKUP(AB13,$AC$6:$AE$17,3,0)=VLOOKUP(AB14,$AC$6:$AE$17,3,0),VLOOKUP(AB14,$AC$6:$AE$17,2,0),"")) | AB14: 12 | AC14: =_xlfn.RANK.EQ(D14,$D$6:$D$17,0)+COUNTIF($D$6:$D14,D14)-1 -> 9 | AD14: =IF(AE14=0,"",B14&D14&"件") | AE14: =D14 -> 0 | AF14: =IF(AF13="","",IF(VLOOKUP(AG13,$AC$6:$AE$17,3,0)=VLOOKUP(AG14,$AC$6:$AE$17,3,0),VLOOKUP(AG14,$AC$6:$AE$17,2,0),"")) | AG14: 12 | AH14: =_xlfn.RANK.EQ(E14,$E$6:$E$17,0)+COUNTIF($E$6:$E14,E14)-1 -> 9 | AI14: =IF(AJ14=0,"",B14&E14&"件") | AJ14: =E14 -> 0 | AK14: =IF(AK13="","",IF(VLOOKUP(AL13,$AH$6:$AJ$17,3,0)=VLOOKUP(AL14,$AH$6:$AJ$17,3,0),VLOOKUP(AL14,$AH$6:$AJ$17,2,0),"")) | AL14: 12
A15: 10 | B15: 诸城 | C15: =COUNTIFS(督办单!L:L,B:B,督办单!M:M,$M$6,督办单!P:P,"无",督办单!C:C,"*一级*") -> 0 | D15: =COUNTIFS(督办单!L:L,B:B,督办单!M:M,$M$6,督办单!P:P,"7天内",督办单!C:C,"*一级*") -> 0 | E15: =COUNTIFS(督办单!L:L,B:B,督办单!M:M,$M$6,督办单!P:P,"30天内",督办单!C:C,"*一级*") -> 0 | F15: =COUNTIFS(督办单!L:L,B:B,督办单!M:M,$M$6,督办单!P:P,"60天内",督办单!C:C,"*一级*") -> 0 | G15: =COUNTIFS(督办单!L:L,B:B,督办单!M:M,$M$6,督办单!P:P,"90天内",督办单!C:C,"*一级*") -> 0 | H15: =COUNTIFS(督办单!L:L,B:B,督办单!C:C,"*一级*",督办单!M:M,$M$6) -> 0 | I15: =COUNTIFS(督办单!L:L,B:B,督办单!C:C,"*一级*",督办单!M:M,$M$6)/(COUNTIFS(累计派单!R:R,B:B,累计派单!S:S,$M$6)-COUNTIFS(累计派单!R:R,B:B,累计派单!I:I,"*业务受理*",累计派单!S:S,$M$6)) -> #DIV/0! | J15: =COUNTIFS(督办单!L:L,B:B,督办单!C:C,"*一级*") -> 38 | K15: =J15/(COUNTIFS(累计派单!R:R,B:B)-COUNTIFS(累计派单!R:R,B:B,累计派单!I:I,"*业务受理*")-COUNTIFS(累计派单!I:I,"*客户咨询*")) -> 0.048780488 | L15: 诸城 | O15: =_xlfn.RANK.EQ(K15,$K$6:$K$17,0)+COUNTIF($K$6:$K15,K15)-1 -> 10 | P15: =B15&"("&ROUND(K15*100,2)&"%)" -> 诸城(4.88%) | Q15: =_xlfn.RANK.EQ(I15,$I$6:$I$17,0)+COUNTIF($I$6:$I15,I15)-1 -> #DIV/0! | R15: =B15&"("&ROUND(I15*100,2)&"%)" -> #DIV/0! | S15: =_xlfn.RANK.EQ(H15,$H$6:$H$17,0)+COUNTIF($H$6:$H15,H15)-1 -> 10 | T15: =IF(H15=0,"",B15&H15&"件") | U15: =H15 -> 0 | X15: =_xlfn.RANK.EQ(C15,$C$6:$C$17,0)+COUNTIF($C$6:$C15,C15)-1 -> 10 | Y15: =IF(Z15=0,"",B15&C15&"件") | Z15: =C15 -> 0 | AC15: =_xlfn.RANK.EQ(D15,$D$6:$D$17,0)+COUNTIF($D$6:$D15,D15)-1 -> 10 | AD15: =IF(AE15=0,"",B15&D15&"件") | AE15: =D15 -> 0 | AH15: =_xlfn.RANK.EQ(E15,$E$6:$E$17,0)+COUNTIF($E$6:$E15,E15)-1 -> 10 | AI15: =IF(AJ15=0,"",B15&E15&"件") | AJ15: =E15 -> 0
A16: 11 | B16: 临朐 | C16: =COUNTIFS(督办单!L:L,B:B,督办单!M:M,$M$6,督办单!P:P,"无",督办单!C:C,"*一级*") -> 0 | D16: =COUNTIFS(督办单!L:L,B:B,督办单!M:M,$M$6,督办单!P:P,"7天内",督办单!C:C,"*一级*") -> 0 | E16: =COUNTIFS(督办单!L:L,B:B,督办单!M:M,$M$6,督办单!P:P,"30天内",督办单!C:C,"*一级*") -> 0 | F16: =COUNTIFS(督办单!L:L,B:B,督办单!M:M,$M$6,督办单!P:P,"60天内",督办单!C:C,"*一级*") -> 0 | G16: =COUNTIFS(督办单!L:L,B:B,督办单!M:M,$M$6,督办单!P:P,"90天内",督办单!C:C,"*一级*") -> 0 | H16: =COUNTIFS(督办单!L:L,B:B,督办单!C:C,"*一级*",督办单!M:M,$M$6) -> 0 | I16: =COUNTIFS(督办单!L:L,B:B,督办单!C:C,"*一级*",督办单!M:M,$M$6)/(COUNTIFS(累计派单!R:R,B:B,累计派单!S:S,$M$6)-COUNTIFS(累计派单!R:R,B:B,累计派单!I:I,"*业务受理*",累计派单!S:S,$M$6)) -> #DIV/0! | J16: =COUNTIFS(督办单!L:L,B:B,督办单!C:C,"*一级*") -> 19 | K16: =J16/(COUNTIFS(累计派单!R:R,B:B)-COUNTIFS(累计派单!R:R,B:B,累计派单!I:I,"*业务受理*")-COUNTIFS(累计派单!I:I,"*客户咨询*")) -> 0.03909465 | L16: 临朐 | O16: =_xlfn.RANK.EQ(K16,$K$6:$K$17,0)+COUNTIF($K$6:$K16,K16)-1 -> 12 | P16: =B16&"("&ROUND(K16*100,2)&"%)" -> 临朐(3.91%) | Q16: =_xlfn.RANK.EQ(I16,$I$6:$I$17,0)+COUNTIF($I$6:$I16,I16)-1 -> #DIV/0! | R16: =B16&"("&ROUND(I16*100,2)&"%)" -> #DIV/0! | S16: =_xlfn.RANK.EQ(H16,$H$6:$H$17,0)+COUNTIF($H$6:$H16,H16)-1 -> 11 | T16: =IF(H16=0,"",B16&H16&"件") | U16: =H16 -> 0 | X16: =_xlfn.RANK.EQ(C16,$C$6:$C$17,0)+COUNTIF($C$6:$C16,C16)-1 -> 11 | Y16: =IF(Z16=0,"",B16&C16&"件") | Z16: =C16 -> 0 | AC16: =_xlfn.RANK.EQ(D16,$D$6:$D$17,0)+COUNTIF($D$6:$D16,D16)-1 -> 11 | AD16: =IF(AE16=0,"",B16&D16&"件") | AE16: =D16 -> 0 | AH16: =_xlfn.RANK.EQ(E16,$E$6:$E$17,0)+COUNTIF($E$6:$E16,E16)-1 -> 11 | AI16: =IF(AJ16=0,"",B16&E16&"件") | AJ16: =E16 -> 0
A17: 12 | B17: 昌乐 | C17: =COUNTIFS(督办单!L:L,B:B,督办单!M:M,$M$6,督办单!P:P,"无",督办单!C:C,"*一级*") -> 0 | D17: =COUNTIFS(督办单!L:L,B:B,督办单!M:M,$M$6,督办单!P:P,"7天内",督办单!C:C,"*一级*") -> 0 | E17: =COUNTIFS(督办单!L:L,B:B,督办单!M:M,$M$6,督办单!P:P,"30天内",督办单!C:C,"*一级*") -> 0 | F17: =COUNTIFS(督办单!L:L,B:B,督办单!M:M,$M$6,督办单!P:P,"60天内",督办单!C:C,"*一级*") -> 0 | G17: =COUNTIFS(督办单!L:L,B:B,督办单!M:M,$M$6,督办单!P:P,"90天内",督办单!C:C,"*一级*") -> 0 | H17: =COUNTIFS(督办单!L:L,B:B,督办单!C:C,"*一级*",督办单!M:M,$M$6) -> 0 | I17: =COUNTIFS(督办单!L:L,B:B,督办单!C:C,"*一级*",督办单!M:M,$M$6)/(COUNTIFS(累计派单!R:R,B:B,累计派单!S:S,$M$6)-COUNTIFS(累计派单!R:R,B:B,累计派单!I:I,"*业务受理*",累计派单!S:S,$M$6)) -> #DIV/0! | J17: =COUNTIFS(督办单!L:L,B:B,督办单!C:C,"*一级*") -> 13 | K17: =J17/(COUNTIFS(累计派单!R:R,B:B)-COUNTIFS(累计派单!R:R,B:B,累计派单!I:I,"*业务受理*")-COUNTIFS(累计派单!I:I,"*客户咨询*")) -> 0.04 | L17: 昌乐 | O17: =_xlfn.RANK.EQ(K17,$K$6:$K$17,0)+COUNTIF($K$6:$K17,K17)-1 -> 11 | P17: =B17&"("&ROUND(K17*100,2)&"%)" -> 昌乐(4%) | Q17: =_xlfn.RANK.EQ(I17,$I$6:$I$17,0)+COUNTIF($I$6:$I17,I17)-1 -> #DIV/0! | R17: =B17&"("&ROUND(I17*100,2)&"%)" -> #DIV/0! | S17: =_xlfn.RANK.EQ(H17,$H$6:$H$17,0)+COUNTIF($H$6:$H17,H17)-1 -> 12 | T17: =IF(H17=0,"",B17&H17&"件") | U17: =H17 -> 0 | X17: =_xlfn.RANK.EQ(C17,$C$6:$C$17,0)+COUNTIF($C$6:$C17,C17)-1 -> 12 | Y17: =IF(Z17=0,"",B17&C17&"件") | Z17: =C17 -> 0 | AC17: =_xlfn.RANK.EQ(D17,$D$6:$D$17,0)+COUNTIF($D$6:$D17,D17)-1 -> 12 | AD17: =IF(AE17=0,"",B17&D17&"件") | AE17: =D17 -> 0 | AH17: =_xlfn.RANK.EQ(E17,$E$6:$E$17,0)+COUNTIF($E$6:$E17,E17)-1 -> 12 | AI17: =IF(AJ17=0,"",B17&E17&"件") | AJ17: =E17 -> 0
A18: 合计 | C18: =SUM(C6:C17) -> 0 | D18: =SUM(D6:D17) -> 0 | E18: =SUM(E6:E17) -> 0 | F18: =SUM(F6:F17) -> 0 | G18: =SUM(G6:G17) -> 0 | H18: =SUM(H6:H17) -> 0 | I18: =H18/(COUNTIFS(累计派单!S:S,$M$6)-COUNTIFS(累计派单!I:I,"*业务受理*",累计派单!S:S,$M$6)-COUNTIFS(累计派单!I:I,"*修复*",累计派单!S:S,$M$6)-COUNTIFS(累计派单!I:I,"*客户咨询*",累计派单!S:S,$M$6)) -> #DIV/0! | J18: =SUM(J6:J17) -> 581 | K18: =J18/(COUNTIFS(累计派单!C:C,"潍坊")-COUNTIFS(累计派单!I:I,"*业务受理*")-COUNTIFS(累计派单!I:I,"*客户咨询*")) -> 0.071737252 | L18: 合计
C20: ="关于10086投诉一级督办占比的通报-截止"&N6&"日 一、整体情况： 1、截止"&N6&"日，累计产生一级督办单"&J18&"件，一级督办单占比"&ROUND(K18*100,2)&"%。 2、一级督办单累计增长："&P5&"较高。 二、单日情况： 1、"&R5&"较多。 2、"&N6&"日新增"&H18&"件："&S2&"较多。 三、分析情况： 1、无重复投诉（重点客户、网课）："&C18&"件"&IF(X2="","。",":"&X2&"。")&" 2、7天内重复投诉"&D18&"件："&AC2&"。 3、大于7天小于30天"&E18&"件："&AH2&"。" -> #N/A

Sheet 督办单
A1: 督办工单号 | B1: 督办工单发起时间 | C1: 督办单主题 | D1: 投诉主题 | E1: 投诉内容 | F1: 投诉地市 | G1: 投诉区县 | H1: 投诉电话 | I1: 投诉工单号 | J1: 重复投诉工单号 | K1: 是否处理 | L1: =IF(OR(LEFT(G1,2)="高新"),"奎文",IF(LEFT(G1,2)="峡山","坊子",IF(LEFT(G1,2)="滨海","寒亭",LEFT(G1,2)))) -> 投诉 | M1: =TEXT(B1,"yyyymmdd") -> 督办工单发起时间 | N1: 工号 | O1: 时间段 | P1: 时间段 | Q1: 网格
A2: SD-db051-250101-931207-37 | B2: 2025-01-01 09:03:51 | C2: (家客)潍坊-青州市-重复投诉投诉督办通知-一级督办13668669581-202501010000116152 | D2: 【调研】-普通区域-青州市-东坝新村-13668669581-200M-宽带上网投诉-次数0-202501010000116152 | E2: 202501010000116152#13668669581客户来电反映宽带无法使用/客户不配合操作/，要求维修人员上门维修，请尽快协助处理，谢谢 联系人：女士 联系电话：13668669581本机 流水：2025010109001361920892105 | F2: 潍坊 | G2: 青州市 | H2: 13668669581 | I2: SD-057-250101-072469-452 | J2: 'SD-057-241009-042561-2426' | K2: 是 | L2: =IF(OR(LEFT(G2,2)="高新"),"奎文",IF(LEFT(G2,2)="峡山","坊子",IF(LEFT(G2,2)="滨海","寒亭",LEFT(G2,2)))) -> 青州 | M2: =TEXT(B2,"mmdd") -> 0101 | N2: =VLOOKUP(I2,累计派单!A:O,15,0) -> dw3_jk_wangzhenhai | O2: =IF(LEN(J2)<2,0,DATEDIF(DATE(IF(MID(J2,9,2)="23",2023,2024),MID(J2,11,2),MID(J2,13,2)),B2,"d")) -> 84 | P2: =IF(O2=0,"无",IF(O2<8,"7天内",IF(O2<31,"30天内",IF(O2<61,"60天内",IF(O2<91,"90天内"))))) -> 90天内 | Q2: =VLOOKUP(I2,累计派单!A:O,13,0) -> 家客铁通潍坊青州-黄楼乡镇装维组
A3: SD-db051-250101-751364-63 | B3: 2025-01-01 09:35:58 | C3: (家客)潍坊-奎文区-重复投诉投诉督办通知-一级督办15963669532-202501010000145903 | D3: 普通区域-奎文区-北王茶城J-15963669532-200M-宽带上网投诉-次数0-202501010000145903 | E3: 202501010000145903#宽带账号：15963669532；联系电话：18463055553宽带地址：潍坊奎文区潍州路街道潍州路北王茶城J3号商品房；客户来电反映宽带无法使用，客户异机来电报修，线上指导无法配合操作，要求上门处理，来电流水：2025010109341165020889173 | F3: 潍坊 | G3: 奎文区 | H3: 15963669532 | I3: SD-057-250101-521943-751 | J3: 'SD-057-241230-495167-1456' | K3: 是 | L3: =IF(OR(LEFT(G3,2)="高新"),"奎文",IF(LEFT(G3,2)="峡山","坊子",IF(LEFT(G3,2)="滨海","寒亭",LEFT(G3,2)))) -> 奎文 | M3: =TEXT(B3,"mmdd") -> 0101 | N3: =VLOOKUP(I3,累计派单!A:O,15,0) -> dw3_jk_zhuwenjie | O3: =IF(LEN(J3)<2,0,DATEDIF(DATE(IF(MID(J3,9,2)="23",2023,2024),MID(J3,11,2),MID(J3,13,2)),B3,"d")) -> 2 | P3: =IF(O3=0,"无",IF(O3<8,"7天内",IF(O3<31,"30天内",IF(O3<61,"60天内",IF(O3<91,"90天内"))))) -> 7天内 | Q3: =VLOOKUP(I3,累计派单!A:O,13,0) -> 家客铁通潍坊奎文-潍州路城区装维组
A4: SD-db051-250101-895720-70 | B4: 2025-01-01 09:45:05 | C4: (家客)潍坊-奎文区-重复投诉投诉督办通知-一级督办15910111711-202501010000151577 | D4: 【调研】-80+白金-普通区域-奎文区-赋海仁居-15910111711-1000M-宽带上网投诉-次数0-202501010000151577 | E4: 202501010000151577#宽带账号：15910111711；宽带地址：潍坊高新高新城区福寿街赋海仁居7号楼*；客户来电反映移动高清无法上网*，经查询客户侧为质差机顶盒，请协助上门更换设备并一并处理故障问题，谢谢！联系电话本机；联系人先生来电流 | F4: 潍坊 | G4: 奎文区 | H4: 15910111711 | I4: SD-057-250101-586490-818 | J4: 'SD-057-241230-152379-8347' | K4: 是 | L4: =IF(OR(LEFT(G4,2)="高新"),"奎文",IF(LEFT(G4,2)="峡山","坊子",IF(LEFT(G4,2)="滨海","寒亭",LEFT(G4,2)))) -> 奎文 | M4: =TEXT(B4,"mmdd") -> 0101 | N4: =VLOOKUP(I4,累计派单!A:O,15,0) -> dw3_jk_wangxingang | O4: =IF(LEN(J4)<2,0,DATEDIF(DATE(IF(MID(J4,9,2)="23",2023,2024),MID(J4,11,2),MID(J4,13,2)),B4,"d")) -> 2 | P4: =IF(O4=0,"无",IF(O4<8,"7天内",IF(O4<31,"30天内",IF(O4<61,"60天内",IF(O4<91,"90天内"))))) -> 7天内 | Q4: =VLOOKUP(I4,累计派单!A:O,13,0) -> 家客铁通潍坊奎文-北宫街城区装维组
A5: SD-db051-250101-172648-114 | B5: 2025-01-01 10:37:00 | C5: (家客)潍坊-临朐县-重复投诉投诉督办通知-一级督办18660665489-202501010000200739 | D5: 【调研】-普通区域-临朐县-城关王家楼小区-18660665489-200M-业务受理宽带-次数0-202501010000200739 | E5: 202501010000200739# 宽带账号:18660665489; 联系电话：18660665489，问题类型：此工单为群障修复工单，根据群障全量闭环修复管理要求，为确保客户网络通畅，请装维人员跟进修复网络问题，谢谢！ 群障标题：公告。故障描述：潍坊临朐县城关王家楼小区光缆故障，预估24小时恢复，请帮忙拦截,如有需要请联系片区装维师傅王兆兵15706307568主叫号码：18660665489.0;该号码仅供参考，请优先联系宽带账号。 | F5: 潍坊 | G5: 临朐县 | H5: 18660665489 | I5: SD-057-250101-847932-1270 | J5: 'SD-057-241219-791403-934' | K5: 是 | L5: =IF(OR(LEFT(G5,2)="高新"),"奎文",IF(LEFT(G5,2)="峡山","坊子",IF(LEFT(G5,2)="滨海","寒亭",LEFT(G5,2)))) -> 临朐 | M5: =TEXT(B5,"mmdd") -> 0101 | N5: =VLOOKUP(I5,累计派单!A:O,15,0) -> #N/A | O5: =IF(LEN(J5)<2,0,DATEDIF(DATE(IF(MID(J5,9,2)="23",2023,2024),MID(J5,11,2),MID(J5,13,2)),B5,"d")) -> 13 | P5: =IF(O5=0,"无",IF(O5<8,"7天内",IF(O5<31,"30天内",IF(O5<61,"60天内",IF(O5<91,"90天内"))))) -> 30天内 | Q5: =VLOOKUP(I5,累计派单!A:O,13,0) -> #N/A
A6: SD-db051-250101-683490-133 | B6: 2025-01-01 10:50:29 | C6: (家客)潍坊-坊子区-重复投诉投诉督办通知-一级督办18764639188-20250101104807X687351747 | D6: 80+银卡-普通区域-坊子区-营子花园-18764639188-1000M-魔百和投诉 | E6: 【农村网络投诉】【预处理派单】宽带账号：18764639188，宽带地址： 潍坊坊子区坊子新区辛李家村营子花园坊子营子花园3号楼*********，故障现象：，故障现象类型：，客户诉求：客户来点反应有部分频道缺失，操作了恢复出厂设置，没有恢复，请协助处理，谢谢，联系电话：18764639188，通话流水：2025010110395658720845521。接入方式：，当前是否在线：，端到端诊断结果：，是否智能网关：，光功率。,单组播状态:组播 | F6: 潍坊 | G6: 坊子区 | H6: 18764639188 | I6: SD-057-250101-503642-1409 | J6: 'SD-057-241230-724903-7676' | K6: 是 | L6: =IF(OR(LEFT(G6,2)="高新"),"奎文",IF(LEFT(G6,2)="峡山","坊子",IF(LEFT(G6,2)="滨海","寒亭",LEFT(G6,2)))) -> 坊子 | M6: =TEXT(B6,"mmdd") -> 0101 | N6: =VLOOKUP(I6,累计派单!A:O,15,0) -> dw3_jk_wangfufeng | O6: =IF(LEN(J6)<2,0,DATEDIF(DATE(IF(MID(J6,9,2)="23",2023,2024),MID(J6,11,2),MID(J6,13,2)),B6,"d")) -> 2 | P6: =IF(O6=0,"无",IF(O6<8,"7天内",IF(O6<31,"30天内",IF(O6<61,"60天内",IF(O6<91,"90天内"))))) -> 7天内 | Q6: =VLOOKUP(I6,累计派单!A:O,13,0) -> 家客铁通潍坊坊子-凤凰城区装维组
A7: SD-db051-250101-795423-183 | B7: 2025-01-01 12:24:27 | C7: (家客)潍坊-安丘市-重复投诉投诉督办通知-一级督办15169416903-202501010000293890 | D7: 普通区域-安丘市-于家河村自然村-15169416903-100M-宽带上网投诉-次数0-202501010000293890 | E7: 202501010000293890#宽带账号：15169416903；宽带地址：潍坊安丘市石埠子镇于家河村于家河村自然村于家河二次追加4号箱*****；客户来电反映宽带上网慢卡顿，测速1-2M，lan1端口1000M，经查询客户侧为质差路由器，请协助上门更换终端并一并处理故障问题，谢谢！ 联系电话：15169416903；联系人：先生；来电流水：2025010112221543720809124 | F7: 潍坊 | G7: 安丘市 | H7: 15169416903 | I7: SD-057-250101-927548-2247 | J7: 'SD-057-241004-169572-211' | K7: 否 | L7: =IF(OR(LEFT(G7,2)="高新"),"奎文",IF(LEFT(G7,2)="峡山","坊子",IF(LEFT(G7,2)="滨海","寒亭",LEFT(G7,2)))) -> 安丘 | M7: =TEXT(B7,"mmdd") -> 0101 | N7: =VLOOKUP(I7,累计派单!A:O,15,0) -> dw3_jk_juzhibin | O7: =IF(LEN(J7)<2,0,DATEDIF(DATE(IF(MID(J7,9,2)="23",2023,2024),MID(J7,11,2),MID(J7,13,2)),B7,"d")) -> 89 | P7: =IF(O7=0,"无",IF(O7<8,"7天内",IF(O7<31,"30天内",IF(O7<61,"60天内",IF(O7<91,"90天内"))))) -> 90天内 | Q7: =VLOOKUP(I7,累计派单!A:O,13,0) -> 家客铁通潍坊安丘-石埠子乡镇装维组
A8: SD-db051-250101-362178-214 | B8: 2025-01-01 13:03:55 | C8: (家客)潍坊-寿光市-重复投诉投诉督办通知-一级督办15753605816-202501010000321429 | D8: 【重投】-【调研】-80+普通-普通区域-寿光市-西稻田村自然村-15753605816-500M-宽带上网投诉-次数0-202501010000321429 | E8: 202501010000321429#流程受理流水号：20250101130138157536058161082732 客户号码:15753605816 客户姓名:宋** 投诉地市:潍坊 来话流水:2025010112580794320837705 宽带账号:15753605816 宽带账号归属地市:潍坊 宽带账号归属区县:寿光市 故障地址:潍坊寿光市稻田镇西稻田村西稻田村自然村扩容131号箱********* 联系电话:15753605816 联系人:先生/女士 工单紧急程度:一般 是否有升级投诉倾向:否 是否重复投诉:否 是否携转意向:否 是否投诉倾向:否 是否智能网关:智能网关 当前是否在线:否 接入方式:FTTH 端到端诊断结果:状态正常 是否质差终端:无质差信息 光功率:无 故障大类:宽带/电视 故障细类:宽带无法上网 携转原因: 故障时间:2025-01-01 13:01:53 具体故障现象:客户的宽带两天了完全没有网，要求维修人员处理。请协助谢谢提示网络无法连接， 客户其他诉求: ;宽带小区$[西稻田村自然村]$ | F8: 潍坊 | G8: 寿光市 | H8: 15753605816 | I8: SD-057-250101-019825-2563 | J8: 'SD-057-241105-729180-1524' | K8: 否 | L8: =IF(OR(LEFT(G8,2)="高新"),"奎文",IF(LEFT(G8,2)="峡山","坊子",IF(LEFT(G8,2)="滨海","寒亭",LEFT(G8,2)))) -> 寿光 | M8: =TEXT(B8,"mmdd") -> 0101 | N8: =VLOOKUP(I8,累计派单!A:O,15,0) -> dw3_jk_songyujie | O8: =IF(LEN(J8)<2,0,DATEDIF(DATE(IF(MID(J8,9,2)="23",2023,2024),MID(J8,11,2),MID(J8,13,2)),B8,"d")) -> 57 | P8: =IF(O8=0,"无",IF(O8<8,"7天内",IF(O8<31,"30天内",IF(O8<61,"60天内",IF(O8<91,"90天内"))))) -> 60天内 | Q8: =VLOOKUP(I8,累计派单!A:O,13,0) -> 家客铁通潍坊寿光-稻田乡镇装维组
A9: SD-db051-250101-958124-218 | B9: 2025-01-01 13:07:33 | C9: (家客)潍坊-高密市-重复投诉投诉督办通知-一级督办19558518557-202501010000325332 | D9: 普通区域-高密市-王家官庄自然村（夏庄恒馨家园）-19558518557-100M-业务受理宽带-次数0-202501010000325332 | E9: 202501010000325332# 宽带账号:19558518557; 联系电话：19558518557，问题类型：此工单为群障修复工单，根据群障全量闭环修复管理要求，为确保客户网络通畅，请装维人员跟进修复网络问题，谢谢！ 群障标题：公告。故障描述：潍坊高密市王家官庄自然村（夏庄恒馨家园）光缆故障，预估24小时恢复，请帮忙拦截,如有需要请联系片区装维师傅高强15706307285主叫号码：19558518557.0;该号码仅供参考，请优先联系宽带账号。 | F9: 潍坊 | G9: 高密市 | H9: 19558518557 | I9: SD-057-250101-043572-2594 | J9: 'SD-057-241024-908576-4509' | K9: 否 | L9: =IF(OR(LEFT(G9,2)="高新"),"奎文",IF(LEFT(G9,2)="峡山","坊子",IF(LEFT(G9,2)="滨海","寒亭",LEFT(G9,2)))) -> 高密 | M9: =TEXT(B9,"mmdd") -> 0101 | N9: =VLOOKUP(I9,累计派单!A:O,15,0) -> #N/A | O9: =IF(LEN(J9)<2,0,DATEDIF(DATE(IF(MID(J9,9,2)="23",2023,2024),MID(J9,11,2),MID(J9,13,2)),B9,"d")) -> 69 | P9: =IF(O9=0,"无",IF(O9<8,"7天内",IF(O9<31,"30天内",IF(O9<61,"60天内",IF(O9<91,"90天内"))))) -> 90天内 | Q9: =VLOOKUP(I9,累计派单!A:O,13,0) -> #N/A
A10: SD-db051-250101-657180-224 | B10: 2025-01-01 13:14:14 | C10: (家客)潍坊-诸城市-重复投诉投诉督办通知-一级督办18106368046-20250101131139X299254251 | D10: 【调研】-普通区域-诸城市-新郎公寓-18106368046-1000M-宽带上网投诉-次数0-20250101131139X299254251 | E10: 流程受理流水号：20250101131101181063680461085049 客户号码:18106368046 客户姓名:葛** 投诉地市:潍坊 来话流水:2025010113094220220839271 宽带账号:18106368046 宽带账号归属地市:潍坊 宽带账号归属区县:诸城市 故障地址:潍坊诸城市密州街道东外环新郎公寓L楼********* 联系电话:13356763517 联系人:先生 工单紧急程度:非常紧急 是否有升级投诉倾向:否 是否重复投诉:否 是否携转意向:否 是否投诉倾向:否 是否智能网关:智能网关 当前是否在线:是 接入方式:FTTH 端到端诊断结果:客户侧设备问题（新增） 是否质差终端:无质差信息 光功率:-18.38 故障大类:宽带/电视 故障细类:宽带无法上网(专席) 携转原因: 故障时间:2025-01-01 13:12:26 具体故障现象:光猫灯正常但电脑手机无法上网， 客户其他诉求: | F10: 潍坊 | G10: 诸城市 | H10: 18106368046 | I10: SD-057-250101-196537-2653 | J10: 'SD-057-241026-924351-6212' | K10: 否 | L10: =IF(OR(LEFT(G10,2)="高新"),"奎文",IF(LEFT(G10,2)="峡山","坊子",IF(LEFT(G10,2)="滨海","寒亭",LEFT(G10,2)))) -> 诸城 | M10: =TEXT(B10,"mmdd") -> 0101 | N10: =VLOOKUP(I10,累计派单!A:O,15,0) -> dw3_jk_shizhen | O10: =IF(LEN(J10)<2,0,DATEDIF(DATE(IF(MID(J10,9,2)="23",2023,2024),MID(J10,11,2),MID(J10,13,2)),B10,"d")) -> 67 | P10: =IF(O10=0,"无",IF(O10<8,"7天内",IF(O10<31,"30天内",IF(O10<61,"60天内",IF(O10<91,"90天内"))))) -> 90天内 | Q10: =VLOOKUP(I10,累计派单!A:O,13,0) -> 家客铁通潍坊诸城-兴华东路城区装维组
A11: SD-db051-250101-528340-230 | B11: 2025-01-01 13:25:50 | C11: (家客)潍坊-诸城市-重复投诉投诉督办通知-一级督办13953667855-202501010000333472 | D11: 【调研】-普通区域-诸城市-金屋小区北区-13953667855-300M-宽带上网投诉-次数0-202501010000333472 | E11: 202501010000333472#客户反映电视无法观看，提示蓝屏，不配合，线上排障未恢复，请协助处理。谢谢 联系人：女士 联系电话：13953667855 流水：2025010113223263220850457 | F11: 潍坊 | G11: 诸城市 | H11: 13953667855 | I11: SD-057-250101-681795-2746 | J11: 'SD-057-241031-481269-2245' | K11: 否 | L11: =IF(OR(LEFT(G11,2)="高新"),"奎文",IF(LEFT(G11,2)="峡山","坊子",IF(LEFT(G11,2)="滨海","寒亭",LEFT(G11,2)))) -> 诸城 | M11: =TEXT(B11,"mmdd") -> 0101 | N11: =VLOOKUP(I11,累计派单!A:O,15,0) -> dw3_jk_xuguodong | O11: =IF(LEN(J11)<2,0,DATEDIF(DATE(IF(MID(J11,9,2)="23",2023,2024),MID(J11,11,2),MID(J11,13,2)),B11,"d")) -> 62 | P11: =IF(O11=0,"无",IF(O11<8,"7天内",IF(O11<31,"30天内",IF(O11<61,"60天内",IF(O11<91,"90天内"))))) -> 90天内 | Q11: =VLOOKUP(I11,累计派单!A:O,13,0) -> 家客铁通潍坊诸城-兴华东路城区装维组
A12: SD-db051-250101-751439-247 | B12: 2025-01-01 14:03:30 | C12: (家客)潍坊-诸城市-重复投诉投诉督办通知-一级督办15006635638-202501010000359256 | D12: 【调研】-80+银卡-普通区域-诸城市-御台苑-15006635638-500M-宽带上网投诉-次数0-202501010000359256 | E12: 202501010000359256#宽带账号：15006635638；宽带地址：潍坊诸城舜王街道御台苑18号楼18号楼 3单元201；客户来电反映电视无法观看，要求师傅上门，请协助处理，谢谢！联系电话：15006635638；联系人：先生；来电流水：2025010113515884320818930。 | F12: 潍坊 | G12: 诸城市 | H12: 15006635638 | I12: SD-057-250101-283641-3107 | J12: 'SD-057-241018-538602-4457' | K12: 否 | L12: =IF(OR(LEFT(G12,2)="高新"),"奎文",IF(LEFT(G12,2)="峡山","坊子",IF(LEFT(G12,2)="滨海","寒亭",LEFT(G12,2)))) -> 诸城 | M12: =TEXT(B12,"mmdd") -> 0101 | N12: =VLOOKUP(I12,累计派单!A:O,15,0) -> dw3_jk_gaoyongkang | O12: =IF(LEN(J12)<2,0,DATEDIF(DATE(IF(MID(J12,9,2)="23",2023,2024),MID(J12,11,2),MID(J12,13,2)),B12,"d")) -> 75 | P12: =IF(O12=0,"无",IF(O12<8,"7天内",IF(O12<31,"30天内",IF(O12<61,"60天内",IF(O12<91,"90天内"))))) -> 90天内 | Q12: =VLOOKUP(I12,累计派单!A:O,13,0) -> 家客铁通潍坊诸城-经开区乡镇装维组
A13: SD-db051-250101-248791-249 | B13: 2025-01-01 14:05:39 | C13: (家客)潍坊-寒亭区-重复投诉投诉督办通知-一级督办17865609592-202501010000363427 | D13: 80+普通-普通区域-寒亭区-蔡家栏子小区-17865609592-1000M-宽带上网投诉-次数0-202501010000363427 | E13: 202501010000363427#流程受理流水号：20250101140451178656095921098738 客户号码:17865609592 客户姓名:邵** 投诉地市:潍坊 来话流水:2025010113544363020845912 宽带账号:17865609592 宽带账号归属地市:潍坊 宽带账号归属区县:寒亭区 故障地址:潍坊寒亭区泊子镇泊南路蔡家栏子小区92号楼箱蔡家春外墙********* 联系电话:15169608022 联系人:先生/女士 工单紧急程度:紧急 是否有升级投诉倾向:否 是否重复投诉:否 是否携转意向:否 是否投诉倾向:否 是否智能网关:智能网关 当前是否在线:是 接入方式:FTTH 端到端诊断结果:客户侧设备问题（新增） 是否质差终端:无质差信息 光功率:-14.78 故障大类:宽带/电视 故障细类:网速慢/上网掉线(专席) 携转原因: 故障时间:2025-01-01 13:59:46 具体故障现象:网速慢卡顿， 客户其他诉求:请审核 ;宽带小区$[蔡家栏子小区]$ | F13: 潍坊 | G13: 寒亭区 | H13: 17865609592 | I13: SD-057-250101-741529-3124 | J13: 'SD-057-241016-462137-2911' | K13: 否 | L13: =IF(OR(LEFT(G13,2)="高新"),"奎文",IF(LEFT(G13,2)="峡山","坊子",IF(LEFT(G13,2)="滨海","寒亭",LEFT(G13,2)))) -> 寒亭 | M13: =TEXT(B13,"mmdd") -> 0101 | N13: =VLOOKUP(I13,累计派单!A:O,15,0) -> dw3_jk_wangweiwei | O13: =IF(LEN(J13)<2,0,DATEDIF(DATE(IF(MID(J13,9,2)="23",2023,2024),MID(J13,11,2),MID(J13,13,2)),B13,"d")) -> 77 | P13: =IF(O13=0,"无",IF(O13<8,"7天内",IF(O13<31,"30天内",IF(O13<61,"60天内",IF(O13<91,"90天内"))))) -> 90天内 | Q13: =VLOOKUP(I13,累计派单!A:O,13,0) -> 家客铁通潍坊寒亭-固高乡镇装维组
... A87: SD-db051-250104-324098-36 | B87: 2025-01-04 09:00:12 | C87: (家客)潍坊-安丘市-重复投诉投诉督办通知-一级督办15653430270-202501040000114033 | D87: 普通区域-安丘市-夹埠村自然村-15653430270-300M-宽带上网投诉-次数0-202501040000114033 | E87: 202501040000114033#流程受理流水号：20250104085921156534302701009734 客户号码:15653430270 客户姓名:刘** 投诉地市:潍坊 来话流水:2025010408585532720832962 宽带账号:15653430270 账号归属区县:潍坊-昌乐-全福元网格-全福元中潍委托 联系电话:15653430270 联系人:先生/女士 宽带地址:潍坊 工单紧急程度:一般 是否投诉倾向:否 是否重复投诉:否 是否携转意向:否 是否有升级投诉倾向:否 *业务名称:业务融合开机流程宽带 投诉内容:手机号码：15653430270，【问题描述】客户已办理宽带业务，有开通单，要求装维尽快联系上门，请处理，谢谢。联系电话：15653430270，联系人：先生/女士，录音流水号：2025010408585532720832962。受理明细：531920062399999999。 在途开通单信息：536241122710709652，15653430270，2024-11-22 14:07:01，业务融合开机流程宽带，处理中，装维选址 是否到厅:否 业务名称:业务融合开机流程宽带 ;宽带小区$[夹埠村自然村]$ | F87: 潍坊 | G87: 安丘市 | H87: 15653430270 | I87: SD-057-250104-092473-405 | J87: 'SD-057-241130-653017-4809' | K87: 是 | L87: =IF(OR(LEFT(G87,2)="高新"),"奎文",IF(LEFT(G87,2)="峡山","坊子",IF(LEFT(G87,2)="滨海","寒亭",LEFT(G87,2)))) -> 安丘 | M87: =TEXT(B87,"mmdd") -> 0104 | N87: =VLOOKUP(I87,累计派单!A:O,15,0) -> dw3_jk_liutongtong | O87: =IF(LEN(J87)<2,0,DATEDIF(DATE(IF(MID(J87,9,2)="23",2023,2024),MID(J87,11,2),MID(J87,13,2)),B87,"d")) -> 35 | P87: =IF(O87=0,"无",IF(O87<8,"7天内",IF(O87<31,"30天内",IF(O87<61,"60天内",IF(O87<91,"90天内"))))) -> 60天内 | Q87: =VLOOKUP(I87,累计派单!A:O,13,0) -> 家客铁通潍坊安丘-贾戈乡镇装维组
A88: SD-db051-250104-546290-37 | B88: 2025-01-04 09:02:23 | C88: (家客)潍坊--重复投诉投诉督办通知-一级督办13562697156-202501040000118386 | D88: 普通区域--null-13562697156-宽带上网投诉-次数0-202501040000118386 | E88: 202501040000118386#流程受理流水号：20250104090114135626971561010353 客户号码:13562697156 客户姓名:王** 投诉地市:潍坊 来话流水:2025010409004447920850038 宽带账号:13562697156 账号归属区县:潍坊-坊子-凤凰网格-吉客便利店 联系电话:13562697156 联系人:先生 宽带地址:潍坊 工单紧急程度:一般 是否投诉倾向:否 是否重复投诉:否 是否携转意向:否 是否有升级投诉倾向:否 *业务名称:业务融合开机流程宽带 投诉内容:手机号码：13562697156，【问题描述】客户已办理宽带业务，有开通单，要求装维尽快联系上门，请处理，谢谢。联系电话：13562697156，联系人：先生，录音流水号：2025010409004447920850038。受理明细：531920062399999999。 在途开通单信息：536241230852788118，13562697156，2024-12-30 12:17:59，业务融合开机流程宽带，处理中，黄单扩容 是否到厅:否 业务名称:业务融合开机流程宽带 ;宽带小区$[null]$ | F88: 潍坊 | H88: 13562697156 | I88: SD-057-250104-018529-422 | J88: 'SD-057-250101-425139-1028' | K88: 是 | L88: =IF(OR(LEFT(G88,2)="高新"),"奎文",IF(LEFT(G88,2)="峡山","坊子",IF(LEFT(G88,2)="滨海","寒亭",LEFT(G88,2)))) | M88: =TEXT(B88,"mmdd") -> 0104 | N88: =VLOOKUP(I88,累计派单!A:O,15,0) -> wangkunwf | O88: =IF(LEN(J88)<2,0,DATEDIF(DATE(IF(MID(J88,9,2)="23",2023,2024),MID(J88,11,2),MID(J88,13,2)),B88,"d")) -> 369 | P88: =IF(O88=0,"无",IF(O88<8,"7天内",IF(O88<31,"30天内",IF(O88<61,"60天内",IF(O88<91,"90天内"))))) -> FALSE | Q88: =VLOOKUP(I88,累计派单!A:O,13,0) -> 0
A89: SD-db051-250104-307829-51 | B89: 2025-01-04 09:17:35 | C89: (家客)潍坊-潍城区-重复投诉投诉督办通知-一级督办13562697000-202501040000129163 | D89: 【调研】-80+普通-普通区域-潍城区-大庄子-13562697000-200M-宽带上网投诉-次数0-202501040000129163 | E89: 202501040000129163#流程受理流水号：20250104091537135626970001015157 客户号码:13562697000 客户姓名:刘** 投诉地市:潍坊 来话流水:2025010409150229320811002 宽带账号:13562697000 宽带账号归属地市:潍坊 宽带账号归属区县:潍城区 故障地址:潍坊潍城区南关街道宝通街大庄子7号楼********* 联系电话:18854323019 联系人:先生/女士 工单紧急程度:一般 是否有升级投诉倾向:否 是否重复投诉:否 是否携转意向:否 是否投诉倾向:否 是否智能网关:智能网关 当前是否在线:是 接入方式:FTTH 端到端诊断结果:客户侧设备问题（新增） 是否质差终端:无质差信息 光功率:-23.76 故障大类:宽带/电视 故障细类:宽带无法上网 携转原因: 故障时间:2025-01-04 09:25:10 具体故障现象:用户无法提供具体故障现象， 客户其他诉求: ;宽带小区$[大庄子]$ | F89: 潍坊 | G89: 潍城区 | H89: 13562697000 | I89: SD-057-250104-405671-571 | J89: 'SD-057-250103-857412-5505' | K89: 是 | L89: =IF(OR(LEFT(G89,2)="高新"),"奎文",IF(LEFT(G89,2)="峡山","坊子",IF(LEFT(G89,2)="滨海","寒亭",LEFT(G89,2)))) -> 潍城 | M89: =TEXT(B89,"mmdd") -> 0104 | N89: =VLOOKUP(I89,累计派单!A:O,15,0) -> dw3_jk_wcliuchao | O89: =IF(LEN(J89)<2,0,DATEDIF(DATE(IF(MID(J89,9,2)="23",2023,2024),MID(J89,11,2),MID(J89,13,2)),B89,"d")) -> 367 | P89: =IF(O89=0,"无",IF(O89<8,"7天内",IF(O89<31,"30天内",IF(O89<61,"60天内",IF(O89<91,"90天内"))))) -> FALSE | Q89: =VLOOKUP(I89,累计派单!A:O,13,0) -> 家客铁通潍坊潍城-胜利街城区装维组
A90: SD-db051-250104-873461-69 | B90: 2025-01-04 09:37:24 | C90: (家客)潍坊-寿光市-重复投诉投诉督办通知-一级督办18766892197-202501040000149608 | D90: 普通区域-寿光市-田二村自然村-18766892197-300M-业务受理宽带-次数0-202501040000149608 | E90: 202501040000149608# 宽带账号:18766892197; 联系电话：18766892197，问题类型：此工单为群障修复工单，根据群障全量闭环修复管理要求，为确保客户网络通畅，请装维人员跟进修复网络问题，谢谢！ 群障标题：公告。故障描述：潍坊寿光市田二村自然村光缆故障，预估24小时恢复，请帮忙拦截,如有需要请联系片区装维师傅王兵15706307817主叫号码：18766892197.0;该号码仅供参考，请优先联系宽带账号。 | F90: 潍坊 | G90: 寿光市 | H90: 18766892197 | I90: SD-057-250104-697348-776 | J90: 'SD-057-250103-642831-2219' | K90: 是 | L90: =IF(OR(LEFT(G90,2)="高新"),"奎文",IF(LEFT(G90,2)="峡山","坊子",IF(LEFT(G90,2)="滨海","寒亭",LEFT(G90,2)))) -> 寿光 | M90: =TEXT(B90,"mmdd") -> 0104 | N90: =VLOOKUP(I90,累计派单!A:O,15,0) -> dw3_jk_wangbing | O90: =IF(LEN(J90)<2,0,DATEDIF(DATE(IF(MID(J90,9,2)="23",2023,2024),MID(J90,11,2),MID(J90,13,2)),B90,"d")) -> 367 | P90: =IF(O90=0,"无",IF(O90<8,"7天内",IF(O90<31,"30天内",IF(O90<61,"60天内",IF(O90<91,"90天内"))))) -> FALSE | Q90: =VLOOKUP(I90,累计派单!A:O,13,0) -> 家客铁通潍坊寿光-稻田乡镇装维组
A91: SD-db051-250104-926540-72 | B91: 2025-01-04 09:37:58 | C91: (家客)潍坊-奎文区-重复投诉投诉督办通知-一级督办15169562082-202501040000148678 | D91: 80+银卡-普通区域-奎文区-世纪花苑-15169562082-1000M-业务受理宽带-次数0-202501040000148678 | E91: 202501040000148678#【已关注中国移动10086微信公众号】 宽带账号:15169562082; 联系电话：15169562082，问题类型：此工单为群障修复工单，根据群障全量闭环修复管理要求，为确保客户网络通畅，请装维人员跟进修复网络问题，谢谢！ 群障标题：公告。故障描述：潍坊奎文区世纪花苑光缆故障，预估24小时恢复，请帮忙拦截,如有需要请联系片区装维师傅张永鸿15706366537主叫号码：15169562082.0;该号码仅供参考，请优先联系宽带账号。 | F91: 潍坊 | G91: 奎文区 | H91: 15169562082 | I91: SD-057-250104-214638-792 | J91: 'SD-057-250103-492305-240' | K91: 是 | L91: =IF(OR(LEFT(G91,2)="高新"),"奎文",IF(LEFT(G91,2)="峡山","坊子",IF(LEFT(G91,2)="滨海","寒亭",LEFT(G91,2)))) -> 奎文 | M91: =TEXT(B91,"mmdd") -> 0104 | N91: =VLOOKUP(I91,累计派单!A:O,15,0) -> dw3_jk_zhangyonghong | O91: =IF(LEN(J91)<2,0,DATEDIF(DATE(IF(MID(J91,9,2)="23",2023,2024),MID(J91,11,2),MID(J91,13,2)),B91,"d")) -> 367 | P91: =IF(O91=0,"无",IF(O91<8,"7天内",IF(O91<31,"30天内",IF(O91<61,"60天内",IF(O91<91,"90天内"))))) -> FALSE | Q91: =VLOOKUP(I91,累计派单!A:O,13,0) -> 家客铁通潍坊奎文-鸢飞路城区装维组
A92: SD-db051-250104-673589-112 | B92: 2025-01-04 10:26:20 | C92: (家客)潍坊-潍城区-重复投诉投诉督办通知-一级督办13963657285-202501040000199165 | D92: 【调研】-80+银卡-普通区域-潍城区-鲁发名城西区-13963657285-1000M-魔百和投诉-次数0-202501040000199165 | E92: 202501040000199165#客户来电投诉 潍城和平路营业厅 客户表示前期机顶盒不好用了营业厅给更换 新的需要缴纳100元对此不满 （客户换了个旧的未收钱）客户表示每个月都收取移动高清（智能版）13元/月 更换时新的也不应该收取费用 我处已按口径解释，客户不满，请协助处理，谢谢！流水2025010410152929420826793 | F92: 潍坊 | G92: 潍城区 | H92: 13963657285 | I92: SD-057-250104-083945-1272 | J92: 'SD-057-241223-931865-479' | K92: 是 | L92: =IF(OR(LEFT(G92,2)="高新"),"奎文",IF(LEFT(G92,2)="峡山","坊子",IF(LEFT(G92,2)="滨海","寒亭",LEFT(G92,2)))) -> 潍城 | M92: =TEXT(B92,"mmdd") -> 0104 | N92: =VLOOKUP(I92,累计派单!A:O,15,0) -> dw3_jk_yaoguoqiang | O92: =IF(LEN(J92)<2,0,DATEDIF(DATE(IF(MID(J92,9,2)="23",2023,2024),MID(J92,11,2),MID(J92,13,2)),B92,"d")) -> 12 | P92: =IF(O92=0,"无",IF(O92<8,"7天内",IF(O92<31,"30天内",IF(O92<61,"60天内",IF(O92<91,"90天内"))))) -> 30天内 | Q92: =VLOOKUP(I92,累计派单!A:O,13,0) -> 家客铁通潍坊潍城-东风街城区装维组
A93: SD-db051-250104-397504-116 | B93: 2025-01-04 10:27:44 | C93: (家客)潍坊-潍城区-重复投诉投诉督办通知-一级督办18806365639-202501040000205383 | D93: 【调研】-80+银卡-普通区域-潍城区-南季自然村-18806365639-300M-业务受理宽带-次数0-202501040000205383 | E93: 202501040000205383# 宽带账号:18806365639; 联系电话：18806365639，问题类型：此工单为群障修复工单，根据群障全量闭环修复管理要求，为确保客户网络通畅，请装维人员跟进修复网络问题，谢谢！ 群障标题：公告。故障描述：潍坊潍城区南季自然村光缆故障，预估24小时恢复，请帮忙拦截,如有需要请联系片区装维师傅张翔宇15706307859主叫号码：18806365639.0;该号码仅供参考，请优先联系宽带账号。 | F93: 潍坊 | G93: 潍城区 | H93: 18806365639 | I93: SD-057-250104-856047-1301 | J93: 'SD-057-250103-983174-6155' | K93: 是 | L93: =IF(OR(LEFT(G93,2)="高新"),"奎文",IF(LEFT(G93,2)="峡山","坊子",IF(LEFT(G93,2)="滨海","寒亭",LEFT(G93,2)))) -> 潍城 | M93: =TEXT(B93,"mmdd") -> 0104 | N93: =VLOOKUP(I93,累计派单!A:O,15,0) -> dw3_jk_wczhangxiangyu | O93: =IF(LEN(J93)<2,0,DATEDIF(DATE(IF(MID(J93,9,2)="23",2023,2024),MID(J93,11,2),MID(J93,13,2)),B93,"d")) -> 367 | P93: =IF(O93=0,"无",IF(O93<8,"7天内",IF(O93<31,"30天内",IF(O93<61,"60天内",IF(O93<91,"90天内"))))) -> FALSE | Q93: =VLOOKUP(I93,累计派单!A:O,13,0) -> 家客铁通潍坊潍城-胜利街城区装维组
A94: SD-db051-250104-398716-130 | B94: 2025-01-04 10:43:39 | C94: (家客)潍坊-安丘市-重复投诉投诉督办通知-一级督办18453631559-202501040000223118 | D94: 普通区域-安丘市-青云瑞景园(含锦绣上河园)-18453631559-100M-宽带上网投诉-次数0-202501040000223118 | E94: 202501040000223118#18453631559客户来电反映宽带无法使用，卡顿。慢。延迟高，线上排障不认可，客户表示多次来电修复，重启，客户表示未解决！要求维修人员上门维修，请尽快协助处理，谢谢 联系人：先生 联系电话：本机 来电流水：）来话流水2025010410390434220865030 | F94: 潍坊 | G94: 安丘市 | H94: 18453631559 | I94: SD-057-250104-123678-1487 | J94: 'SD-057-241110-934185-6546' | K94: 是 | L94: =IF(OR(LEFT(G94,2)="高新"),"奎文",IF(LEFT(G94,2)="峡山","坊子",IF(LEFT(G94,2)="滨海","寒亭",LEFT(G94,2)))) -> 安丘 | M94: =TEXT(B94,"mmdd") -> 0104 | N94: =VLOOKUP(I94,累计派单!A:O,15,0) -> dw3_jk_chenyujun | O94: =IF(LEN(J94)<2,0,DATEDIF(DATE(IF(MID(J94,9,2)="23",2023,2024),MID(J94,11,2),MID(J94,13,2)),B94,"d")) -> 55 | P94: =IF(O94=0,"无",IF(O94<8,"7天内",IF(O94<31,"30天内",IF(O94<61,"60天内",IF(O94<91,"90天内"))))) -> 60天内 | Q94: =VLOOKUP(I94,累计派单!A:O,13,0) -> 家客铁通潍坊安丘-贾戈乡镇装维组
A95: SD-db051-250104-391786-132 | B95: 2025-01-04 10:47:08 | C95: (家客)潍坊-诸城市-重复投诉投诉督办通知-一级督办13791882713-20250104104438X678546266 | D95: FTTR-普通区域-诸城市-金东世纪城-13791882713-1000M-宽带上网投诉-次数0-20250104104438X678546266 | E95: 流程受理流水号：20250104104035137918827131047296 客户号码:13791882713 客户姓名:刘** 投诉地市:潍坊 来话流水:2025010410375796520849253 宽带账号:13791882713 宽带账号归属地市:潍坊 宽带账号归属区县:诸城市 故障地址:潍坊诸城市密州街道东武街金东世纪城18号楼********* 联系电话:13791882713 联系人:先生/女士 工单紧急程度:非常紧急 是否有升级投诉倾向:否 是否重复投诉:否 是否携转意向:否 是否投诉倾向:否 是否智能网关:智能网关 当前是否在线:是 接入方式:-- 端到端诊断结果:客户侧设备问题（新增） 是否质差终端:无质差信息 光功率:-21.36 故障大类:宽带/电视 故障细类:宽带网速慢/卡顿 携转原因: 故障时间:2025-01-04 10:43:02 网站/APP/游戏名称:刷视频 具体故障现象:网速慢卡顿， 客户其他诉求: | F95: 潍坊 | G95: 诸城市 | H95: 13791882713 | I95: SD-057-250104-028361-1510 | J95: 'SD-057-241006-385469-5692' | K95: 是 | L95: =IF(OR(LEFT(G95,2)="高新"),"奎文",IF(LEFT(G95,2)="峡山","坊子",IF(LEFT(G95,2)="滨海","寒亭",LEFT(G95,2)))) -> 诸城 | M95: =TEXT(B95,"mmdd") -> 0104 | N95: =VLOOKUP(I95,累计派单!A:O,15,0) -> dw3_jk_suidongwei | O95: =IF(LEN(J95)<2,0,DATEDIF(DATE(IF(MID(J95,9,2)="23",2023,2024),MID(J95,11,2),MID(J95,13,2)),B95,"d")) -> 90 | P95: =IF(O95=0,"无",IF(O95<8,"7天内",IF(O95<31,"30天内",IF(O95<61,"60天内",IF(O95<91,"90天内"))))) -> 90天内 | Q95: =VLOOKUP(I95,累计派单!A:O,13,0) -> 家客铁通潍坊诸城-繁荣路城区装维组
A96: SD-db051-250104-526048-138 | B96: 2025-01-04 10:50:24 | C96: (家客)潍坊--重复投诉投诉督办通知-一级督办18953660076-202501040000230777 | D96: 普通区域--null-18953660076-宽带上网投诉-次数0-202501040000230777 | E96: 202501040000230777#流程受理流水号：20250104104953189536600761050759 客户号码:18953660076 客户姓名:王** 投诉地市:潍坊 来话流水:2025010410472076120883690 宽带账号:18953660076 账号归属区县:开发区-城区-潍坊高新区弘毅手机通讯店 联系电话:13020591569 联系人:先生/女士 宽带地址:潍坊 工单紧急程度:一般 是否投诉倾向:否 是否重复投诉:否 是否携转意向:否 是否有升级投诉倾向:否 *业务名称:业务融合开机流程宽带+OTT 投诉内容:手机号码：18953660076，【问题描述】客户已办理宽带业务，有开通单，要求装维尽快联系上门，请处理，谢谢。联系电话：13020591569，联系人：先生/女士，录音流水号：2025010410472076120883690。受理明细：531920062399999999。 在途开通单信息：536250104110475424，18953660076，2025-01-04 10:34:47，业务融合开机流程宽带+OTT，处理中，手写判断和地址录入 是否到厅:否 业务名称:业务融合开机流程宽带+OTT ;宽带小区$[null]$ | F96: 潍坊 | H96: 18953660076 | I96: SD-057-250104-294807-1553 | J96: 'SD-057-250103-148562-344' | K96: 否 | L96: =IF(OR(LEFT(G96,2)="高新"),"奎文",IF(LEFT(G96,2)="峡山","坊子",IF(LEFT(G96,2)="滨海","寒亭",LEFT(G96,2)))) | M96: =TEXT(B96,"mmdd") -> 0104 | N96: =VLOOKUP(I96,累计派单!A:O,15,0) -> wangkunwf | O96: =IF(LEN(J96)<2,0,DATEDIF(DATE(IF(MID(J96,9,2)="23",2023,2024),MID(J96,11,2),MID(J96,13,2)),B96,"d")) -> 367 | P96: =IF(O96=0,"无",IF(O96<8,"7天内",IF(O96<31,"30天内",IF(O96<61,"60天内",IF(O96<91,"90天内"))))) -> FALSE | Q96: =VLOOKUP(I96,累计派单!A:O,13,0) -> 0
A97: SD-db051-250104-736419-143 | B97: 2025-01-04 10:57:32 | C97: (家客)潍坊-寒亭区-重复投诉投诉督办通知-一级督办15863615468-202501040000240291 | D97: 普通区域-寒亭区-蔡家栏子小区-15863615468-100M-业务受理宽带-次数0-202501040000240291 | E97: 202501040000240291# 宽带账号:15863615468; 联系电话：15863615468，问题类型：此工单为群障修复工单，根据群障全量闭环修复管理要求，为确保客户网络通畅，请装维人员跟进修复网络问题，谢谢！ 群障标题：公告。故障描述：潍坊寒亭区蔡家栏子小区光缆故障，预估24小时恢复，请帮忙拦截,如有需要请联系片区装维师傅王伟伟15706307460主叫号码：15863615468.0;该号码仅供参考，请优先联系宽带账号。 | F97: 潍坊 | G97: 寒亭区 | H97: 15863615468 | I97: SD-057-250104-132864-1616 | J97: 'SD-057-241103-283659-7245' | K97: 是 | L97: =IF(OR(LEFT(G97,2)="高新"),"奎文",IF(LEFT(G97,2)="峡山","坊子",IF(LEFT(G97,2)="滨海","寒亭",LEFT(G97,2)))) -> 寒亭 | M97: =TEXT(B97,"mmdd") -> 0104 | N97: =VLOOKUP(I97,累计派单!A:O,15,0) -> dw3_jk_wangweiwei | O97: =IF(LEN(J97)<2,0,DATEDIF(DATE(IF(MID(J97,9,2)="23",2023,2024),MID(J97,11,2),MID(J97,13,2)),B97,"d")) -> 62 | P97: =IF(O97=0,"无",IF(O97<8,"7天内",IF(O97<31,"30天内",IF(O97<61,"60天内",IF(O97<91,"90天内"))))) -> 90天内 | Q97: =VLOOKUP(I97,累计派单!A:O,13,0) -> 家客铁通潍坊寒亭-固高乡镇装维组
A98: SD-db051-250104-431795-151 | B98: 2025-01-04 11:05:57 | C98: (家客)潍坊-寒亭区-重复投诉投诉督办通知-一级督办13869623195-202501040000248302 | D98: 普通区域-寒亭区-锦程中学宿舍-13869623195-100M-宽带上网投诉-次数0-202501040000248302 | E98: 202501040000248302#流程受理流水号：20250104110212138696231951055576 客户号码:13869623195 客户姓名:刘** 投诉地市:潍坊 来话流水:2025010411011528720882243 宽带账号:13869623195 宽带账号归属地市:潍坊 宽带账号归属区县:寒亭区 故障地址:潍坊寒亭区经济开发区月河路锦程中学宿舍1号楼********* 联系电话:13869623195 联系人:先生/女士 工单紧急程度:一般 是否有升级投诉倾向:否 是否重复投诉:否 是否携转意向:否 是否投诉倾向:否 是否智能网关:智能网关 当前是否在线:否 接入方式:FTTH 端到端诊断结果:状态正常 是否质差终端:无质差信息 光功率:无 故障大类:宽带/电视 故障细类:宽带无法上网 携转原因: 故障时间:2025-01-04 11:01:56 具体故障现象:提示网络无法连接， 客户其他诉求: ;宽带小区$[锦程中学宿舍]$ | F98: 潍坊 | G98: 寒亭区 | H98: 13869623195 | I98: SD-057-250104-273104-1723 | J98: 'SD-057-250103-273145-3993' | K98: 是 | L98: =IF(OR(LEFT(G98,2)="高新"),"奎文",IF(LEFT(G98,2)="峡山","坊子",IF(LEFT(G98,2)="滨海","寒亭",LEFT(G98,2)))) -> 寒亭 | M98: =TEXT(B98,"mmdd") -> 0104 | N98: =VLOOKUP(I98,累计派单!A:O,15,0) -> dw3_jk_liyuan | O98: =IF(LEN(J98)<2,0,DATEDIF(DATE(IF(MID(J98,9,2)="23",2023,2024),MID(J98,11,2),MID(J98,13,2)),B98,"d")) -> 367 | P98: =IF(O98=0,"无",IF(O98<8,"7天内",IF(O98<31,"30天内",IF(O98<61,"60天内",IF(O98<91,"90天内"))))) -> FALSE | Q98: =VLOOKUP(I98,累计派单!A:O,13,0) -> 家客铁通潍坊寒亭-开发区乡镇装维组
A99: SD-db051-250104-642895-154 | B99: 2025-01-04 11:08:15 | C99: (家客)潍坊-奎文区-重复投诉投诉督办通知-一级督办15806483000-20250104110349X829853776 | D99: 80+银卡-普通区域-奎文区-金鼎华府-15806483000-300M-宽带上网投诉-次数0-20250104110349X829853776 | E99: 流程受理流水号：20250103133856158064830001102152 客户号码:15806483000 客户姓名:田* 投诉地市:潍坊 来话流水:2025010313362065420816638 宽带账号:15806483000 宽带账号归属地市:潍坊 宽带账号归属区县:奎文区 故障地址:潍坊奎文区大虞街道鸢飞路金鼎华府6号楼********* 联系电话:15806483000 联系人:先生/女士 工单紧急程度:一般 是否有升级投诉倾向:否 是否重复投诉:否 是否携转意向:否 是否投诉倾向:否 是否智能网关:智能网关 当前是否在线:否 接入方式:FTTH 端到端诊断结果:大面积故障 是否质差终端:无质差信息 光功率:无 故障大类:宽带/电视 故障细类:宽带无法上网 携转原因: 故障时间:2025-01-03 13:39:28 具体故障现象:光猫亮红灯， 客户其他诉求: 前期工单20250103134017X817138296，要求继续处理，谢谢 | F99: 潍坊 | G99: 奎文区 | H99: 15806483000 | I99: SD-057-250104-073421-1766 | J99: 'SD-057-250103-783015-2547' | K99: 是 | L99: =IF(OR(LEFT(G99,2)="高新"),"奎文",IF(LEFT(G99,2)="峡山","坊子",IF(LEFT(G99,2)="滨海","寒亭",LEFT(G99,2)))) -> 奎文 | M99: =TEXT(B99,"mmdd") -> 0104 | N99: =VLOOKUP(I99,累计派单!A:O,15,0) -> dw3_jk_renfeng | O99: =IF(LEN(J99)<2,0,DATEDIF(DATE(IF(MID(J99,9,2)="23",2023,2024),MID(J99,11,2),MID(J99,13,2)),B99,"d")) -> 367 | P99: =IF(O99=0,"无",IF(O99<8,"7天内",IF(O99<31,"30天内",IF(O99<61,"60天内",IF(O99<91,"90天内"))))) -> FALSE | Q99: =VLOOKUP(I99,累计派单!A:O,13,0) -> 家客铁通潍坊奎文-鸢飞路城区装维组
A100: SD-db051-250104-913672-155 | B100: 2025-01-04 11:08:46 | C100: (家客)潍坊-高密市-重复投诉投诉督办通知-一级督办18863647333-202501040000250943 | D100: 【调研】-80+金卡-普通区域-高密市-书香漫步-18863647333-1000M-宽带上网投诉-次数0-202501040000250943 | E100: 202501040000250943#【已关注中国移动10086微信公众号】流程受理流水号：20250104110639188636473331057311 客户号码:18863647333 客户姓名:李* 投诉地市:潍坊 来话流水:2025010411004360620874673 宽带账号:18863647333 宽带账号归属地市:潍坊 宽带账号归属区县:高密市 故障地址:潍坊高密市醴泉街道站南街书香漫步6号楼********* 联系电话:18863647333 联系人:先生 工单紧急程度:非常紧急 是否有升级投诉倾向:否 是否重复投诉:否 是否携转意向:否 是否投诉倾向:否 是否智能网关:智能网关 当前是否在线:是 接入方式:FTTH 端到端诊断结果:客户侧设备问题（新增） 是否质差终端:无质差信息 光功率:-21.24 故障大类:宽带/电视 故障细类:网速慢/上网掉线(专席) 携转原因: 故障时间:2025-01-04 11:10:36 具体故障现象:网速慢卡顿， 客户其他诉求:客户拒绝联系工作人员过去排查，并要求解决宽带网速慢的问题，请协助处理，谢谢 ;宽带小区$[书香漫步]$ | F100: 潍坊 | G100: 高密市 | H100: 18863647333 | I100: SD-057-250104-702368-1777 | J100: 'SD-057-241220-851467-5701' | K100: 否 | L100: =IF(OR(LEFT(G100,2)="高新"),"奎文",IF(LEFT(G100,2)="峡山","坊子",IF(LEFT(G100,2)="滨海","寒亭",LEFT(G100,2)))) -> 高密 | M100: =TEXT(B100,"mmdd") -> 0104 | N100: =VLOOKUP(I100,累计派单!A:O,15,0) -> dw3_jk_liuzhigang | O100: =IF(LEN(J100)<2,0,DATEDIF(DATE(IF(MID(J100,9,2)="23",2023,2024),MID(J100,11,2),MID(J100,13,2)),B100,"d")) -> 15 | P100: =IF(O100=0,"无",IF(O100<8,"7天内",IF(O100<31,"30天内",IF(O100<61,"60天内",IF(O100<91,"90天内"))))) -> 30天内 | Q100: =VLOOKUP(I100,累计派单!A:O,13,0) -> 家客铁通潍坊高密-朝阳城区装维组
A101: SD-db051-250104-952648-178 | B101: 2025-01-04 11:39:15 | C101: (家客)潍坊-青州市-重复投诉投诉督办通知-一级督办13455683982-202501040000278356 | D101: 【调研】-80+银卡-普通区域-青州市-东郝村自然村-13455683982-300M-宽带上网投诉-次数0-202501040000278356 | E101: 202501040000278356#13455683982客户来电表示线路全部拔掉了 客户无法自行安装 要求师傅上门 请尽快处理 谢谢 联系人：先生 联系电话：13455683982 来电流水：2025010411341478520847139 | F101: 潍坊 | G101: 青州市 | H101: 13455683982 | I101: SD-057-250104-837269-2047 | J101: 'SD-057-241105-790162-2543' | K101: 否 | L101: =IF(OR(LEFT(G101,2)="高新"),"奎文",IF(LEFT(G101,2)="峡山","坊子",IF(LEFT(G101,2)="滨海","寒亭",LEFT(G101,2)))) -> 青州 | M101: =TEXT(B101,"mmdd") -> 0104 | N101: =VLOOKUP(I101,累计派单!A:O,15,0) -> 0 | O101: =IF(LEN(J101)<2,0,DATEDIF(DATE(IF(MID(J101,9,2)="23",2023,2024),MID(J101,11,2),MID(J101,13,2)),B101,"d")) -> 60 | P101: =IF(O101=0,"无",IF(O101<8,"7天内",IF(O101<31,"30天内",IF(O101<61,"60天内",IF(O101<91,"90天内"))))) -> 60天内 | Q101: =VLOOKUP(I101,累计派单!A:O,13,0) -> 家客铁通潍坊青州-谭坊乡镇装维组
A102: SD-db051-250104-053729-225 | B102: 2025-01-04 12:41:12 | C102: (家客)潍坊-寒亭区-重复投诉投诉督办通知-一级督办15963645371-20250104124032X632172397 | D102: 【调研】-80+普通-普通区域-寒亭区-海盛花苑小区-15963645371-1000M-宽带上网投诉-次数0-20250104124032X632172397 | E102: 流程受理流水号：20250104123509159636453711086288 客户号码:15963645371 客户姓名:张** 投诉地市:潍坊 来话流水:2025010412344224520891362 宽带账号:15963645371 宽带账号归属地市:潍坊 宽带账号归属区县:寒亭区 故障地址:潍坊寒亭区寒亭街道丰华路海盛花苑小区6号楼********* 联系电话:15963645371 联系人:先生/女士 工单紧急程度:非常紧急 是否有升级投诉倾向:否 是否重复投诉:否 是否携转意向:否 是否投诉倾向:否 是否智能网关:智能网关 当前是否在线:否 接入方式:FTTH 端到端诊断结果:状态正常 是否质差终端:无质差信息 光功率:无 故障大类:宽带/电视 故障细类:宽带无法上网 携转原因: 故障时间:2025-01-04 12:39:28 具体故障现象:无法上网 客户其他诉求:要求恢复正常 | F102: 潍坊 | G102: 寒亭区 | H102: 15963645371 | I102: SD-057-250104-089534-2583 | J102: 'SD-057-241229-639502-6307' | K102: 否 | L102: =IF(OR(LEFT(G102,2)="高新"),"奎文",IF(LEFT(G102,2)="峡山","坊子",IF(LEFT(G102,2)="滨海","寒亭",LEFT(G102,2)))) -> 寒亭 | M102: =TEXT(B102,"mmdd") -> 0104 | N102: =VLOOKUP(I102,累计派单!A:O,15,0) -> dw3_jk_zhangdeqian | O102: =IF(LEN(J102)<2,0,DATEDIF(DATE(IF(MID(J102,9,2)="23",2023,2024),MID(J102,11,2),MID(J102,13,2)),B102,"d")) -> 6 | P102: =IF(O102=0,"无",IF(O102<8,"7天内",IF(O102<31,"30天内",IF(O102<61,"60天内",IF(O102<91,"90天内"))))) -> 7天内 | Q102: =VLOOKUP(I102,累计派单!A:O,13,0) -> 家客铁通潍坊寒亭-城东城区装维组
A103: SD-db051-250104-794620-243 | B103: 2025-01-04 13:16:54 | C103: (家客)潍坊-潍城区-重复投诉投诉督办通知-一级督办15269616887-202501040000353803 | D103: 普通区域-潍城区-丽景酒店片区-15269616887-300M-业务受理宽带-次数0-202501040000353803 | E103: 202501040000353803#【已关注中国移动10086微信公众号】 宽带账号:15269616887; 联系电话：15269616887，问题类型：此工单为群障修复工单，根据群障全量闭环修复管理要求，为确保客户网络通畅，请装维人员跟进修复网络问题，谢谢！ 群障标题：公告。故障描述：丽景酒店片区主叫号码：15269616887.0;该号码仅供参考，请优先联系宽带账号。 | F103: 潍坊 | G103: 潍城区 | H103: 15269616887 | I103: SD-057-250104-705631-2863 | J103: 'SD-057-241106-752468-3692' | K103: 否 | L103: =IF(OR(LEFT(G103,2)="高新"),"奎文",IF(LEFT(G103,2)="峡山","坊子",IF(LEFT(G103,2)="滨海","寒亭",LEFT(G103,2)))) -> 潍城 | M103: =TEXT(B103,"mmdd") -> 0104 | N103: =VLOOKUP(I103,累计派单!A:O,15,0) -> dw3_jk_wcduwangfeng | O103: =IF(LEN(J103)<2,0,DATEDIF(DATE(IF(MID(J103,9,2)="23",2023,2024),MID(J103,11,2),MID(J103,13,2)),B103,"d")) -> 59 | P103: =IF(O103=0,"无",IF(O103<8,"7天内",IF(O103<31,"30天内",IF(O103<61,"60天内",IF(O103<91,"90天内"))))) -> 60天内 | Q103: =VLOOKUP(I103,累计派单!A:O,13,0) -> 家客铁通潍坊潍城-胜利街城区装维组
A104: SD-db051-250104-302176-257 | B104: 2025-01-04 13:46:24 | C104: (家客)潍坊-诸城市-重复投诉投诉督办通知-一级督办13953667716-202501040000373154 | D104: 80+白金-普通区域-诸城市-南湖公安小区-13953667716-300M-宽带上网投诉-次数0-202501040000373154 | E104: 202501040000373154#宽带账号：13953667716；宽带地址：潍坊诸城市密州街道文化路南湖公安小区南湖公安小区；客户来电反映宽带无法上网，客户已将光猫路由器断电并按顺序重启后仍未恢复，要求上门，请协助处理，谢谢！联系电话：本机；联系人：女士；来电流水：2025010413422040720837077。 | F104: 潍坊 | G104: 诸城市 | H104: 13953667716 | I104: SD-057-250104-586042-3131 | J104: 'SD-057-241014-742638-4356' | K104: 否 | L104: =IF(OR(LEFT(G104,2)="高新"),"奎文",IF(LEFT(G104,2)="峡山","坊子",IF(LEFT(G104,2)="滨海","寒亭",LEFT(G104,2)))) -> 诸城 | M104: =TEXT(B104,"mmdd") -> 0104 | N104: =VLOOKUP(I104,累计派单!A:O,15,0) -> dw3_jk_xuguodong | O104: =IF(LEN(J104)<2,0,DATEDIF(DATE(IF(MID(J104,9,2)="23",2023,2024),MID(J104,11,2),MID(J104,13,2)),B104,"d")) -> 82 | P104: =IF(O104=0,"无",IF(O104<8,"7天内",IF(O104<31,"30天内",IF(O104<61,"60天内",IF(O104<91,"90天内"))))) -> 90天内 | Q104: =VLOOKUP(I104,累计派单!A:O,13,0) -> 家客铁通潍坊诸城-兴华东路城区装维组
A105: SD-db051-250104-950467-345 | B105: 2025-01-04 15:37:05 | C105: (家客)潍坊-昌邑市-重复投诉投诉督办通知-一级督办15610610734-202501040000477560 | D105: 【重投】-【调研】-普通区域-昌邑市-山前村-15610610734-1000M-业务受理宽带-次数0-202501040000477560 | E105: 202501040000477560#【已关注中国移动10086微信公众号】 宽带账号:15610610734; 联系电话：15610610734，问题类型：此工单为群障修复工单，根据群障全量闭环修复管理要求，为确保客户网络通畅，请装维人员跟进修复网络问题，谢谢！ 群障标题：公告。故障描述：潍坊昌邑市山前村光缆故障，预估24小时恢复，请帮忙拦截,如有需要请联系片区装维师傅邓艺浩15706307216主叫号码：15610610734.0;该号码仅供参考，请优先联系宽带账号。 | F105: 潍坊 | G105: 昌邑市 | H105: 15610610734 | I105: SD-057-250104-386409-4338 | J105: 'SD-057-241215-378254-6559' | K105: 否 | L105: =IF(OR(LEFT(G105,2)="高新"),"奎文",IF(LEFT(G105,2)="峡山","坊子",IF(LEFT(G105,2)="滨海","寒亭",LEFT(G105,2)))) -> 昌邑 | M105: =TEXT(B105,"mmdd") -> 0104 | N105: =VLOOKUP(I105,累计派单!A:O,15,0) -> dw3_jk_dengyihao | O105: =IF(LEN(J105)<2,0,DATEDIF(DATE(IF(MID(J105,9,2)="23",2023,2024),MID(J105,11,2),MID(J105,13,2)),B105,"d")) -> 20 | P105: =IF(O105=0,"无",IF(O105<8,"7天内",IF(O105<31,"30天内",IF(O105<61,"60天内",IF(O105<91,"90天内"))))) -> 30天内 | Q105: =VLOOKUP(I105,累计派单!A:O,13,0) -> 家客铁通潍坊昌邑-城西城区装维组
A106: SD-db051-250104-756849-365 | B106: 2025-01-04 16:03:33 | C106: (家客)潍坊-寿光市-重复投诉投诉督办通知-一级督办15154480806-202501040000502106 | D106: 80+普通-普通区域-寿光市-五台台后村自然村-15154480806-200M-宽带上网投诉-次数0-202501040000502106 | E106: 202501040000502106#15154480806客户来电反映宽带无法使用，客户拒绝线上排障，要求维修人员上门维修，请尽快协助处理，谢谢 联系人：女士联系电话： 15154480806 流水：2025010416014367820844373 | F106: 潍坊 | G106: 寿光市 | H106: 15154480806 | I106: SD-057-250104-098731-4583 | J106: 'SD-057-241225-049785-1678' | K106: 否 | L106: =IF(OR(LEFT(G106,2)="高新"),"奎文",IF(LEFT(G106,2)="峡山","坊子",IF(LEFT(G106,2)="滨海","寒亭",LEFT(G106,2)))) -> 寿光 | M106: =TEXT(B106,"mmdd") -> 0104 | N106: =VLOOKUP(I106,累计派单!A:O,15,0) -> dw3_jk_wangshuaisg | O106: =IF(LEN(J106)<2,0,DATEDIF(DATE(IF(MID(J106,9,2)="23",2023,2024),MID(J106,11,2),MID(J106,13,2)),B106,"d")) -> 10 | P106: =IF(O106=0,"无",IF(O106<8,"7天内",IF(O106<31,"30天内",IF(O106<61,"60天内",IF(O106<91,"90天内"))))) -> 30天内 | Q106: =VLOOKUP(I106,累计派单!A:O,13,0) -> 家客铁通潍坊寿光-侯镇乡镇装维组
