Workbook

Sheet 通报
A1: =N6&"日10086投诉一级督办单占比通报" -> 17日10086投诉一级督办单占比通报
A2: 序号 | B2: 区县 | C2: =TEXT(NOW()-1,"dd")&"日新增" -> 17日新增 | J2: 累计一级督办单 | K2: 累计一级督办单占比 | L2: 区县 | U2: =_xlfn.TEXTJOIN(",",,X3:X14) | X2: 前3 | Z2: =_xlfn.TEXTJOIN(",",,AC3:AC14) | AC2: 前3
C3: 重复投诉时间段 | H3: 一级督办单新增 | I3: 一级督办单占比新增 | X3: =VLOOKUP(1,$U$6:$V$17,2,0) | Y3: 1 | AC3: =VLOOKUP(1,$Z$6:$AA$17,2,0) | AD3: 1
C4: 无重复投诉（网课、重点客户） | D4: 7天内重复投诉 | E4: 7-30天以内重复投诉 | F4: 30-60天以内重复投诉 | G4: 60-90天以内重复投诉 | X4: =VLOOKUP(2,$U$6:$V$17,2,0) | Y4: 2 | AC4: =VLOOKUP(2,$Z$6:$AA$17,2,0) | AD4: 2
O5: 对比列 | P5: =VLOOKUP(1,O6:P17,2,0)&","&VLOOKUP(2,O6:P17,2,0)&","&VLOOKUP(3,O6:P17,2,0) -> 昌邑(5.5%),安丘(4.83%),潍城(4.57%) | Q5: 对比列 | R5: =VLOOKUP(1,Q6:R17,2,0)&","&VLOOKUP(2,Q6:R17,2,0)&","&VLOOKUP(3,Q6:R17,2,0) -> #N/A | T5: =VLOOKUP(1,S6:T17,2,0)&","&VLOOKUP(2,S6:T17,2,0)&","&VLOOKUP(3,S6:T17,2,0) -> 昌邑0件,安丘0件,潍城0件 | X5: =VLOOKUP(3,$U$6:$V$17,2,0) | Y5: 3 | AC5: =VLOOKUP(3,$Z$6:$AA$17,2,0) | AD5: 3
A6: 1 | B6: 昌邑 | C6: =COUNTIFS(督办单!L:L,B:B,督办单!M:M,$M$6,督办单!P:P,"无",督办单!C:C,"*一级*") -> 0 | D6: =COUNTIFS(督办单!L:L,B:B,督办单!M:M,$M$6,督办单!P:P,"7天内",督办单!C:C,"*一级*") -> 0 | E6: =COUNTIFS(督办单!L:L,B:B,督办单!M:M,$M$6,督办单!P:P,"30天内",督办单!C:C,"*一级*") -> 0 | F6: =COUNTIFS(督办单!L:L,B:B,督办单!M:M,$M$6,督办单!P:P,"60天内",督办单!C:C,"*一级*") -> 0 | G6: =COUNTIFS(督办单!L:L,B:B,督办单!M:M,$M$6,督办单!P:P,"90天内",督办单!C:C,"*一级*") -> 0 | H6: =COUNTIFS(督办单!L:L,B:B,督办单!C:C,"*一级*",督办单!M:M,$M$6) -> 0 | I6: =COUNTIFS(督办单!L:L,B:B,督办单!C:C,"*一级*",督办单!M:M,$M$6)/(COUNTIFS(累计派单!R:R,B:B,累计派单!S:S,$M$6)-COUNTIFS(累计派单!R:R,B:B,累计派单!I:I,"*业务受理*",累计派单!S:S,$M$6)) -> #DIV/0! | J6: =COUNTIFS(督办单!L:L,B:B,督办单!C:C,"*一级*") -> 23 | K6: =J6/(COUNTIFS(累计派单!R:R,B:B)-COUNTIFS(累计派单!R:R,B:B,累计派单!I:I,"*业务受理*")-COUNTIFS(累计派单!I:I,"*客户咨询*")) -> 0.055023923 | L6: 昌邑 | M6: =TEXT(TODAY()-1,"mmdd") -> 0717 | N6: =TEXT(M6,"dd") -> 17 | O6: =_xlfn.RANK.AVG(K6,$K$6:$K$17) -> 1 | P6: =B6&"("&ROUND(K6*100,2)&"%)" -> 昌邑(5.5%) | Q6: =_xlfn.RANK.AVG(I6,$I$6:$I$17) -> #DIV/0! | R6: =B6&"("&ROUND(I6*100,2)&"%)" -> #DIV/0! | S6: =_xlfn.RANK.EQ(H6,$H$6:$H$17,0)+COUNTIF($H$6:$H6,H6)-1 -> 1 | T6: =B6&H6&"件" -> 昌邑0件 | U6: =_xlfn.RANK.EQ(D6,$D$6:$D$17,0)+COUNTIF($D$6:$D6,D6)-1 -> 1 | V6: =IF(W6=0,"",B6&D6&"件") | W6: =D6 -> 0 | X6: =IF(VLOOKUP(Y5,$U$6:$W$17,3,0)=VLOOKUP(Y6,$U$6:$W$17,3,0),VLOOKUP(Y6,$U$6:$W$17,2,0),"") | Y6: 4 | Z6: =_xlfn.RANK.EQ(E6,$E$6:$E$17,0)+COUNTIF($E$6:$E6,E6)-1 -> 1 | AA6: =IF(AB6=0,"",B6&E6&"件") | AB6: =E6 -> 0 | AC6: =IF(VLOOKUP(AD5,$Z$6:$AB$17,3,0)=VLOOKUP(AD6,$Z$6:$AB$17,3,0),VLOOKUP(AD6,$Z$6:$AB$17,2,0),"") | AD6: 4
A7: 2 | B7: 安丘 | C7: =COUNTIFS(督办单!L:L,B:B,督办单!M:M,$M$6,督办单!P:P,"无",督办单!C:C,"*一级*") -> 0 | D7: =COUNTIFS(督办单!L:L,B:B,督办单!M:M,$M$6,督办单!P:P,"7天内",督办单!C:C,"*一级*") -> 0 | E7: =COUNTIFS(督办单!L:L,B:B,督办单!M:M,$M$6,督办单!P:P,"30天内",督办单!C:C,"*一级*") -> 0 | F7: =COUNTIFS(督办单!L:L,B:B,督办单!M:M,$M$6,督办单!P:P,"60天内",督办单!C:C,"*一级*") -> 0 | G7: =COUNTIFS(督办单!L:L,B:B,督办单!M:M,$M$6,督办单!P:P,"90天内",督办单!C:C,"*一级*") -> 0 | H7: =COUNTIFS(督办单!L:L,B:B,督办单!C:C,"*一级*",督办单!M:M,$M$6) -> 0 | I7: =COUNTIFS(督办单!L:L,B:B,督办单!C:C,"*一级*",督办单!M:M,$M$6)/(COUNTIFS(累计派单!R:R,B:B,累计派单!S:S,$M$6)-COUNTIFS(累计派单!R:R,B:B,累计派单!I:I,"*业务受理*",累计派单!S:S,$M$6)) -> #DIV/0! | J7: =COUNTIFS(督办单!L:L,B:B,督办单!C:C,"*一级*") -> 36 | K7: =J7/(COUNTIFS(累计派单!R:R,B:B)-COUNTIFS(累计派单!R:R,B:B,累计派单!I:I,"*业务受理*")-COUNTIFS(累计派单!I:I,"*客户咨询*")) -> 0.048322148 | L7: 安丘 | O7: =_xlfn.RANK.AVG(K7,$K$6:$K$17) -> 2 | P7: =B7&"("&ROUND(K7*100,2)&"%)" -> 安丘(4.83%) | Q7: =_xlfn.RANK.AVG(I7,$I$6:$I$17) -> #DIV/0! | R7: =B7&"("&ROUND(I7*100,2)&"%)" -> #DIV/0! | S7: =_xlfn.RANK.EQ(H7,$H$6:$H$17,0)+COUNTIF($H$6:$H7,H7)-1 -> 2 | T7: =B7&H7&"件" -> 安丘0件 | U7: =_xlfn.RANK.EQ(D7,$D$6:$D$17,0)+COUNTIF($D$6:$D7,D7)-1 -> 2 | V7: =IF(W7=0,"",B7&D7&"件") | W7: =D7 -> 0 | X7: =IF(VLOOKUP(Y6,$U$6:$W$17,3,0)=VLOOKUP(Y7,$U$6:$W$17,3,0),VLOOKUP(Y7,$U$6:$W$17,2,0),"") | Y7: 5 | Z7: =_xlfn.RANK.EQ(E7,$E$6:$E$17,0)+COUNTIF($E$6:$E7,E7)-1 -> 2 | AA7: =IF(AB7=0,"",B7&E7&"件") | AB7: =E7 -> 0 | AC7: =IF(VLOOKUP(AD6,$Z$6:$AB$17,3,0)=VLOOKUP(AD7,$Z$6:$AB$17,3,0),VLOOKUP(AD7,$Z$6:$AB$17,2,0),"") | AD7: 5
A8: 3 | B8: 潍城 | C8: =COUNTIFS(督办单!L:L,B:B,督办单!M:M,$M$6,督办单!P:P,"无",督办单!C:C,"*一级*") -> 0 | D8: =COUNTIFS(督办单!L:L,B:B,督办单!M:M,$M$6,督办单!P:P,"7天内",督办单!C:C,"*一级*") -> 0 | E8: =COUNTIFS(督办单!L:L,B:B,督办单!M:M,$M$6,督办单!P:P,"30天内",督办单!C:C,"*一级*") -> 0 | F8: =COUNTIFS(督办单!L:L,B:B,督办单!M:M,$M$6,督办单!P:P,"60天内",督办单!C:C,"*一级*") -> 0 | G8: =COUNTIFS(督办单!L:L,B:B,督办单!M:M,$M$6,督办单!P:P,"90天内",督办单!C:C,"*一级*") -> 0 | H8: =COUNTIFS(督办单!L:L,B:B,督办单!C:C,"*一级*",督办单!M:M,$M$6) -> 0 | I8: =COUNTIFS(督办单!L:L,B:B,督办单!C:C,"*一级*",督办单!M:M,$M$6)/(COUNTIFS(累计派单!R:R,B:B,累计派单!S:S,$M$6)-COUNTIFS(累计派单!R:R,B:B,累计派单!I:I,"*业务受理*",累计派单!S:S,$M$6)) -> #DIV/0! | J8: =COUNTIFS(督办单!L:L,B:B,督办单!C:C,"*一级*") -> 27 | K8: =J8/(COUNTIFS(累计派单!R:R,B:B)-COUNTIFS(累计派单!R:R,B:B,累计派单!I:I,"*业务受理*")-COUNTIFS(累计派单!I:I,"*客户咨询*")) -> 0.045685279 | L8: 潍城 | O8: =_xlfn.RANK.AVG(K8,$K$6:$K$17) -> 3 | P8: =B8&"("&ROUND(K8*100,2)&"%)" -> 潍城(4.57%) | Q8: =_xlfn.RANK.AVG(I8,$I$6:$I$17) -> #DIV/0! | R8: =B8&"("&ROUND(I8*100,2)&"%)" -> #DIV/0! | S8: =_xlfn.RANK.EQ(H8,$H$6:$H$17,0)+COUNTIF($H$6:$H8,H8)-1 -> 3 | T8: =B8&H8&"件" -> 潍城0件 | U8: =_xlfn.RANK.EQ(D8,$D$6:$D$17,0)+COUNTIF($D$6:$D8,D8)-1 -> 3 | V8: =IF(W8=0,"",B8&D8&"件") | W8: =D8 -> 0 | X8: =IF(VLOOKUP(Y7,$U$6:$W$17,3,0)=VLOOKUP(Y8,$U$6:$W$17,3,0),VLOOKUP(Y8,$U$6:$W$17,2,0),"") | Y8: 6 | Z8: =_xlfn.RANK.EQ(E8,$E$6:$E$17,0)+COUNTIF($E$6:$E8,E8)-1 -> 3 | AA8: =IF(AB8=0,"",B8&E8&"件") | AB8: =E8 -> 0 | AC8: =IF(VLOOKUP(AD7,$Z$6:$AB$17,3,0)=VLOOKUP(AD8,$Z$6:$AB$17,3,0),VLOOKUP(AD8,$Z$6:$AB$17,2,0),"") | AD8: 6
A9: 4 | B9: 寒亭 | C9: =COUNTIFS(督办单!L:L,B:B,督办单!M:M,$M$6,督办单!P:P,"无",督办单!C:C,"*一级*") -> 0 | D9: =COUNTIFS(督办单!L:L,B:B,督办单!M:M,$M$6,督办单!P:P,"7天内",督办单!C:C,"*一级*") -> 0 | E9: =COUNTIFS(督办单!L:L,B:B,督办单!M:M,$M$6,督办单!P:P,"30天内",督办单!C:C,"*一级*") -> 0 | F9: =COUNTIFS(督办单!L:L,B:B,督办单!M:M,$M$6,督办单!P:P,"60天内",督办单!C:C,"*一级*") -> 0 | G9: =COUNTIFS(督办单!L:L,B:B,督办单!M:M,$M$6,督办单!P:P,"90天内",督办单!C:C,"*一级*") -> 0 | H9: =COUNTIFS(督办单!L:L,B:B,督办单!C:C,"*一级*",督办单!M:M,$M$6) -> 0 | I9: =COUNTIFS(督办单!L:L,B:B,督办单!C:C,"*一级*",督办单!M:M,$M$6)/(COUNTIFS(累计派单!R:R,B:B,累计派单!S:S,$M$6)-COUNTIFS(累计派单!R:R,B:B,累计派单!I:I,"*业务受理*",累计派单!S:S,$M$6)) -> #DIV/0! | J9: =COUNTIFS(督办单!L:L,B:B,督办单!C:C,"*一级*") -> 19 | K9: =J9/(COUNTIFS(累计派单!R:R,B:B)-COUNTIFS(累计派单!R:R,B:B,累计派单!I:I,"*业务受理*")-COUNTIFS(累计派单!I:I,"*客户咨询*")) -> 0.045673077 | L9: 寒亭 | O9: =_xlfn.RANK.AVG(K9,$K$6:$K$17) -> 4 | P9: =B9&"("&ROUND(K9*100,2)&"%)" -> 寒亭(4.57%) | Q9: =_xlfn.RANK.AVG(I9,$I$6:$I$17) -> #DIV/0! | R9: =B9&"("&ROUND(I9*100,2)&"%)" -> #DIV/0! | S9: =_xlfn.RANK.EQ(H9,$H$6:$H$17,0)+COUNTIF($H$6:$H9,H9)-1 -> 4 | T9: =B9&H9&"件" -> 寒亭0件 | U9: =_xlfn.RANK.EQ(D9,$D$6:$D$17,0)+COUNTIF($D$6:$D9,D9)-1 -> 4 | V9: =IF(W9=0,"",B9&D9&"件") | W9: =D9 -> 0 | X9: =IF(VLOOKUP(Y8,$U$6:$W$17,3,0)=VLOOKUP(Y9,$U$6:$W$17,3,0),VLOOKUP(Y9,$U$6:$W$17,2,0),"") | Y9: 7 | Z9: =_xlfn.RANK.EQ(E9,$E$6:$E$17,0)+COUNTIF($E$6:$E9,E9)-1 -> 4 | AA9: =IF(AB9=0,"",B9&E9&"件") | AB9: =E9 -> 0 | AC9: =IF(VLOOKUP(AD8,$Z$6:$AB$17,3,0)=VLOOKUP(AD9,$Z$6:$AB$17,3,0),VLOOKUP(AD9,$Z$6:$AB$17,2,0),"") | AD9: 7
A10: 5 | B10: 奎文 | C10: =COUNTIFS(督办单!L:L,B:B,督办单!M:M,$M$6,督办单!P:P,"无",督办单!C:C,"*一级*") -> 0 | D10: =COUNTIFS(督办单!L:L,B:B,督办单!M:M,$M$6,督办单!P:P,"7天内",督办单!C:C,"*一级*") -> 0 | E10: =COUNTIFS(督办单!L:L,B:B,督办单!M:M,$M$6,督办单!P:P,"30天内",督办单!C:C,"*一级*") -> 0 | F10: =COUNTIFS(督办单!L:L,B:B,督办单!M:M,$M$6,督办单!P:P,"60天内",督办单!C:C,"*一级*") -> 0 | G10: =COUNTIFS(督办单!L:L,B:B,督办单!M:M,$M$6,督办单!P:P,"90天内",督办单!C:C,"*一级*") -> 0 | H10: =COUNTIFS(督办单!L:L,B:B,督办单!C:C,"*一级*",督办单!M:M,$M$6) -> 0 | I10: =COUNTIFS(督办单!L:L,B:B,督办单!C:C,"*一级*",督办单!M:M,$M$6)/(COUNTIFS(累计派单!R:R,B:B,累计派单!S:S,$M$6)-COUNTIFS(累计派单!R:R,B:B,累计派单!I:I,"*业务受理*",累计派单!S:S,$M$6)) -> #DIV/0! | J10: =COUNTIFS(督办单!L:L,B:B,督办单!C:C,"*一级*") -> 41 | K10: =J10/(COUNTIFS(累计派单!R:R,B:B)-COUNTIFS(累计派单!R:R,B:B,累计派单!I:I,"*业务受理*")-COUNTIFS(累计派单!I:I,"*客户咨询*")) -> 0.039347409 | L10: 奎文 | O10: =_xlfn.RANK.AVG(K10,$K$6:$K$17) -> 7 | P10: =B10&"("&ROUND(K10*100,2)&"%)" -> 奎文(3.93%) | Q10: =_xlfn.RANK.AVG(I10,$I$6:$I$17) -> #DIV/0! | R10: =B10&"("&ROUND(I10*100,2)&"%)" -> #DIV/0! | S10: =_xlfn.RANK.EQ(H10,$H$6:$H$17,0)+COUNTIF($H$6:$H10,H10)-1 -> 5 | T10: =B10&H10&"件" -> 奎文0件 | U10: =_xlfn.RANK.EQ(D10,$D$6:$D$17,0)+COUNTIF($D$6:$D10,D10)-1 -> 5 | V10: =IF(W10=0,"",B10&D10&"件") | W10: =D10 -> 0 | X10: =IF(VLOOKUP(Y9,$U$6:$W$17,3,0)=VLOOKUP(Y10,$U$6:$W$17,3,0),VLOOKUP(Y10,$U$6:$W$17,2,0),"") | Y10: 8 | Z10: =_xlfn.RANK.EQ(E10,$E$6:$E$17,0)+COUNTIF($E$6:$E10,E10)-1 -> 5 | AA10: =IF(AB10=0,"",B10&E10&"件") | AB10: =E10 -> 0 | AC10: =IF(VLOOKUP(AD9,$Z$6:$AB$17,3,0)=VLOOKUP(AD10,$Z$6:$AB$17,3,0),VLOOKUP(AD10,$Z$6:$AB$17,2,0),"") | AD10: 8
A11: 6 | B11: 临朐 | C11: =COUNTIFS(督办单!L:L,B:B,督办单!M:M,$M$6,督办单!P:P,"无",督办单!C:C,"*一级*") -> 0 | D11: =COUNTIFS(督办单!L:L,B:B,督办单!M:M,$M$6,督办单!P:P,"7天内",督办单!C:C,"*一级*") -> 0 | E11: =COUNTIFS(督办单!L:L,B:B,督办单!M:M,$M$6,督办单!P:P,"30天内",督办单!C:C,"*一级*") -> 0 | F11: =COUNTIFS(督办单!L:L,B:B,督办单!M:M,$M$6,督办单!P:P,"60天内",督办单!C:C,"*一级*") -> 0 | G11: =COUNTIFS(督办单!L:L,B:B,督办单!M:M,$M$6,督办单!P:P,"90天内",督办单!C:C,"*一级*") -> 0 | H11: =COUNTIFS(督办单!L:L,B:B,督办单!C:C,"*一级*",督办单!M:M,$M$6) -> 0 | I11: =COUNTIFS(督办单!L:L,B:B,督办单!C:C,"*一级*",督办单!M:M,$M$6)/(COUNTIFS(累计派单!R:R,B:B,累计派单!S:S,$M$6)-COUNTIFS(累计派单!R:R,B:B,累计派单!I:I,"*业务受理*",累计派单!S:S,$M$6)) -> #DIV/0! | J11: =COUNTIFS(督办单!L:L,B:B,督办单!C:C,"*一级*") -> 20 | K11: =J11/(COUNTIFS(累计派单!R:R,B:B)-COUNTIFS(累计派单!R:R,B:B,累计派单!I:I,"*业务受理*")-COUNTIFS(累计派单!I:I,"*客户咨询*")) -> 0.043859649 | L11: 临朐 | O11: =_xlfn.RANK.AVG(K11,$K$6:$K$17) -> 5 | P11: =B11&"("&ROUND(K11*100,2)&"%)" -> 临朐(4.39%) | Q11: =_xlfn.RANK.AVG(I11,$I$6:$I$17) -> #DIV/0! | R11: =B11&"("&ROUND(I11*100,2)&"%)" -> #DIV/0! | S11: =_xlfn.RANK.EQ(H11,$H$6:$H$17,0)+COUNTIF($H$6:$H11,H11)-1 -> 6 | T11: =B11&H11&"件" -> 临朐0件 | U11: =_xlfn.RANK.EQ(D11,$D$6:$D$17,0)+COUNTIF($D$6:$D11,D11)-1 -> 6 | V11: =IF(W11=0,"",B11&D11&"件") | W11: =D11 -> 0 | X11: =IF(VLOOKUP(Y10,$U$6:$W$17,3,0)=VLOOKUP(Y11,$U$6:$W$17,3,0),VLOOKUP(Y11,$U$6:$W$17,2,0),"") | Y11: 9 | Z11: =_xlfn.RANK.EQ(E11,$E$6:$E$17,0)+COUNTIF($E$6:$E11,E11)-1 -> 6 | AA11: =IF(AB11=0,"",B11&E11&"件") | AB11: =E11 -> 0 | AC11: =IF(VLOOKUP(AD10,$Z$6:$AB$17,3,0)=VLOOKUP(AD11,$Z$6:$AB$17,3,0),VLOOKUP(AD11,$Z$6:$AB$17,2,0),"") | AD11: 9
A12: 7 | B12: 坊子 | C12: =COUNTIFS(督办单!L:L,B:B,督办单!M:M,$M$6,督办单!P:P,"无",督办单!C:C,"*一级*") -> 0 | D12: =COUNTIFS(督办单!L:L,B:B,督办单!M:M,$M$6,督办单!P:P,"7天内",督办单!C:C,"*一级*") -> 0 | E12: =COUNTIFS(督办单!L:L,B:B,督办单!M:M,$M$6,督办单!P:P,"30天内",督办单!C:C,"*一级*") -> 0 | F12: =COUNTIFS(督办单!L:L,B:B,督办单!M:M,$M$6,督办单!P:P,"60天内",督办单!C:C,"*一级*") -> 0 | G12: =COUNTIFS(督办单!L:L,B:B,督办单!M:M,$M$6,督办单!P:P,"90天内",督办单!C:C,"*一级*") -> 0 | H12: =COUNTIFS(督办单!L:L,B:B,督办单!C:C,"*一级*",督办单!M:M,$M$6) -> 0 | I12: =COUNTIFS(督办单!L:L,B:B,督办单!C:C,"*一级*",督办单!M:M,$M$6)/(COUNTIFS(累计派单!R:R,B:B,累计派单!S:S,$M$6)-COUNTIFS(累计派单!R:R,B:B,累计派单!I:I,"*业务受理*",累计派单!S:S,$M$6)) -> #DIV/0! | J12: =COUNTIFS(督办单!L:L,B:B,督办单!C:C,"*一级*") -> 14 | K12: =J12/(COUNTIFS(累计派单!R:R,B:B)-COUNTIFS(累计派单!R:R,B:B,累计派单!I:I,"*业务受理*")-COUNTIFS(累计派单!I:I,"*客户咨询*")) -> 0.042168675 | L12: 坊子 | O12: =_xlfn.RANK.AVG(K12,$K$6:$K$17) -> 6 | P12: =B12&"("&ROUND(K12*100,2)&"%)" -> 坊子(4.22%) | Q12: =_xlfn.RANK.AVG(I12,$I$6:$I$17) -> #DIV/0! | R12: =B12&"("&ROUND(I12*100,2)&"%)" -> #DIV/0! | S12: =_xlfn.RANK.EQ(H12,$H$6:$H$17,0)+COUNTIF($H$6:$H12,H12)-1 -> 7 | T12: =B12&H12&"件" -> 坊子0件 | U12: =_xlfn.RANK.EQ(D12,$D$6:$D$17,0)+COUNTIF($D$6:$D12,D12)-1 -> 7 | V12: =IF(W12=0,"",B12&D12&"件") | W12: =D12 -> 0 | X12: =IF(VLOOKUP(Y11,$U$6:$W$17,3,0)=VLOOKUP(Y12,$U$6:$W$17,3,0),VLOOKUP(Y12,$U$6:$W$17,2,0),"") | Y12: 10 | Z12: =_xlfn.RANK.EQ(E12,$E$6:$E$17,0)+COUNTIF($E$6:$E12,E12)-1 -> 7 | AA12: =IF(AB12=0,"",B12&E12&"件") | AB12: =E12 -> 0 | AC12: =IF(VLOOKUP(AD11,$Z$6:$AB$17,3,0)=VLOOKUP(AD12,$Z$6:$AB$17,3,0),VLOOKUP(AD12,$Z$6:$AB$17,2,0),"") | AD12: 10
A13: 8 | B13: 寿光 | C13: =COUNTIFS(督办单!L:L,B:B,督办单!M:M,$M$6,督办单!P:P,"无",督办单!C:C,"*一级*") -> 0 | D13: =COUNTIFS(督办单!L:L,B:B,督办单!M:M,$M$6,督办单!P:P,"7天内",督办单!C:C,"*一级*") -> 0 | E13: =COUNTIFS(督办单!L:L,B:B,督办单!M:M,$M$6,督办单!P:P,"30天内",督办单!C:C,"*一级*") -> 0 | F13: =COUNTIFS(督办单!L:L,B:B,督办单!M:M,$M$6,督办单!P:P,"60天内",督办单!C:C,"*一级*") -> 0 | G13: =COUNTIFS(督办单!L:L,B:B,督办单!M:M,$M$6,督办单!P:P,"90天内",督办单!C:C,"*一级*") -> 0 | H13: =COUNTIFS(督办单!L:L,B:B,督办单!C:C,"*一级*",督办单!M:M,$M$6) -> 0 | I13: =COUNTIFS(督办单!L:L,B:B,督办单!C:C,"*一级*",督办单!M:M,$M$6)/(COUNTIFS(累计派单!R:R,B:B,累计派单!S:S,$M$6)-COUNTIFS(累计派单!R:R,B:B,累计派单!I:I,"*业务受理*",累计派单!S:S,$M$6)) -> #DIV/0! | J13: =COUNTIFS(督办单!L:L,B:B,督办单!C:C,"*一级*") -> 37 | K13: =J13/(COUNTIFS(累计派单!R:R,B:B)-COUNTIFS(累计派单!R:R,B:B,累计派单!I:I,"*业务受理*")-COUNTIFS(累计派单!I:I,"*客户咨询*")) -> 0.032656664 | L13: 寿光 | O13: =_xlfn.RANK.AVG(K13,$K$6:$K$17) -> 8 | P13: =B13&"("&ROUND(K13*100,2)&"%)" -> 寿光(3.27%) | Q13: =_xlfn.RANK.AVG(I13,$I$6:$I$17) -> #DIV/0! | R13: =B13&"("&ROUND(I13*100,2)&"%)" -> #DIV/0! | S13: =_xlfn.RANK.EQ(H13,$H$6:$H$17,0)+COUNTIF($H$6:$H13,H13)-1 -> 8 | T13: =B13&H13&"件" -> 寿光0件 | U13: =_xlfn.RANK.EQ(D13,$D$6:$D$17,0)+COUNTIF($D$6:$D13,D13)-1 -> 8 | V13: =IF(W13=0,"",B13&D13&"件") | W13: =D13 -> 0 | X13: =IF(VLOOKUP(Y12,$U$6:$W$17,3,0)=VLOOKUP(Y13,$U$6:$W$17,3,0),VLOOKUP(Y13,$U$6:$W$17,2,0),"") | Y13: 11 | Z13: =_xlfn.RANK.EQ(E13,$E$6:$E$17,0)+COUNTIF($E$6:$E13,E13)-1 -> 8 | AA13: =IF(AB13=0,"",B13&E13&"件") | AB13: =E13 -> 0 | AC13: =IF(VLOOKUP(AD12,$Z$6:$AB$17,3,0)=VLOOKUP(AD13,$Z$6:$AB$17,3,0),VLOOKUP(AD13,$Z$6:$AB$17,2,0),"") | AD13: 11
A14: 9 | B14: 高密 | C14: =COUNTIFS(督办单!L:L,B:B,督办单!M:M,$M$6,督办单!P:P,"无",督办单!C:C,"*一级*") -> 0 | D14: =COUNTIFS(督办单!L:L,B:B,督办单!M:M,$M$6,督办单!P:P,"7天内",督办单!C:C,"*一级*") -> 0 | E14: =COUNTIFS(督办单!L:L,B:B,督办单!M:M,$M$6,督办单!P:P,"30天内",督办单!C:C,"*一级*") -> 0 | F14: =COUNTIFS(督办单!L:L,B:B,督办单!M:M,$M$6,督办单!P:P,"60天内",督办单!C:C,"*一级*") -> 0 | G14: =COUNTIFS(督办单!L:L,B:B,督办单!M:M,$M$6,督办单!P:P,"90天内",督办单!C:C,"*一级*") -> 0 | H14: =COUNTIFS(督办单!L:L,B:B,督办单!C:C,"*一级*",督办单!M:M,$M$6) -> 0 | I14: =COUNTIFS(督办单!L:L,B:B,督办单!C:C,"*一级*",督办单!M:M,$M$6)/(COUNTIFS(累计派单!R:R,B:B,累计派单!S:S,$M$6)-COUNTIFS(累计派单!R:R,B:B,累计派单!I:I,"*业务受理*",累计派单!S:S,$M$6)) -> #DIV/0! | J14: =COUNTIFS(督办单!L:L,B:B,督办单!C:C,"*一级*") -> 20 | K14: =J14/(COUNTIFS(累计派单!R:R,B:B)-COUNTIFS(累计派单!R:R,B:B,累计派单!I:I,"*业务受理*")-COUNTIFS(累计派单!I:I,"*客户咨询*")) -> 0.028653295 | L14: 高密 | O14: =_xlfn.RANK.AVG(K14,$K$6:$K$17) -> 9 | P14: =B14&"("&ROUND(K14*100,2)&"%)" -> 高密(2.87%) | Q14: =_xlfn.RANK.AVG(I14,$I$6:$I$17) -> #DIV/0! | R14: =B14&"("&ROUND(I14*100,2)&"%)" -> #DIV/0! | S14: =_xlfn.RANK.EQ(H14,$H$6:$H$17,0)+COUNTIF($H$6:$H14,H14)-1 -> 9 | T14: =B14&H14&"件" -> 高密0件 | U14: =_xlfn.RANK.EQ(D14,$D$6:$D$17,0)+COUNTIF($D$6:$D14,D14)-1 -> 9 | V14: =IF(W14=0,"",B14&D14&"件") | W14: =D14 -> 0 | X14: =IF(VLOOKUP(Y13,$U$6:$W$17,3,0)=VLOOKUP(Y14,$U$6:$W$17,3,0),VLOOKUP(Y14,$U$6:$W$17,2,0),"") | Y14: 12 | Z14: =_xlfn.RANK.EQ(E14,$E$6:$E$17,0)+COUNTIF($E$6:$E14,E14)-1 -> 9 | AA14: =IF(AB14=0,"",B14&E14&"件") | AB14: =E14 -> 0 | AC14: =IF(VLOOKUP(AD13,$Z$6:$AB$17,3,0)=VLOOKUP(AD14,$Z$6:$AB$17,3,0),VLOOKUP(AD14,$Z$6:$AB$17,2,0),"") | AD14: 12
A15: 10 | B15: 青州 | C15: =COUNTIFS(督办单!L:L,B:B,督办单!M:M,$M$6,督办单!P:P,"无",督办单!C:C,"*一级*") -> 0 | D15: =COUNTIFS(督办单!L:L,B:B,督办单!M:M,$M$6,督办单!P:P,"7天内",督办单!C:C,"*一级*") -> 0 | E15: =COUNTIFS(督办单!L:L,B:B,督办单!M:M,$M$6,督办单!P:P,"30天内",督办单!C:C,"*一级*") -> 0 | F15: =COUNTIFS(督办单!L:L,B:B,督办单!M:M,$M$6,督办单!P:P,"60天内",督办单!C:C,"*一级*") -> 0 | G15: =COUNTIFS(督办单!L:L,B:B,督办单!M:M,$M$6,督办单!P:P,"90天内",督办单!C:C,"*一级*") -> 0 | H15: =COUNTIFS(督办单!L:L,B:B,督办单!C:C,"*一级*",督办单!M:M,$M$6) -> 0 | I15: =COUNTIFS(督办单!L:L,B:B,督办单!C:C,"*一级*",督办单!M:M,$M$6)/(COUNTIFS(累计派单!R:R,B:B,累计派单!S:S,$M$6)-COUNTIFS(累计派单!R:R,B:B,累计派单!I:I,"*业务受理*",累计派单!S:S,$M$6)) -> #DIV/0! | J15: =COUNTIFS(督办单!L:L,B:B,督办单!C:C,"*一级*") -> 24 | K15: =J15/(COUNTIFS(累计派单!R:R,B:B)-COUNTIFS(累计派单!R:R,B:B,累计派单!I:I,"*业务受理*")-COUNTIFS(累计派单!I:I,"*客户咨询*")) -> 0.02690583 | L15: 青州 | O15: =_xlfn.RANK.AVG(K15,$K$6:$K$17) -> 10 | P15: =B15&"("&ROUND(K15*100,2)&"%)" -> 青州(2.69%) | Q15: =_xlfn.RANK.AVG(I15,$I$6:$I$17) -> #DIV/0! | R15: =B15&"("&ROUND(I15*100,2)&"%)" -> #DIV/0! | S15: =_xlfn.RANK.EQ(H15,$H$6:$H$17,0)+COUNTIF($H$6:$H15,H15)-1 -> 10 | T15: =B15&H15&"件" -> 青州0件 | U15: =_xlfn.RANK.EQ(D15,$D$6:$D$17,0)+COUNTIF($D$6:$D15,D15)-1 -> 10 | V15: =IF(W15=0,"",B15&D15&"件") | W15: =D15 -> 0 | Z15: =_xlfn.RANK.EQ(E15,$E$6:$E$17,0)+COUNTIF($E$6:$E15,E15)-1 -> 10 | AA15: =IF(AB15=0,"",B15&E15&"件") | AB15: =E15 -> 0
A16: 11 | B16: 诸城 | C16: =COUNTIFS(督办单!L:L,B:B,督办单!M:M,$M$6,督办单!P:P,"无",督办单!C:C,"*一级*") -> 0 | D16: =COUNTIFS(督办单!L:L,B:B,督办单!M:M,$M$6,督办单!P:P,"7天内",督办单!C:C,"*一级*") -> 0 | E16: =COUNTIFS(督办单!L:L,B:B,督办单!M:M,$M$6,督办单!P:P,"30天内",督办单!C:C,"*一级*") -> 0 | F16: =COUNTIFS(督办单!L:L,B:B,督办单!M:M,$M$6,督办单!P:P,"60天内",督办单!C:C,"*一级*") -> 0 | G16: =COUNTIFS(督办单!L:L,B:B,督办单!M:M,$M$6,督办单!P:P,"90天内",督办单!C:C,"*一级*") -> 0 | H16: =COUNTIFS(督办单!L:L,B:B,督办单!C:C,"*一级*",督办单!M:M,$M$6) -> 0 | I16: =COUNTIFS(督办单!L:L,B:B,督办单!C:C,"*一级*",督办单!M:M,$M$6)/(COUNTIFS(累计派单!R:R,B:B,累计派单!S:S,$M$6)-COUNTIFS(累计派单!R:R,B:B,累计派单!I:I,"*业务受理*",累计派单!S:S,$M$6)) -> #DIV/0! | J16: =COUNTIFS(督办单!L:L,B:B,督办单!C:C,"*一级*") -> 16 | K16: =J16/(COUNTIFS(累计派单!R:R,B:B)-COUNTIFS(累计派单!R:R,B:B,累计派单!I:I,"*业务受理*")-COUNTIFS(累计派单!I:I,"*客户咨询*")) -> 0.022191401 | L16: 诸城 | O16: =_xlfn.RANK.AVG(K16,$K$6:$K$17) -> 11 | P16: =B16&"("&ROUND(K16*100,2)&"%)" -> 诸城(2.22%) | Q16: =_xlfn.RANK.AVG(I16,$I$6:$I$17) -> #DIV/0! | R16: =B16&"("&ROUND(I16*100,2)&"%)" -> #DIV/0! | S16: =_xlfn.RANK.EQ(H16,$H$6:$H$17,0)+COUNTIF($H$6:$H16,H16)-1 -> 11 | T16: =B16&H16&"件" -> 诸城0件 | U16: =_xlfn.RANK.EQ(D16,$D$6:$D$17,0)+COUNTIF($D$6:$D16,D16)-1 -> 11 | V16: =IF(W16=0,"",B16&D16&"件") | W16: =D16 -> 0 | Z16: =_xlfn.RANK.EQ(E16,$E$6:$E$17,0)+COUNTIF($E$6:$E16,E16)-1 -> 11 | AA16: =IF(AB16=0,"",B16&E16&"件") | AB16: =E16 -> 0
A17: 12 | B17: 昌乐 | C17: =COUNTIFS(督办单!L:L,B:B,督办单!M:M,$M$6,督办单!P:P,"无",督办单!C:C,"*一级*") -> 0 | D17: =COUNTIFS(督办单!L:L,B:B,督办单!M:M,$M$6,督办单!P:P,"7天内",督办单!C:C,"*一级*") -> 0 | E17: =COUNTIFS(督办单!L:L,B:B,督办单!M:M,$M$6,督办单!P:P,"30天内",督办单!C:C,"*一级*") -> 0 | F17: =COUNTIFS(督办单!L:L,B:B,督办单!M:M,$M$6,督办单!P:P,"60天内",督办单!C:C,"*一级*") -> 0 | G17: =COUNTIFS(督办单!L:L,B:B,督办单!M:M,$M$6,督办单!P:P,"90天内",督办单!C:C,"*一级*") -> 0 | H17: =COUNTIFS(督办单!L:L,B:B,督办单!C:C,"*一级*",督办单!M:M,$M$6) -> 0 | I17: =COUNTIFS(督办单!L:L,B:B,督办单!C:C,"*一级*",督办单!M:M,$M$6)/(COUNTIFS(累计派单!R:R,B:B,累计派单!S:S,$M$6)-COUNTIFS(累计派单!R:R,B:B,累计派单!I:I,"*业务受理*",累计派单!S:S,$M$6)) -> #DIV/0! | J17: =COUNTIFS(督办单!L:L,B:B,督办单!C:C,"*一级*") -> 5 | K17: =J17/(COUNTIFS(累计派单!R:R,B:B)-COUNTIFS(累计派单!R:R,B:B,累计派单!I:I,"*业务受理*")-COUNTIFS(累计派单!I:I,"*客户咨询*")) -> 0.021551724 | L17: 昌乐 | O17: =_xlfn.RANK.AVG(K17,$K$6:$K$17) -> 12 | P17: =B17&"("&ROUND(K17*100,2)&"%)" -> 昌乐(2.16%) | Q17: =_xlfn.RANK.AVG(I17,$I$6:$I$17) -> #DIV/0! | R17: =B17&"("&ROUND(I17*100,2)&"%)" -> #DIV/0! | S17: =_xlfn.RANK.EQ(H17,$H$6:$H$17,0)+COUNTIF($H$6:$H17,H17)-1 -> 12 | T17: =B17&H17&"件" -> 昌乐0件 | U17: =_xlfn.RANK.EQ(D17,$D$6:$D$17,0)+COUNTIF($D$6:$D17,D17)-1 -> 12 | V17: =IF(W17=0,"",B17&D17&"件") | W17: =D17 -> 0 | Z17: =_xlfn.RANK.EQ(E17,$E$6:$E$17,0)+COUNTIF($E$6:$E17,E17)-1 -> 12 | AA17: =IF(AB17=0,"",B17&E17&"件") | AB17: =E17 -> 0
A18: 合计 | C18: =SUM(C6:C17) -> 0 | D18: =SUM(D6:D17) -> 0 | E18: =SUM(E6:E17) -> 0 | F18: =SUM(F6:F17) -> 0 | G18: =SUM(G6:G17) -> 0 | H18: =SUM(H6:H17) -> 0 | I18: =H18/(COUNTIFS(累计派单!S:S,$M$6)-COUNTIFS(累计派单!I:I,"*业务受理*",累计派单!S:S,$M$6)-COUNTIFS(累计派单!I:I,"*修复*",累计派单!S:S,$M$6)-COUNTIFS(累计派单!I:I,"*客户咨询*",累计派单!S:S,$M$6)) -> #DIV/0! | J18: =SUM(J6:J17) -> 282 | K18: =J18/(COUNTIFS(累计派单!C:C,"潍坊")-COUNTIFS(累计派单!I:I,"*业务受理*")-COUNTIFS(累计派单!I:I,"*客户咨询*")) -> 0.036270096 | L18: 合计
C20: ="关于10086投诉一级督办占比的通报-截止"&N6&"日 一、整体情况： 1、截止"&N6&"日，累计产生一级督办单"&J18&"件，一级督办单占比"&ROUND(K18*100,2)&"%。 2、一级督办单累计增长："&P5&"较高。 二、单日情况： 1、"&R5&"较多。 2、"&N6&"日新增"&H18&"件："&T5&"较多。 三、分析情况： 1、无重复投诉（重点客户、网课）："&C18&"件。 2、7天内重复投诉"&D18&"件："&U2&"。 3、大于7天小于30天"&E18&"件："&Z2&"。" -> #N/A

Sheet 督办单
A1: 督办工单号 | B1: 督办工单发起时间 | C1: 督办单主题 | D1: 投诉主题 | E1: 投诉内容 | F1: 投诉地市 | G1: 投诉区县 | H1: 投诉电话 | I1: 投诉工单号 | J1: 重复投诉工单号 | K1: 是否处理 | L1: =IF(OR(LEFT(G1,2)="高新"),"奎文",IF(LEFT(G1,2)="峡山","坊子",IF(LEFT(G1,2)="滨海","寒亭",LEFT(G1,2)))) -> 投诉 | M1: =TEXT(B1,"yyyymmdd") -> 督办工单发起时间 | N1: 工号 | O1: 时间段 | P1: 时间段 | Q1: 网格
A2: SD-db051-240703-735269-5 | B2: 2024-07-03 07:28:06 | C2: (家客)潍坊-诸城市-重复投诉投诉督办通知-一级督办18805365378-202407030000090931 | D2: 【调研】-普通区域-诸城市-山钢碧桂园·翡翠城-18805365378-200M-宽带上网投诉-次数0-202407030000090931 | E2: 202407030000090931#流程受理流水号：20240703072721188053653781000254 客户号码:18805365378 客户姓名:郭** 投诉地市:潍坊 来话流水:2024070307224877020852549 宽带账号:18805365378 宽带账号归属地市:潍坊 宽带账号归属区县:诸城市 故障地址:潍坊诸城市密州街道南外环山钢碧桂园·翡翠城27号楼********* 联系电话:18353631333 联系人:先生 工单紧急程度:一般 是否有升级投诉倾向:否 是否重复投诉:否 是否携转意向:否 是否投诉倾向:否 是否智 | F2: 潍坊 | G2: 诸城市 | H2: 18805365378 | I2: SD-057-240703-451762-61 | J2: 'SD-057-240501-762354-6441' | K2: 是 | L2: =IF(OR(LEFT(G2,2)="高新"),"奎文",IF(LEFT(G2,2)="峡山","坊子",IF(LEFT(G2,2)="滨海","寒亭",LEFT(G2,2)))) -> 诸城 | M2: =TEXT(B2,"mmdd") -> 0703 | N2: =VLOOKUP(I2,累计派单!A:O,15,0) -> dw3_jk_liuyong | O2: =IF(LEN(J2)<2,0,DATEDIF(DATE(IF(MID(J2,9,2)="23",2023,2024),MID(J2,11,2),MID(J2,13,2)),B2,"d")) -> 63 | P2: =IF(O2=0,"无",IF(O2<8,"7天内",IF(O2<31,"30天内",IF(O2<61,"60天内",IF(O2<91,"90天内"))))) -> 90天内 | Q2: =VLOOKUP(I:I,累计派单!A:M,13,0) -> 家客铁通潍坊诸城-兴华东路城区装维组
A3: SD-db051-240703-137465-22 | B3: 2024-07-03 08:50:08 | C3: (家客)潍坊-安丘市-重复投诉投诉督办通知-一级督办15762672444-20240703084737X657898290 | D3: 普通区域-安丘市-于家营子居民楼-15762672444-300M-宽带上网投诉-次数0-20240703084737X657898290 | E3: 【农村网络投诉】流程受理流水号：20240703084706157626724441006608 客户号码:15762672444 客户姓名:曹** 投诉地市:潍坊 来话流水:2024070308454173720834966 宽带账号:15762672444 宽带账号归属地市:潍坊 宽带账号归属区县:安丘市 故障地址:潍坊安丘市刘家尧镇于家营子村于家营子居民楼北楼********* 联系电话:18764651666 联系人:先生 工单紧急程度:一般 是否有升级投诉倾向:否 是否重复投诉:否 是 | F3: 潍坊 | G3: 安丘市 | H3: 15762672444 | I3: SD-057-240703-354692-421 | J3: 'SD-057-240518-847215-6881' | K3: 否 | L3: =IF(OR(LEFT(G3,2)="高新"),"奎文",IF(LEFT(G3,2)="峡山","坊子",IF(LEFT(G3,2)="滨海","寒亭",LEFT(G3,2)))) -> 安丘 | M3: =TEXT(B3,"mmdd") -> 0703 | N3: =VLOOKUP(I3,累计派单!A:O,15,0) -> dw3_jk_yvshubo | O3: =IF(LEN(J3)<2,0,DATEDIF(DATE(IF(MID(J3,9,2)="23",2023,2024),MID(J3,11,2),MID(J3,13,2)),B3,"d")) -> 46 | P3: =IF(O3=0,"无",IF(O3<8,"7天内",IF(O3<31,"30天内",IF(O3<61,"60天内",IF(O3<91,"90天内"))))) -> 60天内 | Q3: =VLOOKUP(I:I,累计派单!A:M,13,0) -> 家客铁通潍坊安丘-刘家尧乡镇装维组
A4: SD-db051-240703-439850-115 | B4: 2024-07-03 10:55:41 | C4: (家客)潍坊-昌邑市-重复投诉投诉督办通知-一级督办13963626484-202407030000237758 | D4: 普通区域-昌邑市-昌邑北海花园-13963626484-300M-宽带上网投诉-次数0-202407030000237758 | E4: 202407030000237758#流程受理流水号：20240703105501139636264841052844 客户号码:13963626484 客户姓名:马** 投诉地市:潍坊 来话流水:2024070310544538220815984 宽带账号:13963626484 宽带账号归属地市:潍坊 宽带账号归属区县:昌邑市 故障地址:潍坊昌邑市城区天水路北海花园5号楼********* 联系电话:13963626484 联系人:先生/女士 工单紧急程度:一般 是否有升级投诉倾向:否 是否重复投诉:否 是否携转意向:否 是否投诉倾向:否 是否智能网关 | F4: 潍坊 | G4: 昌邑市 | H4: 13963626484 | I4: SD-057-240703-621375-1808 | J4: 'SD-057-240414-134857-6898' | K4: 是 | L4: =IF(OR(LEFT(G4,2)="高新"),"奎文",IF(LEFT(G4,2)="峡山","坊子",IF(LEFT(G4,2)="滨海","寒亭",LEFT(G4,2)))) -> 昌邑 | M4: =TEXT(B4,"mmdd") -> 0703 | N4: =VLOOKUP(I4,累计派单!A:O,15,0) -> dw3_jk_wangsongliang | O4: =IF(LEN(J4)<2,0,DATEDIF(DATE(IF(MID(J4,9,2)="23",2023,2024),MID(J4,11,2),MID(J4,13,2)),B4,"d")) -> 80 | P4: =IF(O4=0,"无",IF(O4<8,"7天内",IF(O4<31,"30天内",IF(O4<61,"60天内",IF(O4<91,"90天内"))))) -> 90天内 | Q4: =VLOOKUP(I:I,累计派单!A:M,13,0) -> 家客铁通潍坊昌邑-城北城区装维组
A5: SD-db051-240703-375482-116 | B5: 2024-07-03 10:56:15 | C5: (家客)潍坊-奎文区-重复投诉投诉督办通知-一级督办15953670982-20240703105429X269466225 | D5: 普通区域-奎文区-苇湾社区-15953670982-300M-宽带上网投诉-次数0-20240703105429X269466225 | E5: 流程受理流水号：20240703105319159536709821052260 客户号码:15953670982 客户姓名:何* 投诉地市:潍坊 来话流水:2024070310504465120857181 宽带账号:15953670982 宽带账号归属地市:潍坊 宽带账号归属区县:奎文区 故障地址:潍坊奎文区东关街道东风街四平路苇湾社区31号楼********* 联系电话:15253676293 联系人:先生 工单紧急程度:一般 是否有升级投诉倾向:否 是否重复投诉:否 是否携转意向:否 是否投诉倾向:否 是否智能网关:智能网关 当前是否在线:是 接入方式:FTTH 端到端诊断结果:客户侧设备问题（新增） 是否质差终端:无质差信息 光功率:-19.70 故障大类:宽带/电视 故障细类:宽带无法上网(专席) 携转原因: 故障时间:2024-07-03 10:54:46 具体故障现象:宽带不能上网，排障之后没有恢复 客户其他诉求: | F5: 潍坊 | G5: 奎文区 | H5: 15953670982 | I5: SD-057-240703-192637-1814 | J5: 'SD-057-240622-159832-2435' | K5: 是 | L5: =IF(OR(LEFT(G5,2)="高新"),"奎文",IF(LEFT(G5,2)="峡山","坊子",IF(LEFT(G5,2)="滨海","寒亭",LEFT(G5,2)))) -> 奎文 | M5: =TEXT(B5,"mmdd") -> 0703 | N5: =VLOOKUP(I5,累计派单!A:O,15,0) -> dw3_ji_liguolei | O5: =IF(LEN(J5)<2,0,DATEDIF(DATE(IF(MID(J5,9,2)="23",2023,2024),MID(J5,11,2),MID(J5,13,2)),B5,"d")) -> 11 | P5: =IF(O5=0,"无",IF(O5<8,"7天内",IF(O5<31,"30天内",IF(O5<61,"60天内",IF(O5<91,"90天内"))))) -> 30天内 | Q5: =VLOOKUP(I:I,累计派单!A:M,13,0) -> 家客铁通潍坊奎文-鸢飞路城区装维组
A6: SD-db051-240703-186530-134 | B6: 2024-07-03 11:20:47 | C6: (家客)潍坊-昌邑市-重复投诉投诉督办通知-一级督办15863416817-20240703111910X750915355 | D6: 【调研】-普通区域-昌邑市-南苏村自然村-15863416817-300M-宽带上网投诉-次数0-20240703111910X750915355 | E6: 【农村网络投诉】流程受理流水号：20240703111707158634168171060001 客户号码:15863416817 客户姓名:苏** 投诉地市:潍坊 来话流水:2024070311161618120826646 宽带账号:15863416817 宽带账号归属地市:潍坊 宽带账号归属区县:昌邑市 故障地址:潍坊昌邑市围子镇南苏村南苏村自然村5号箱苏海波********* 联系电话:15863416817 联系人:先生 工单紧急程度:非常紧急 是否有升级投诉倾向:否 是否重复投诉:否 是否携转意向:否 是否投诉倾向:否 是否智能网关:智能网关 当前是否在线:否 接入方式:FTTH 端到端诊断结果:状态正常 是否质差终端:无质差信息 光功率:无 故障大类:宽带/电视 故障细类:宽带无法上网 携转原因: 故障时间:2024-07-03 11:25:28 具体故障现象:光猫亮红灯 客户其他诉求: | F6: 潍坊 | G6: 昌邑市 | H6: 15863416817 | I6: SD-057-240703-425139-2137 | J6: 'SD-057-240630-560193-65' | K6: 否 | L6: =IF(OR(LEFT(G6,2)="高新"),"奎文",IF(LEFT(G6,2)="峡山","坊子",IF(LEFT(G6,2)="滨海","寒亭",LEFT(G6,2)))) -> 昌邑 | M6: =TEXT(B6,"mmdd") -> 0703 | N6: =VLOOKUP(I6,累计派单!A:O,15,0) -> dw3_jk_dongwenqi | O6: =IF(LEN(J6)<2,0,DATEDIF(DATE(IF(MID(J6,9,2)="23",2023,2024),MID(J6,11,2),MID(J6,13,2)),B6,"d")) -> 3 | P6: =IF(O6=0,"无",IF(O6<8,"7天内",IF(O6<31,"30天内",IF(O6<61,"60天内",IF(O6<91,"90天内"))))) -> 7天内 | Q6: =VLOOKUP(I:I,累计派单!A:M,13,0) -> 家客铁通潍坊昌邑-围子乡镇装维组
A7: SD-db051-240703-786035-151 | B7: 2024-07-03 11:56:56 | C7: (家客)潍坊-安丘市-重复投诉投诉督办通知-一级督办15244405552-202407030000298786 | D7: 【调研】-普通区域-安丘市-金地太阳城(含小庄子安置楼)-15244405552-1000M-宽带上网投诉-次数0-202407030000298786 | E7: 202407030000298786#15244405552客户来电反映对前期工单处理结果不认可，要求回电处理，前期工单流水：202405270000201921，本次通话流水：2024070311485682820866598，联系人：先生，联系电话：15244405552，请协助处理，谢谢 | F7: 潍坊 | G7: 安丘市 | H7: 15244405552 | I7: SD-057-240703-136847-2442 | J7: 'SD-057-240527-579816-1712' | K7: 是 | L7: =IF(OR(LEFT(G7,2)="高新"),"奎文",IF(LEFT(G7,2)="峡山","坊子",IF(LEFT(G7,2)="滨海","寒亭",LEFT(G7,2)))) -> 安丘 | M7: =TEXT(B7,"mmdd") -> 0703 | N7: =VLOOKUP(I7,累计派单!A:O,15,0) -> dw3_jk_sunhao | O7: =IF(LEN(J7)<2,0,DATEDIF(DATE(IF(MID(J7,9,2)="23",2023,2024),MID(J7,11,2),MID(J7,13,2)),B7,"d")) -> 37 | P7: =IF(O7=0,"无",IF(O7<8,"7天内",IF(O7<31,"30天内",IF(O7<61,"60天内",IF(O7<91,"90天内"))))) -> 60天内 | Q7: =VLOOKUP(I:I,累计派单!A:M,13,0) -> 家客铁通潍坊安丘-潍安路城区装维组
A8: SD-db051-240703-628401-156 | B8: 2024-07-03 12:05:28 | C8: (家客)潍坊-潍城区-重复投诉投诉督办通知-一级督办15953692822-20240703120359X439850191 | D8: 【调研】-80+白金-普通区域-潍城区-恒信玫瑰公馆二期-15953692822-1000M-宽带上网投诉-次数0-20240703120359X439850191 | E8: 流程受理流水号：20240703120102159536928221073605 客户号码:15953692822 客户姓名:杨** 投诉地市:潍坊 来话流水:2024070311591672620893501 宽带账号:15953692822 宽带账号归属地市:潍坊 宽带账号归属区县:潍城区 故障地址:潍坊潍城区北关街道永安路恒信玫瑰公馆二期13号楼********* 联系电话:15953692822 联系人:先生/女士 工单紧急程度:非常紧急 是否有升级投诉倾向:否 是否重复投诉:否 是否携转意向:否 是否投诉倾向:否 是否智能网关:智能网关 当前是否在线:是 接入方式:FTTH 端到端诊断结果:客户侧设备问题（新增） 是否质差终端:无质差信息 光功率:-22.67 故障大类:宽带/电视 故障细类:网速慢/上网掉线(专席) 携转原因: 故障时间:2024-07-03 12:01:03 具体故障现象:光猫频繁掉线，重启设备未恢复，客户要求换工作人员处理，客户要求换光猫设备，解释不认可，请核实处理谢谢 客户其他诉求: | F8: 潍坊 | G8: 潍城区 | H8: 15953692822 | I8: SD-057-240703-735402-2504 | J8: 'SD-057-240619-967481-6759' | K8: 否 | L8: =IF(OR(LEFT(G8,2)="高新"),"奎文",IF(LEFT(G8,2)="峡山","坊子",IF(LEFT(G8,2)="滨海","寒亭",LEFT(G8,2)))) -> 潍城 | M8: =TEXT(B8,"mmdd") -> 0703 | N8: =VLOOKUP(I8,累计派单!A:O,15,0) -> dw3_jk_wcfuguangjie | O8: =IF(LEN(J8)<2,0,DATEDIF(DATE(IF(MID(J8,9,2)="23",2023,2024),MID(J8,11,2),MID(J8,13,2)),B8,"d")) -> 14 | P8: =IF(O8=0,"无",IF(O8<8,"7天内",IF(O8<31,"30天内",IF(O8<61,"60天内",IF(O8<91,"90天内"))))) -> 30天内 | Q8: =VLOOKUP(I:I,累计派单!A:M,13,0) -> 家客铁通潍坊潍城-和平路城区装维组
A9: SD-db051-240703-469150-205 | B9: 2024-07-03 14:02:31 | C9: (家客)潍坊-高密市-重复投诉投诉督办通知-一级督办18366317111-20240703140136X496524849 | D9: 80+金卡-普通区域-高密市-十里堡自然村-18366317111-1000M-宽带上网投诉-次数0-20240703140136X496524849 | E9: 【农村网络投诉】流程受理流水号：20240703140116183663171111100489 客户号码:18366317111 客户姓名:葛** 投诉地市:潍坊 来话流水:2024070314004669020825575 宽带账号:18366317111 宽带账号归属地市:潍坊 宽带账号归属区县:高密市 故障地址:潍坊高密市夏庄镇十里堡十里堡自然村新村张先荣西屋山K18号********* 联系电话:18366317111 联系人:先生/女士 工单紧急程度:非常紧急 是否有升级投诉倾向:否 是否重复投诉:否 是否携转意向:否 是否投诉倾向:否 是否智能网关:智能网关 当前是否在线:否 接入方式:FTTH 端到端诊断结果:状态正常 是否质差终端:无质差信息 光功率:无 故障大类:宽带/电视 故障细类:宽带无法上网(专席) 携转原因: 故障时间:2024-07-03 14:03:38 具体故障现象:打不开网页， 客户其他诉求: | F9: 潍坊 | G9: 高密市 | H9: 18366317111 | I9: SD-057-240703-152489-3592 | J9: 'SD-057-240503-375284-3143' | K9: 是 | L9: =IF(OR(LEFT(G9,2)="高新"),"奎文",IF(LEFT(G9,2)="峡山","坊子",IF(LEFT(G9,2)="滨海","寒亭",LEFT(G9,2)))) -> 高密 | M9: =TEXT(B9,"mmdd") -> 0703 | N9: =VLOOKUP(I9,累计派单!A:O,15,0) -> dw3_jk_gaoqiang | O9: =IF(LEN(J9)<2,0,DATEDIF(DATE(IF(MID(J9,9,2)="23",2023,2024),MID(J9,11,2),MID(J9,13,2)),B9,"d")) -> 61 | P9: =IF(O9=0,"无",IF(O9<8,"7天内",IF(O9<31,"30天内",IF(O9<61,"60天内",IF(O9<91,"90天内"))))) -> 90天内 | Q9: =VLOOKUP(I:I,累计派单!A:M,13,0) -> 家客铁通潍坊高密-夏庄乡镇装维组
A10: SD-db051-240703-791634-281 | B10: 2024-07-03 16:56:40 | C10: (家客)潍坊-寒亭区-重复投诉投诉督办通知-一级督办15163615099-202407030000552400 | D10: 普通区域-寒亭区-元和新城-15163615099-300M-宽带上网投诉-次数0-202407030000552400 | E10: 202407030000552400#流程受理流水号：20240703165457151636150991150667 客户号码:15163615099 客户姓名:董** 投诉地市:潍坊 来话流水:2024070316524804320850494 宽带账号:15163615099 宽带账号归属地市:潍坊 宽带账号归属区县:寒亭区 故障地址:潍坊寒亭区寒亭街道益新街元和新城29号楼********* 联系电话:15163615099 联系人:先生/女士 工单紧急程度:非常紧急 是否有升级投诉倾向:否 是否重复投诉:否 是否携转意向:否 是否投诉倾向:否 是否智能网关:智能网关 当前是否在线:是 接入方式:FTTH 端到端诊断结果:客户侧设备问题 是否质差终端:是 光功率:-18.96 故障大类:宽带/电视 故障细类:宽带无法上网 携转原因: 故障时间:2024-07-03 16:54:46 具体故障现象:网速慢卡顿， 客户其他诉求:客户侧为质差终端，要求上门更换终端并一并处理故障问题。 | F10: 潍坊 | G10: 寒亭区 | H10: 15163615099 | I10: SD-057-240703-237615-5158 | J10: 'SD-057-240406-873246-6570' | K10: 是 | L10: =IF(OR(LEFT(G10,2)="高新"),"奎文",IF(LEFT(G10,2)="峡山","坊子",IF(LEFT(G10,2)="滨海","寒亭",LEFT(G10,2)))) -> 寒亭 | M10: =TEXT(B10,"mmdd") -> 0703 | N10: =VLOOKUP(I10,累计派单!A:O,15,0) -> dw3_jk_liuxingtao | O10: =IF(LEN(J10)<2,0,DATEDIF(DATE(IF(MID(J10,9,2)="23",2023,2024),MID(J10,11,2),MID(J10,13,2)),B10,"d")) -> 88 | P10: =IF(O10=0,"无",IF(O10<8,"7天内",IF(O10<31,"30天内",IF(O10<61,"60天内",IF(O10<91,"90天内"))))) -> 90天内 | Q10: =VLOOKUP(I:I,累计派单!A:M,13,0) -> 家客铁通潍坊寒亭-城东城区装维组
A11: SD-db051-240703-456791-314 | B11: 2024-07-03 18:10:07 | C11: (家客)潍坊-寿光市-重复投诉投诉督办通知-一级督办18253639999-202407030000614989 | D11: 80+普通-普通区域-寿光市-西丹河村-18253639999-1000M-宽带 | E11: 202407030000614989#18253639999客户来电反应前期处理不满，前期工单 202407010000431538，要求再次反馈处理并回复电话，联系电话本机，流水 2024070317555677320842113 | F11: 潍坊 | G11: 寿光市 | H11: 18253639999 | I11: SD-057-240703-976382-5904 | J11: 'SD-057-240701-293764-5373' | K11: 否 | L11: =IF(OR(LEFT(G11,2)="高新"),"奎文",IF(LEFT(G11,2)="峡山","坊子",IF(LEFT(G11,2)="滨海","寒亭",LEFT(G11,2)))) -> 寿光 | M11: =TEXT(B11,"mmdd") -> 0703 | N11: =VLOOKUP(I11,累计派单!A:O,15,0) -> dw3_jk_songyujie | O11: =IF(LEN(J11)<2,0,DATEDIF(DATE(IF(MID(J11,9,2)="23",2023,2024),MID(J11,11,2),MID(J11,13,2)),B11,"d")) -> 2 | P11: =IF(O11=0,"无",IF(O11<8,"7天内",IF(O11<31,"30天内",IF(O11<61,"60天内",IF(O11<91,"90天内"))))) -> 7天内 | Q11: =VLOOKUP(I:I,累计派单!A:M,13,0) -> 家客铁通潍坊寿光-稻田乡镇装维组
A12: SD-db051-240703-780253-383 | B12: 2024-07-03 20:05:15 | C12: (家客)潍坊-青州市-重复投诉投诉督办通知-一级督办13863640425-20240703200329X209594402 | D12: 普通区域-青州市-黄家里双-13863640425-300M-宽带上网投诉-次数0-20240703200329X209594402 | E12: 【农村网络投诉】流程受理流水号：20240703200153138636404251193536 客户号码:13863640425 客户姓名:王** 投诉地市:潍坊 来话流水:2024070320010989920884106 宽带账号:13863640425 宽带账号归属地市:潍坊 宽带账号归属区县:青州市 故障地址:潍坊青州市何官镇黄家里双村黄家里双28号箱#刘君#********* 联系电话:15006611390 联系人:先生 工单紧急程度:一般 是否有升级投诉倾向:否 是否重复投诉:否 是否携转意向:否 是否投诉倾向:否 是否智能网关:智能网关 当前是否在线:否 接入方式:FTTH 端到端诊断结果:状态正常 是否质差终端:无质差信息 光功率:无 故障大类:宽带/电视 故障细类:宽带无法上网 携转原因: 故障时间:2024-07-03 20:03:05 具体故障现象:光猫亮红灯， 客户其他诉求: | F12: 潍坊 | G12: 青州市 | H12: 13863640425 | I12: SD-057-240703-962174-7212 | J12: 'SD-057-240630-638107-6013' | K12: 是 | L12: =IF(OR(LEFT(G12,2)="高新"),"奎文",IF(LEFT(G12,2)="峡山","坊子",IF(LEFT(G12,2)="滨海","寒亭",LEFT(G12,2)))) -> 青州 | M12: =TEXT(B12,"mmdd") -> 0703 | N12: =VLOOKUP(I12,累计派单!A:O,15,0) -> dw3_jk_liuqunbo | O12: =IF(LEN(J12)<2,0,DATEDIF(DATE(IF(MID(J12,9,2)="23",2023,2024),MID(J12,11,2),MID(J12,13,2)),B12,"d")) -> 3 | P12: =IF(O12=0,"无",IF(O12<8,"7天内",IF(O12<31,"30天内",IF(O12<61,"60天内",IF(O12<91,"90天内"))))) -> 7天内 | Q12: =VLOOKUP(I:I,累计派单!A:M,13,0) -> 家客铁通潍坊青州-何官乡镇装维组
A13: SD-db051-240703-374582-403 | B13: 2024-07-03 21:04:25 | C13: (家客)潍坊-临朐县-重复投诉投诉督办通知-一级督办15153663187-202407030000720174 | D13: 普通区域-临朐县-高家庄-15153663187-1000M-宽带上网投诉-次数0-202407030000720174 | E13: 202407030000720174#宽带账号：15153663187；宽带地址：潍坊临朐县寺头镇人民政府高家庄村高家庄高家庄3号箱张长忠（；客户来电反映宽带连不上网，经查询客户侧为质差路由器导致宽带使用不畅，请参考处理，谢谢！联系电话：15153663187；来电流水：2024070320595888720878369 | F13: 潍坊 | G13: 临朐县 | H13: 15153663187 | I13: SD-057-240703-496531-7815 | J13: 'SD-057-240501-065924-6120' | K13: 是 | L13: =IF(OR(LEFT(G13,2)="高新"),"奎文",IF(LEFT(G13,2)="峡山","坊子",IF(LEFT(G13,2)="滨海","寒亭",LEFT(G13,2)))) -> 临朐 | M13: =TEXT(B13,"mmdd") -> 0703 | N13: =VLOOKUP(I13,累计派单!A:O,15,0) -> dw3_jk_zhangjin | O13: =IF(LEN(J13)<2,0,DATEDIF(DATE(IF(MID(J13,9,2)="23",2023,2024),MID(J13,11,2),MID(J13,13,2)),B13,"d")) -> 63 | P13: =IF(O13=0,"无",IF(O13<8,"7天内",IF(O13<31,"30天内",IF(O13<61,"60天内",IF(O13<91,"90天内"))))) -> 90天内 | Q13: =VLOOKUP(I:I,累计派单!A:M,13,0) -> 家客铁通潍坊临朐-五井乡镇装维组
... A283: SD-db051-240716-392475-434 | B283: 2024-07-16 21:11:17 | C283: (家客)潍坊-奎文区-重复投诉投诉督办通知-一级督办15269624455-202407160000611545 | D283: 80+金卡-普通区域-奎文区-四方家和-15269624455-500M-宽带上网投诉-次数0-202407160000611545 | E283: 202407160000611545#宽带账号：15269624455；宽带地址：**潍坊奎文区北苑街道玄武街四方家和3号楼客户来电反映宽带网速慢，客户要求师傅上门，请协助处理，谢谢！联系电话18763607766联系人张***；来电流水：*2024071621070873720835070 | F283: 潍坊 | G283: 奎文区 | H283: 15269624455 | I283: SD-057-240716-037658-7509 | J283: 'SD-057-240507-816537-990' | K283: 否 | L283: =IF(OR(LEFT(G283,2)="高新"),"奎文",IF(LEFT(G283,2)="峡山","坊子",IF(LEFT(G283,2)="滨海","寒亭",LEFT(G283,2)))) -> 奎文 | M283: =TEXT(B283,"mmdd") -> 0716 | N283: =VLOOKUP(I283,累计派单!A:O,15,0) -> dw3_jk_wangxiao | O283: =IF(LEN(J283)<2,0,DATEDIF(DATE(IF(MID(J283,9,2)="23",2023,2024),MID(J283,11,2),MID(J283,13,2)),B283,"d")) -> 70 | P283: =IF(O283=0,"无",IF(O283<8,"7天内",IF(O283<31,"30天内",IF(O283<61,"60天内",IF(O283<91,"90天内"))))) -> 90天内 | Q283: =VLOOKUP(I:I,累计派单!A:M,13,0) -> 家客铁通潍坊奎文-鸢飞路城区装维组

Sheet 累计派单
A1: 工单号 | B1: 派单时间 | C1: 地市 | D1: 主题 | E1: 处理时限 | F1: 客服侧工单流水号 | G1: 故障现象 | H1: T1受理时间 | I1: 投诉细类 | J1: T1处理人 | K1: T1处理人电话 | L1: 新小区名称 | M1: 装维所属网格 | N1: t3环节处理措施 | O1: 装维处理人账号 | P1: 首次响应成功时间 | Q1: 关联装移机单号 | R1: =IF(OR(LEFT(L1,2)="高新"),"奎文",IF(LEFT(L1,2)="峡山","坊子",IF(LEFT(L1,2)="滨海","寒亭",LEFT(L1,2)))) -> 新小 | S1: =TEXT(B1,"mmdd") -> 派单时间
A2: SD-057-240703-759214-7766 | B2: 2024-07-03 20:56:25 | C2: 潍坊 | D2: 普通区域-青州市-代楼-15095195694-200M-业务受理宽带-次数0-202407030000717621 | E2: 2024-07-04 18:00:00 | F2: 202407030000717621 | G2: 202407030000717621#导航立单,用户所在位置有群障,已向客户播报,客户要求装维回访.此工单为群障修复工单,根据群障全量闭环管理要求,为确保客户网络通畅,请装维人员跟进修复网络问题,谢谢.联系电话：15095195694 | H2: 2024-07-03 21:06:12 | I2: 业务受理->线上义诊->家庭业务->全局流转->功能使用->群障弹窗->全局流转 | J2: 王迪 | K2: 15706307660 | L2: 青州市 | M2: 家客铁通潍坊青州-何官乡镇装维组 | N2: 用户感觉网速慢，但测速达标 | O2: dw3_jk_wangdi | P2: 2024-07-03 21:07:02 | R2: =IF(OR(LEFT(L2,2)="高新"),"奎文",IF(LEFT(L2,2)="峡山","坊子",IF(LEFT(L2,2)="滨海","寒亭",LEFT(L2,2)))) -> 青州 | S2: =TEXT(B2,"mmdd") -> 0703
A3: SD-057-240703-817504-3357 | B3: 2024-07-03 13:26:20 | C3: 潍坊 | D3: 【重投】-(目标)普通区域-安丘市-景阳小区(含景中路沿街)-13793676927-200M-宽带上网投诉-次数0-20240703132345X225357224 | E3: 2024-07-04 13:00:00 | F3: 20240703132345X225357224 | G3: 流程受理流水号：20240703132216137936769271091549 客户号码:13793676927 客户姓名:张** 投诉地市:潍坊 来话流水:2024070313203096320855956 宽带账号:13793676927 宽带账号归属地市:潍坊 宽带账号归属区县:安丘市 故障地址:潍坊安丘市景芝镇景中路景阳小区景阳小区3号楼********* 联系电话:13963687477 联系人:先生/女士 工单紧急程度:一般 是否有升级投诉倾向:否 是否重复投诉:否 是否携转意向:否 是否投诉倾向:否 是否智能网关:智能网关 当前是否在线:否 接入方式:FTTH 端到端诊断结果:状态正常 是否质差终端:无质差信息 光功率:无 故障大类:宽带/电视 故障细类:宽带无法上网(专席) 携转原因: 故障时间:2024-07-03 13:21:49 具体故障现象:光猫灯不亮 插排有电 拔插电源线 换插头位置 按开光 未恢复 谢谢 客户其他诉求: | H3: 2024-07-03 13:29:55 | I3: 家宽业务->网络质量->家庭宽带->全局流转->功能使用->网络无法连接->全局流转 | J3: 刘彤彤 | K3: 15706307065 | L3: 安丘市 | M3: 家客铁通潍坊安丘-景芝乡镇装维组 | N3: 更换尾纤 | O3: dw3_jk_liutongtong | P3: 2024-07-03 13:30:41 | R3: =IF(OR(LEFT(L3,2)="高新"),"奎文",IF(LEFT(L3,2)="峡山","坊子",IF(LEFT(L3,2)="滨海","寒亭",LEFT(L3,2)))) -> 安丘 | S3: =TEXT(B3,"mmdd") -> 0703
A4: SD-057-240703-826105-4583 | B4: 2024-07-03 15:45:01 | C4: 潍坊 | D4: 普通区域-安丘市-育英家园-18364666990-300M-宽带上网投诉-次数0-202407030000480165 | E4: 2024-07-04 08:00:00 | F4: 202407030000480165 | G4: 202407030000480165#宽带账号：18364666990；宽带地址：潍坊安丘市兴安街道南苑路育英家园迁2号楼*****；客户来电反映无法上网，客户不在现场，无法配合线上指导，要求上门，请协助处理，谢谢！联系电话：18364666990；联系人：先生；来电流水：2024070315400866320855840 | H4: 2024-07-03 15:52:38 | I4: 家庭咨询->网络质量->家庭宽带->全局流转->功能使用->客户要求装维上门服务->全局流转 | J4: 周龙涛 | K4: 15706307025 | L4: 安丘市 | M4: 家客铁通潍坊安丘-潍安路城区装维组 | N4: 重新连接机顶盒网络 | O4: dw3_jk_zhoulongtao | P4: 2024-07-03 15:53:12 | Q4: SD-851-247561-5815-25557 | R4: =IF(OR(LEFT(L4,2)="高新"),"奎文",IF(LEFT(L4,2)="峡山","坊子",IF(LEFT(L4,2)="滨海","寒亭",LEFT(L4,2)))) -> 安丘 | S4: =TEXT(B4,"mmdd") -> 0703
A5: SD-057-240703-857319-4593 | B5: 2024-07-03 15:47:12 | C5: 潍坊 | D5: 【调研】-(目标)普通区域-高密市-苗家屯自然村-13406603097-300M-宽带上网投诉-次数0-20240703154557X757357681 | E5: 2024-07-04 08:00:00 | F5: 20240703154557X757357681 | G5: 【农村网络投诉】【预处理派单】宽带账号：13406603097，宽带地址： 潍坊高密市密水街道苗家屯，故障现象：无法连接，故障现象类型：手机或笔记本电脑，客户诉求：客户来电反映宽带无法上网，注册灯熄灭，将光纤线插紧捋直、重启光猫后未恢复，请协助谢谢，联系电话：17662431408，通话流水：2024070315354658220895151。接入方式：FTTH，当前是否在线：不在线，端到端诊断结果：状态正常，是否智能网关：是，光功率。 | H5: 2024-07-03 15:51:03 | I5: 家宽业务->网络质量->家庭宽带->全局流转->功能使用->LOS红灯，无法上网->全局流转 | J5: 冷光朋 | K5: 15706307276 | L5: 高密市 | M5: 家客铁通潍坊高密-密水城区装维组 | N5: 更换光猫 | O5: dw3_jk_lengguangpeng | P5: 2024-07-03 15:56:44 | R5: =IF(OR(LEFT(L5,2)="高新"),"奎文",IF(LEFT(L5,2)="峡山","坊子",IF(LEFT(L5,2)="滨海","寒亭",LEFT(L5,2)))) -> 高密 | S5: =TEXT(B5,"mmdd") -> 0703
A6: SD-057-240703-308549-29 | B6: 2024-07-03 07:03:07 | C6: 潍坊 | D6: 80+普通-普通区域-青州市-董家庄村自然村-15069657728-1000M-宽带上网投诉-次数0-202407030000092937 | E6: 2024-07-03 19:00:00 | F6: 202407030000092937 | G6: 202407030000092937#流程受理流水号：20240703070140150696577281000138 客户号码:15069657728 客户姓名:徐** 投诉地市:潍坊 来话流水:2024070307011938120846658 宽带账号:15069657728 宽带账号归属地市:潍坊 宽带账号归属区县:青州市 故障地址:潍坊青州市黄楼街道董家庄村董家庄村自然村二次扩容7号箱（董福华）********* 联系电话:15069657728 联系人:先生/女士 工单紧急程度:非常紧急 是否有升级投诉倾向:否 是否重复投诉:否 是否携转意向:否 是否投诉倾向:否 是否智能网关:智能网关 当前是否在线:否 接入方式:FTTH 端到端诊断结果:光猫掉电 是否质差终端:无质差信息 光功率:无 故障大类:宽带/电视 故障细类:宽带无法上网 携转原因: 故障时间:2024-07-03 07:02:42 具体故障现象:光猫亮红灯， 客户其他诉求: ;宽带小区$[董家庄村自然村]$ | H6: 2024-07-03 07:07:25 | I6: 家宽咨询->网络质量->家庭宽带->全局流转->功能使用->LOS红灯，无法上网->全局流转 | J6: 李明辉 | K6: 15706307719 | L6: 青州市 | M6: 家客铁通潍坊青州-开发区城区装维组 | N6: 重新配置光猫 | O6: dw3_jk_liminghui | P6: 2024-07-03 07:09:17 | Q6: SD-851-273959-379-23823 | R6: =IF(OR(LEFT(L6,2)="高新"),"奎文",IF(LEFT(L6,2)="峡山","坊子",IF(LEFT(L6,2)="滨海","寒亭",LEFT(L6,2)))) -> 青州 | S6: =TEXT(B6,"mmdd") -> 0703
A7: SD-057-240703-805142-3354 | B7: 2024-07-03 13:26:09 | C7: 潍坊 | D7: 【调研】-80+金卡-普通区域-奎文区-阳光100二期-18263663731-1000M-宽带上网投诉-次数0-20240703132329X209361728 | E7: 2024-07-04 08:00:00 | F7: 20240703132329X209361728 | G7: 流程受理流水号：20240703132151182636637311091469 客户号码:18263663731 客户姓名:陈** 投诉地市:潍坊 来话流水:2024070313195415120851352 宽带账号:18263663731 宽带账号归属地市:潍坊 宽带账号归属区县:奎文区 故障地址:潍坊奎文区广文街道胜利街阳光100二期7号楼********* 联系电话:13280706363 联系人:先生/女士 工单紧急程度:非常紧急 是否有升级投诉倾向:否 是否重复投诉:否 是否携转意向:否 是否投诉倾向:否 是否智能网关:智能网关 当前是否在线:否 接入方式:FTTH 端到端诊断结果:状态正常 是否质差终端:无质差信息 光功率:无 故障大类:宽带/电视 故障细类:宽带无法上网(专席) 携转原因: 故障时间:2024-07-03 13:18:45 具体故障现象:注册闪烁：引导客户将光纤线插紧，将弯折的位置捋直后重启无效 客户其他诉求: | H7: 2024-07-03 13:27:32 | I7: 家宽业务->网络质量->家庭宽带->全局流转->功能使用->网络无法连接->全局流转 | J7: 孙晓波 | K7: 15706366530 | L7: 奎文区 | M7: 家客铁通潍坊奎文-樱前街城区装维组 | N7: 重新配置光猫 | O7: dw3_jk_sunxiaobo | P7: 2024-07-03 13:27:48 | Q7: SD-851-278690-7493-19981 | R7: =IF(OR(LEFT(L7,2)="高新"),"奎文",IF(LEFT(L7,2)="峡山","坊子",IF(LEFT(L7,2)="滨海","寒亭",LEFT(L7,2)))) -> 奎文 | S7: =TEXT(B7,"mmdd") -> 0703
A8: SD-057-240703-023865-113 | B8: 2024-07-03 08:00:06 | C8: 潍坊 | D8: 80+普通-普通区域-临朐县-后楼安置楼-15966101741-300M-宽带上网投诉-次数0-202407030000093591 | E8: 2024-07-03 19:00:00 | F8: 202407030000093591 | G8: 202407030000093591#流程受理流水号：20240703075752159661017411000514 客户号码:15966101741 客户姓名:聂** 投诉地市:潍坊 来话流水:2024070307571144220866176 宽带账号:15966101741 宽带账号归属地市:潍坊 宽带账号归属区县:临朐县 故障地址:潍坊临朐县城关街道龙泉路后楼安置楼恒信首府6号楼********* 联系电话:15966101741 联系人:先生/女士 工单紧急程度:非常紧急 是否有升级投诉倾向:否 是否重复投诉:否 是否携转意向:否 是否投诉倾向:否 是否智能网关:智能网关 当前是否在线:否 接入方式:FTTH 端到端诊断结果:状态正常 是否质差终端:无质差信息 光功率:无 故障大类:宽带/电视 故障细类:宽带无法上网 携转原因: 故障时间:2024-07-03 07:59:05 具体故障现象:光猫亮红灯 客户其他诉求:客户要求尽快处理。 ;宽带小区$[后楼安置楼]$ | H8: 2024-07-03 08:07:52 | I8: 家宽咨询->网络质量->家庭宽带->全局流转->功能使用->LOS红灯，无法上网->全局流转 | J8: 邓兆然 | K8: 15706307539 | L8: 临朐县 | M8: 家客铁通潍坊临朐-城关城区装维组 | N8: 重新熔接皮线 | O8: dw3_jk_dengzhaoran | P8: 2024-07-03 08:08:20 | R8: =IF(OR(LEFT(L8,2)="高新"),"奎文",IF(LEFT(L8,2)="峡山","坊子",IF(LEFT(L8,2)="滨海","寒亭",LEFT(L8,2)))) -> 临朐 | S8: =TEXT(B8,"mmdd") -> 0703
A9: SD-057-240703-987615-138 | B9: 2024-07-03 08:07:05 | C9: 潍坊 | D9: 80+普通-普通区域-安丘市-关王村自然村-13465361792-200M-业务受理宽带-次数0-202407030000090351 | E9: 2024-07-04 08:08:00 | F9: 202407030000090351 | G9: 202407030000090351# 宽带账号:13465361792; 联系电话：13465361792，问题类型：此工单为群障修复工单，根据群障全量闭环修复管理要求，为确保客户网络通畅，请装维人员跟进修复网络问题，谢谢！ 群障标题：公告。故障描述：分支光纤断或OLT检测不到ONT的预期的光信号(LOSi/LOBi)主叫号码：13465361792.0;该号码仅供参考，请优先联系宽带账号。 | H9: 2024-07-03 08:13:58 | I9: 业务受理->线上义诊->家庭业务->全局流转->功能使用->群障弹窗->全局流转 | J9: 宋龙海 | K9: 15706307016 | L9: 安丘市 | M9: 家客铁通潍坊安丘-刘家尧乡镇装维组 | N9: 重新熔接皮线 | O9: dw3_jk_songlonghai | P9: 2024-07-03 08:16:20 | R9: =IF(OR(LEFT(L9,2)="高新"),"奎文",IF(LEFT(L9,2)="峡山","坊子",IF(LEFT(L9,2)="滨海","寒亭",LEFT(L9,2)))) -> 安丘 | S9: =TEXT(B9,"mmdd") -> 0703
A10: SD-057-240703-368195-4577 | B10: 2024-07-03 15:44:30 | C10: 潍坊 | D10: FTTR-普通区域-临朐县-大成新文华苑一期-15953628966-1000M-宽带上网投诉-次数0-202407030000479491 | E10: 2024-07-04 08:00:00 | F10: 202407030000479491 | G10: 202407030000479491#宽带账号：15953628966；宽带地址：潍坊临朐县城关街道秦池路大成新文华苑一期1号楼；客户来电反映宽带使用不畅，客户不在现场，无法配合线上指导，要求上门，请协助处理，谢谢！联系电话：本机；联系人：先生；来电流水2024070315422624620886980 | H10: 2024-07-03 15:52:38 | I10: 家庭咨询->网络质量->家庭宽带->全局流转->功能使用->客户要求装维上门服务->全局流转 | J10: 韩崇 | K10: 15706307608 | L10: 临朐县 | M10: 家客铁通潍坊临朐-城关城区装维组 | N10: 重新连接机顶盒网络 | O10: dw3_jk_hanchong | P10: 2024-07-03 15:53:09 | Q10: SD-851-258399-6579-23200 | R10: =IF(OR(LEFT(L10,2)="高新"),"奎文",IF(LEFT(L10,2)="峡山","坊子",IF(LEFT(L10,2)="滨海","寒亭",LEFT(L10,2)))) -> 临朐 | S10: =TEXT(B10,"mmdd") -> 0703
A11: SD-057-240703-451762-61 | B11: 2024-07-03 07:28:05 | C11: 潍坊 | D11: 【调研】-普通区域-诸城市-山钢碧桂园·翡翠城-18805365378-200M-宽带上网投诉-次数0-202407030000090931 一级督办 | E11: 2024-07-03 19:00:00 | F11: 202407030000090931 | G11: 202407030000090931#流程受理流水号：20240703072721188053653781000254 客户号码:18805365378 客户姓名:郭** 投诉地市:潍坊 来话流水:2024070307224877020852549 宽带账号:18805365378 宽带账号归属地市:潍坊 宽带账号归属区县:诸城市 故障地址:潍坊诸城市密州街道南外环山钢碧桂园·翡翠城27号楼********* 联系电话:18353631333 联系人:先生 工单紧急程度:一般 是否有升级投诉倾向:否 是否重复投诉:否 是否携转意向:否 是否投诉倾向:否 是否智能网关:智能网关 当前是否在线:是 接入方式:FTTH 端到端诊断结果:客户侧设备问题（新增） 是否质差终端:无质差信息 光功率:-19.82 故障大类:宽带/电视 故障细类:宽带无法上网 携转原因: 故障时间:2024-07-03 07:27:36 具体故障现象:打不开网页， 客户其他诉求: ;宽带小区$[山钢碧桂园·翡翠城]$ | H11: 2024-07-03 07:35:11 | I11: 家宽咨询->网络质量->家庭宽带->全局流转->功能使用->网络连接掉线->全局流转 | J11: 刘永 | K11: 15706307953 | L11: 诸城市 | M11: 家客铁通潍坊诸城-兴华东路城区装维组 | N11: 机顶盒重新升级 | O11: dw3_jk_liuyong | P11: 2024-07-03 07:35:31 | Q11: SD-851-253327-20031-7246 | R11: =IF(OR(LEFT(L11,2)="高新"),"奎文",IF(LEFT(L11,2)="峡山","坊子",IF(LEFT(L11,2)="滨海","寒亭",LEFT(L11,2)))) -> 诸城 | S11: =TEXT(B11,"mmdd") -> 0703
A12: SD-057-240703-748950-4581 | B12: 2024-07-03 15:44:36 | C12: 潍坊 | D12: FTTR-普通区域-坊子区-下小路沿街-15726054555-1000M-宽带上网投诉-次数0-20240703154343X623753968 一级督办 | E12: 2024-07-04 08:00:00 | F12: 20240703154343X623753968 | G12: 流程受理流水号：20240703154145157260545551128630 客户号码:15726054555 客户姓名:郭** 投诉地市:潍坊 来话流水:2024070315355941720898098 宽带账号:15726054555 宽带账号归属地市:潍坊 宽带账号归属区县:坊子区 故障地址:潍坊坊子区岞山街道岞山大街下小路沿街神州姜窖2号箱李鑫灏外墙 联系电话:15726054555 联系人:先生/女士 工单紧急程度:非常紧急 是否有升级投诉倾向:是 是否重复投诉:否 是否携转意向:否 是否投诉倾向:是 是否智能网关:智能网关 当前是否在线:是 接入方式:FTTH 端到端诊断结果:客户侧设备问题（新增） 是否质差终端:无质差信息 光功率:-14.93 故障大类:宽带/电视 故障细类:网速慢/上网掉线(专席) 携转原因: 故障时间:2024-07-03 15:41:57 具体故障现象:网速慢卡顿，客户称为移动公司线上恶意限速了，在线时间不就，设备支持带宽无损耗，通话中提及12300投诉，请协助，谢谢。 客户其他诉求: | H12: 2024-07-03 15:49:49 | I12: 家宽业务->网络质量->家庭宽带->全局流转->功能使用->频繁出现故障、网速慢->全局流转 | J12: 王其治 | K12: 15706307917 | L12: 坊子区 | M12: 家客铁通潍坊坊子-太保庄乡镇装维组 | O12: dw3_jk_wangqizhi | P12: 2024-07-03 15:50:29 | Q12: SD-851-320940-17145-7584 | R12: =IF(OR(LEFT(L12,2)="高新"),"奎文",IF(LEFT(L12,2)="峡山","坊子",IF(LEFT(L12,2)="滨海","寒亭",LEFT(L12,2)))) -> 坊子 | S12: =TEXT(B12,"mmdd") -> 0703
A13: SD-057-240703-986172-4598 | B13: 2024-07-03 15:47:30 | C13: 潍坊 | D13: 普通区域-临朐县-石门小区-17888364612-300M-宽带上网投诉-次数0-202407030000483603 | E13: 2024-07-04 08:00:00 | F13: 202407030000483603 | G13: 202407030000483603#宽带账号：17888364612；宽带地址：潍坊临朐县城关街道弥河路石门小区15号楼**；客户来电反映宽带上网慢，客户不配合排障，要求上门，请协助处理，谢谢！联系电话：17888364612；联系人：先生；来电流水：2024070315434160620804339。 | H13: 2024-07-03 15:52:06 | I13: 家庭咨询->网络质量->家庭宽带->全局流转->功能使用->客户要求装维上门服务->全局流转 | J13: 尹筱 | K13: 15706307601 | L13: 临朐县 | M13: 家客铁通潍坊临朐-城关城区装维组 | N13: 重启路由器 | O13: dw3_jk_yinxiao | P13: 2024-07-03 15:55:14 | Q13: SD-852-276576-789-28795 | R13: =IF(OR(LEFT(L13,2)="高新"),"奎文",IF(LEFT(L13,2)="峡山","坊子",IF(LEFT(L13,2)="滨海","寒亭",LEFT(L13,2)))) -> 临朐 | S13: =TEXT(B13,"mmdd") -> 0703
A14: SD-057-240703-341876-3374 | B14: 2024-07-03 13:28:33 | C14: 潍坊 | D14: 普通区域-安丘市-江山一品-18706691699-500M-宽带上网投诉-次数0-202407030000343694 | E14: 2024-07-04 08:00:00 | F14: 202407030000343694 | G14: 202407030000343694# 宽带账号：18706691699；宽带地址：潍坊安丘市兴安街道金融街江山一品江山一品14号楼*****客户来电反映 移动高清 不能看/客户不配合排障，要求上门，请协助处理，谢谢！联系电话：***；联系人：18706691699；来电流水：2024070313234194320879800。 | H14: 2024-07-03 13:31:14 | I14: 家庭咨询->网络质量->家庭宽带->全局流转->功能使用->客户要求装维上门服务->全局流转 | J14: 杨晓龙 | K14: 15706307058 | L14: 安丘市 | M14: 家客铁通潍坊安丘-永安路城区装维组 | N14: 重新连接机顶盒网络 | O14: dw3_jk_yangxiaolong | P14: 2024-07-03 13:31:48 | Q14: SD-851-232227-6269-4730 | R14: =IF(OR(LEFT(L14,2)="高新"),"奎文",IF(LEFT(L14,2)="峡山","坊子",IF(LEFT(L14,2)="滨海","寒亭",LEFT(L14,2)))) -> 安丘 | S14: =TEXT(B14,"mmdd") -> 0703
A15: SD-057-240703-829145-7733 | B15: 2024-07-03 20:51:15 | C15: 潍坊 | D15: 【调研】-80+银卡-普通区域-临朐县-御景花园-15054846650-100M-宽带上网投诉-次数0-202407030000715830 | E15: 2024-07-04 19:00:00 | F15: 202407030000715830 | G15: 202407030000715830#流程受理流水号：20240703205032150548466501200165 客户号码:15054846650 客户姓名:李** 投诉地市:潍坊 来话流水:2024070320500520420834842 宽带账号:15054846650 宽带账号归属地市:潍坊 宽带账号归属区县:临朐县 故障地址:潍坊临朐县城关街道骈邑路御景花园2号楼********* 联系电话:15054846650 联系人:先生/女士 工单紧急程度:一般 是否有升级投诉倾向:否 是否重复投诉:否 是否携转意向:否 是否投诉倾向:否 是否智能网关:智能网关 当前是否在线:否 接入方式:FTTH 端到端诊断结果:状态正常 是否质差终端:无质差信息 光功率:无 故障大类:宽带/电视 故障细类:宽带无法上网 携转原因: 故障时间:2024-07-03 20:50:55 具体故障现象:打不开网页， 客户其他诉求: ;宽带小区$[御景花园]$ | H15: 2024-07-03 20:58:59 | I15: 家宽咨询->网络质量->家庭宽带->全局流转->功能使用->网络无法连接->全局流转 | J15: 韩太永 | K15: 15706307573 | L15: 临朐县 | M15: 家客铁通潍坊临朐-城关城区装维组 | N15: 重新熔接皮线 | O15: dw3_jk_hantaiyong | P15: 2024-07-03 21:05:42 | R15: =IF(OR(LEFT(L15,2)="高新"),"奎文",IF(LEFT(L15,2)="峡山","坊子",IF(LEFT(L15,2)="滨海","寒亭",LEFT(L15,2)))) -> 临朐 | S15: =TEXT(B15,"mmdd") -> 0703
A16: SD-057-240703-670325-142 | B16: 2024-07-03 08:07:16 | C16: 潍坊 | D16: 【调研】-普通区域-奎文区-金玉豪府-13406618893-200M-业务受理宽带-次数0-202407030000093176 | E16: 2024-07-04 08:08:00 | F16: 202407030000093176 | G16: 202407030000093176#【已关注中国移动10086微信公众号】 宽带账号:13406618893; 联系电话：13406618893，问题类型：此工单为群障修复工单，根据群障全量闭环修复管理要求，为确保客户网络通畅，请装维人员跟进修复网络问题，谢谢！ 群障标题：公告。故障描述：分支光纤断或OLT检测不到ONT的预期的光信号(LOSi/LOBi)主叫号码：13406618893.0;该号码仅供参考，请优先联系宽带账号。 | H16: 2024-07-03 08:14:03 | I16: 业务受理->线上义诊->家庭业务->全局流转->功能使用->群障弹窗->全局流转 | J16: 吕开迪 | K16: 15706307454 | L16: 奎文区 | M16: 家客铁通潍坊奎文-北宫街城区装维组 | N16: 更换尾纤 | O16: dw3_jk_lvkaidi | P16: 2024-07-03 08:14:24 | Q16: SD-852-290447-2351-5113 | R16: =IF(OR(LEFT(L16,2)="高新"),"奎文",IF(LEFT(L16,2)="峡山","坊子",IF(LEFT(L16,2)="滨海","寒亭",LEFT(L16,2)))) -> 奎文 | S16: =TEXT(B16,"mmdd") -> 0703
A17: SD-057-240703-315097-7752 | B17: 2024-07-03 20:53:34 | C17: 潍坊 | D17: 80+金卡-普通区域-奎文区-舜华园-13646467963-500M-宽带上网投诉-次数0-20240703205250X170928541 | E17: 2024-07-04 19:00:00 | F17: 20240703205250X170928541 | G17: 流程受理流水号：20240703205132136464679631200295 客户号码:13646467963 客户姓名:张** 投诉地市:潍坊 来话流水:2024070320505323720838474 宽带账号:13646467963 宽带账号归属地市:潍坊 宽带账号归属区县:奎文区 故障地址:潍坊奎文区大虞街道北宫街舜华园4号楼********* 联系电话:18263672507 联系人:先生/女士 工单紧急程度:非常紧急 是否有升级投诉倾向:否 是否重复投诉:否 是否携转意向:否 是否投诉倾向:否 是否智能网关:智能网关 当前是否在线:是 接入方式:FTTH 端到端诊断结果:客户侧设备问题（新增） 是否质差终端:无质差信息 光功率:-19.82 故障大类:宽带/电视 故障细类:宽带无法上网 携转原因: 故障时间:2024-07-03 20:51:54 具体故障现象:光猫灯正常但电脑手机无法上网， 客户其他诉求:客户来电要求尽快回电处理 | H17: 2024-07-03 20:55:07 | I17: 家宽业务->网络质量->家庭宽带->全局流转->功能使用->网络无法连接->全局流转 | J17: 李春龙 | K17: 15706366503 | L17: 奎文区 | M17: 家客铁通潍坊奎文-鸢飞路城区装维组 | N17: 更换热缩管 | O17: dw3_jk_lichunlong | P17: 2024-07-03 20:59:43 | Q17: SD-851-303890-2620-15513 | R17: =IF(OR(LEFT(L17,2)="高新"),"奎文",IF(LEFT(L17,2)="峡山","坊子",IF(LEFT(L17,2)="滨海","寒亭",LEFT(L17,2)))) -> 奎文 | S17: =TEXT(B17,"mmdd") -> 0703
A18: SD-057-240703-524103-7751 | B18: 2024-07-03 20:53:30 | C18: 潍坊 | D18: 【调研】-80+金卡-普通区域-奎文区-锦绣苑-13964638833-1000M-宽带上网投诉-次数0-20240703205231X151615755 | E18: 2024-07-04 19:00:00 | F18: 20240703205231X151615755 | G18: 流程受理流水号：20240703205109139646388331200245 客户号码:13964638833 客户姓名:赵** 投诉地市:潍坊 来话流水:2024070320475819120825156 宽带账号:13964638833 宽带账号归属地市:潍坊 宽带账号归属区县:奎文区 故障地址:潍坊奎文区北苑街道玉清街锦绣苑14号楼********* 联系电话:13964638833 联系人:先生/女士 工单紧急程度:非常紧急 是否有升级投诉倾向:否 是否重复投诉:否 是否携转意向:否 是否投诉倾向:否 是否智能网关:智能网关 当前是否在线:否 接入方式:FTTH 端到端诊断结果:设备告警 是否质差终端:无质差信息 光功率:无 故障大类:宽带/电视 故障细类:宽带无法上网(专席) 携转原因: 故障时间:2024-07-03 20:50:23 具体故障现象:客户来电反映无法上网，光信号亮红灯：拔插捋直光纤线未恢复，请处理，谢谢。 客户其他诉求: | H18: 2024-07-03 20:55:52 | I18: 家宽业务->网络质量->家庭宽带->全局流转->功能使用->网络无法连接->全局流转 | J18: 张根涛 | K18: 15706307406 | L18: 奎文区 | M18: 家客铁通潍坊奎文-鸢飞路城区装维组 | O18: dw3_jk_zhangentao | P18: 2024-07-03 20:56:23 | Q18: SD-851-255278-20071-11623 | R18: =IF(OR(LEFT(L18,2)="高新"),"奎文",IF(LEFT(L18,2)="峡山","坊子",IF(LEFT(L18,2)="滨海","寒亭",LEFT(L18,2)))) -> 奎文 | S18: =TEXT(B18,"mmdd") -> 0703
A19: SD-057-240703-526913-3320 | B19: 2024-07-03 13:20:38 | C19: 潍坊 | D19: 【调研】-(目标)普通区域-安丘市-坡庄村自然村-13863641309-300M-宽带上网投诉-次数0-20240703131840X920574522 | E19: 2024-07-04 08:00:00 | F19: 20240703131840X920574522 | G19: 【农村网络投诉】流程受理流水号：20240703131545138636413091090219 客户号码:13863641309 客户姓名:李* 投诉地市:潍坊 来话流水:2024070313141761520809073 宽带账号:13863641309 宽带账号归属地市:潍坊 宽带账号归属区县:安丘市 故障地址:潍坊安丘市官庄镇坡庄村坡庄村自然村坡庄三次追加9号箱游成敏********* 联系电话:15753680705 联系人:先生 工单紧急程度:一般 是否有升级投诉倾向:否 是否重复投诉:否 是否携转意向:否 是否投诉倾向:否 是否智能网关:智能网关 当前是否在线:否 接入方式:FTTH 端到端诊断结果:状态正常 是否质差终端:无质差信息 光功率:无 故障大类:宽带/电视 故障细类:宽带无法上网 携转原因: 故障时间:2024-07-03 13:17:11 具体故障现象:提示网络无法连接， 客户其他诉求: | H19: 2024-07-03 13:28:36 | I19: 家宽业务->网络质量->家庭宽带->全局流转->功能使用->网络无法连接->全局流转 | J19: 李焕江 | K19: 15706307048 | L19: 安丘市 | M19: 家客铁通潍坊安丘-官庄乡镇装维组 | O19: dw3_jk_lihuanjiang | P19: 2024-07-03 13:29:11 | R19: =IF(OR(LEFT(L19,2)="高新"),"奎文",IF(LEFT(L19,2)="峡山","坊子",IF(LEFT(L19,2)="滨海","寒亭",LEFT(L19,2)))) -> 安丘 | S19: =TEXT(B19,"mmdd") -> 0703
A20: SD-057-240703-583196-3340 | B20: 2024-07-03 13:23:36 | C20: 潍坊 | D20: 普通区域-安丘市-蒯沟-15966153193-300M-宽带上网投诉-次数0-20240703132230X150476217 | E20: 2024-07-04 08:00:00 | F20: 20240703132230X150476217 | G20: 【农村网络投诉】流程受理流水号：20240703132130159661531931091407 客户号码:15966153193 客户姓名:殷** 投诉地市:潍坊 来话流水:2024070313200418120852632 宽带账号:15966153193 宽带账号归属地市:潍坊 宽带账号归属区县:安丘市 故障地址:潍坊安丘市石埠子镇蒯沟村蒯沟蒯沟二次追加5号箱张杰********* 联系电话:15954415739 联系人:先生/女士 工单紧急程度:一般 是否有升级投诉倾向:否 是否重复投诉:否 是否携转意向:否 是否投诉倾向:否 是否智能网关:智能网关 当前是否在线:否 接入方式:FTTH 端到端诊断结果:状态正常 是否质差终端:无质差信息 光功率:无 故障大类:宽带/电视 故障细类:宽带无法上网(专席) 携转原因: 故障时间:2024-07-03 13:22:28 具体故障现象:光猫亮红灯， 客户其他诉求: | H20: 2024-07-03 13:30:06 | I20: 家宽业务->网络质量->家庭宽带->全局流转->功能使用->网络无法连接->全局流转 | J20: 鞠知彬 | K20: 15706307020 | L20: 安丘市 | M20: 家客铁通潍坊安丘-石埠子乡镇装维组 | N20: 更换二级分光器 | O20: dw3_jk_juzhibin | P20: 2024-07-03 13:30:38 | R20: =IF(OR(LEFT(L20,2)="高新"),"奎文",IF(LEFT(L20,2)="峡山","坊子",IF(LEFT(L20,2)="滨海","寒亭",LEFT(L20,2)))) -> 安丘 | S20: =TEXT(B20,"mmdd") -> 0703
A21: SD-057-240703-160972-4549 | B21: 2024-07-03 15:41:07 | C21: 潍坊 | D21: 【调研】-80+银卡-普通区域-高密市-梓潼家园-13853628968-1000M-宽带上网投诉-次数0-20240703153832X312157112 | E21: 2024-07-04 08:00:00 | F21: 20240703153832X312157112 | G21: 流程受理流水号：20240703153725138536289681127368 客户号码:13853628968 客户姓名:单** 投诉地市:潍坊 来话流水:2024070315370080820812386 宽带账号:13853628968 宽带账号归属地市:潍坊 宽带账号归属区县:高密市 故障地址:潍坊高密市朝阳街道夷安大道梓潼家园101号箱********* 联系电话:13853628968 联系人:先生/女士 工单紧急程度:非常紧急 是否有升级投诉倾向:否 是否重复投诉:否 是否携转意向:否 是否投诉倾向:否 是否智能网关:智能网关 当前是否在线:是 接入方式:FTTH 端到端诊断结果:客户侧设备问题（新增） 是否质差终端:无质差信息 光功率:-17.03 故障大类:宽带/电视 故障细类:宽带无法上网(专席) 携转原因: 故障时间:2024-07-03 15:39:08 具体故障现象:提示网络无法连接， 客户其他诉求: | H21: 2024-07-03 16:02:22 | I21: 家宽业务->网络质量->家庭宽带->全局流转->功能使用->网络无法连接->全局流转 | J21: 满勇 | K21: 15706307304 | L21: 高密市 | M21: 家客铁通潍坊高密-朝阳城区装维组 | N21: 更换二级分光器 | O21: dw3_jk_manyong | P21: 2024-07-03 16:02:54 | Q21: SD-851-300127-29120-17453 | R21: =IF(OR(LEFT(L21,2)="高新"),"奎文",IF(LEFT(L21,2)="峡山","坊子",IF(LEFT(L21,2)="滨海","寒亭",LEFT(L21,2)))) -> 高密 | S21: =TEXT(B21,"mmdd") -> 0703
A22: SD-057-240703-982607-5107 | B22: 2024-07-03 16:50:20 | C22: 潍坊 | D22: 【重投】-普通区域-安丘市-乐山原墅-13646463446-200M-魔百和投诉-次数0-202407030000543681 | E22: 2024-07-04 17:51:00 | F22: 202407030000543681 | G22: 202407030000543681#【已关注中国移动10086微信公众号】流程受理流水号：20240703164938136464634461149054 客户号码:13646463446 客户姓名:李** 投诉地市:潍坊 来话流水:2024070316434570620829899 宽带账号:13646463446 宽带账号归属地市:潍坊 宽带账号归属区县:安丘市 故障地址:潍坊安丘市新安街道莲花山路乐山原墅乐山原墅Y3号楼********* 联系电话:13646463446 联系人:女士 工单紧急程度:一般 是否有升级投诉倾向:否 是否重复投诉:否 是否携转意向:否 是否投诉倾向:否 是否智能网关:智能网关 当前是否在线:是 接入方式:FTTH 端到端诊断结果:客户侧设备问题（新增） 是否质差终端:无质差信息 光功率:-22.21 故障大类:宽带/电视 故障细类:移动高清电视故障(专席) 携转原因: 故障时间:2024-07-03 16:48:32 魔百和单播/组播:组播 具体故障现象:电视机提示无信号 客户其他诉求:尽快处理 谢谢 魔百和单/组播：组播;宽带小区$[乐山原墅]$ | H22: 2024-07-03 16:53:27 | I22: 家庭咨询->产品质量->互联网电视(移动高清)->全局流转->售后服务->电视机提示“无信号”->全局流转 | J22: 苏凯明 | K22: 15706307021 | L22: 安丘市 | M22: 家客铁通潍坊安丘-刘家尧乡镇装维组 | N22: 机顶盒恢复出厂 | O22: dw3_jk_sukaiming | P22: 2024-07-03 16:53:45 | R22: =IF(OR(LEFT(L22,2)="高新"),"奎文",IF(LEFT(L22,2)="峡山","坊子",IF(LEFT(L22,2)="滨海","寒亭",LEFT(L22,2)))) -> 安丘 | S22: =TEXT(B22,"mmdd") -> 0703
A23: SD-057-240703-649735-7685 | B23: 2024-07-03 20:43:42 | C23: 潍坊 | D23: 普通区域-寒亭区-元和新城-15163615099-300M-宽带延伸服务-次数0-202407030000712984 | E23: 2024-07-04 18:00:00 | F23: 202407030000712984 | G23: 202407030000712984#流程受理流水号：20240703204219151636150991199085 客户号码:15163615099 客户姓名:董** 投诉地市:潍坊 来话流水:2024070320412863720894673 宽带账号:15163615099 宽带账号归属地市:潍坊 宽带账号归属区县:寒亭区 故障地址:潍坊寒亭区寒亭街道益新街元和新城29号楼********* 联系电话:15163615099 联系人:先生/女士 工单紧急程度:紧急 是否有升级投诉倾向:否 是否重复投诉:否 是否携转意向:否 是否投诉倾向:否 是否智能网关:智能网关 当前是否在线:是 接入方式:FTTH 是否质差终端:是 光功率:-18.99 故障大类:宽带/电视 故障细类:宽带延伸服务 携转原因: 故障时间:2024-07-03 20:42:31 具体故障现象:客户对换光锚收费100元不认可，请处理谢谢！ | H23: 2024-07-03 20:45:49 | I23: 业务受理->宽带延伸服务->家庭业务->全局流转->功能使用->代装终端->全局流转 | J23: 刘兴涛 | K23: 15706307476 | L23: 寒亭区 | M23: 家客铁通潍坊寒亭-城东城区装维组 | N23: 指导用户加固线缆 | O23: dw3_jk_liuxingtao | P23: 2024-07-03 20:46:24 | R23: =IF(OR(LEFT(L23,2)="高新"),"奎文",IF(LEFT(L23,2)="峡山","坊子",IF(LEFT(L23,2)="滨海","寒亭",LEFT(L23,2)))) -> 寒亭 | S23: =TEXT(B23,"mmdd") -> 0703
A24: SD-057-240703-860543-7667 | B24: 2024-07-03 20:41:43 | C24: 潍坊 | D24: 【调研】-80+普通-普通区域-昌乐县-前孔自然村（含前孔、南刘家沟）-18763687627-1000M-宽带上网投诉-次数0-20240703204055X455900115 | E24: 2024-07-04 19:00:00 | F24: 20240703204055X455900115 | G24: 【农村网络投诉】流程受理流水号：20240703203918187636876271198669 客户号码:18763687627 客户姓名:赵** 投诉地市:潍坊 来话流水:2024070320353267320865783 宽带账号:18763687627 宽带账号归属地市:潍坊 宽带账号归属区县:昌乐县 故障地址:潍坊昌乐县鄌郚镇前孔前孔自然村前孔村5#（村东北吴汉亮）********* 联系电话:18706537286 联系人:先生/女士 工单紧急程度:非常紧急 是否有升级投诉倾向:否 是否重复投诉:否 是否携转意向:否 是否投诉倾向:否 是否智能网关:智能网关 当前是否在线:否 接入方式:FTTH 端到端诊断结果:状态正常 是否质差终端:无质差信息 光功率:无 故障大类:宽带/电视 故障细类:宽带无法上网(专席) 携转原因: 故障时间:2024-07-03 20:39:21 具体故障现象:注册灯闪烁，引导客户将光纤线插紧，将弯折的位置捋直后重启无效，请协助处理，谢谢。 客户其他诉求: | H24: 2024-07-03 20:43:25 | I24: 家宽业务->网络质量->家庭宽带->全局流转->功能使用->网络无法连接->全局流转 | J24: 刘志诚 | K24: 15706307122 | L24: 昌乐县 | M24: 家客铁通潍坊昌乐-唐吾乡镇装维组 | N24: 重新熔接皮线 | O24: dw3_jk_liuzhicheng | P24: 2024-07-03 20:47:09 | Q24: SD-851-237769-28867-17713 | R24: =IF(OR(LEFT(L24,2)="高新"),"奎文",IF(LEFT(L24,2)="峡山","坊子",IF(LEFT(L24,2)="滨海","寒亭",LEFT(L24,2)))) -> 昌乐 | S24: =TEXT(B24,"mmdd") -> 0703
A25: SD-057-240703-857264-3420 | B25: 2024-07-03 13:38:05 | C25: 潍坊 | D25: (目标)普通区域-青州市-西水渠-13853644178-300M-宽带上网投诉-次数0-20240703133539X939467998 | E25: 2024-07-04 08:00:00 | F25: 20240703133539X939467998 | G25: 【农村网络投诉】流程受理流水号：20240703133450138536441781094087 客户号码:13853644178 客户姓名:闫** 投诉地市:潍坊 来话流水:2024070313321974820846158 宽带账号:13853644178 宽带账号归属地市:潍坊 宽带账号归属区县:青州市 故障地址:潍坊青州市高柳镇西水渠村西水渠西水渠村12号箱（闫炳河）********* 联系电话:15006685166 联系人:先生/女士 工单紧急程度:紧急 是否有升级投诉倾向:否 是否重复投诉:否 是否携转意向:否 是否投诉倾向:否 是否智能网关:智能网关 当前是否在线:否 接入方式:FTTH 端到端诊断结果:设备告警 是否质差终端:无质差信息 光功率:无 故障大类:宽带/电视 故障细类:宽带无法上网(专席) 携转原因: 故障时间:2024-07-03 13:34:30 具体故障现象:光猫亮红灯，客户表示室外线断了 ，家里不能上网 客户其他诉求: | H25: 2024-07-03 13:41:37 | I25: 家宽业务->网络质量->家庭宽带->全局流转->功能使用->网络无法连接->全局流转 | J25: 李超 | K25: 15706307648 | L25: 青州市 | M25: 家客铁通潍坊青州-高柳乡镇装维组 | N25: 重新连接机顶盒网络 | O25: dw3_jk_weixiaoliang | P25: 2024-07-03 13:42:01 | R25: =IF(OR(LEFT(L25,2)="高新"),"奎文",IF(LEFT(L25,2)="峡山","坊子",IF(LEFT(L25,2)="滨海","寒亭",LEFT(L25,2)))) -> 青州 | S25: =TEXT(B25,"mmdd") -> 0703
A26: SD-057-240703-085762-307 | B26: 2024-07-03 08:39:19 | C26: 潍坊 | D26: 【调研】-80+普通-普通区域-奎文区-帝景苑-15905361026-500M-宽带上网投诉-次数0-202407030000100853 | E26: 2024-07-04 08:00:00 | F26: 202407030000100853 | G26: 202407030000100853#流程受理流水号：20240703083600159053610261002999 客户号码:15905361026 客户姓名:王* 投诉地市:潍坊 来话流水:2024070308350727620841880 宽带账号:15905361026 宽带账号归属地市:潍坊 宽带账号归属区县:奎文区 故障地址:潍坊奎文区广文街道民生东街帝景苑35********* 联系电话:18615088887 联系人:先生/女士 工单紧急程度:紧急 是否有升级投诉倾向:否 是否重复投诉:否 是否携转意向:否 是否投诉倾向:否 是否智能网关:智能网关 当前是否在线:否 接入方式:FTTH 端到端诊断结果:状态正常 是否质差终端:无质差信息 光功率:无 故障大类:宽带/电视 故障细类:宽带无法上网 携转原因: 故障时间:2024-07-03 08:37:56 具体故障现象:光猫亮红灯， 客户其他诉求:要求尽快处理 ;宽带小区$[帝景苑]$ | H26: 2024-07-03 08:50:09 | I26: 家宽咨询->网络质量->家庭宽带->全局流转->功能使用->网络无法连接->全局流转 | J26: 姚克胜 | K26: 15706307480 | L26: 奎文区 | M26: 家客铁通潍坊奎文-樱前街城区装维组 | N26: 更换光猫 | O26: dw3_jk_yaokesheng | P26: 2024-07-03 08:56:03 | Q26: SD-851-285398-20429-7221 | R26: =IF(OR(LEFT(L26,2)="高新"),"奎文",IF(LEFT(L26,2)="峡山","坊子",IF(LEFT(L26,2)="滨海","寒亭",LEFT(L26,2)))) -> 奎文 | S26: =TEXT(B26,"mmdd") -> 0703
A27: SD-057-240703-185734-281 | B27: 2024-07-03 08:37:29 | C27: 潍坊 | D27: 普通区域-寿光市-杨家庄村自然村-15163698310-300M-宽带上网投诉-次数0-202407030000099778 | E27: 2024-07-04 08:00:00 | F27: 202407030000099778 | G27: 202407030000099778#导航立单,客户通过语音导航反馈宽带故障问题,经诊断光猫设备性能不佳,要求装维回访处理,请协助.联系电话：15163698310 | H27: 2024-07-03 08:54:18 | I27: 家庭咨询->网络质量->家庭宽带->全局流转->功能使用->光猫设备故障->全局流转 | J27: 赵坤 | K27: 15706307757 | L27: 寿光市 | M27: 家客铁通潍坊寿光-古城乡镇装维组 | N27: 重新施工布放光缆 | O27: dw3_jk_zhaokun | P27: 2024-07-03 08:57:06 | R27: =IF(OR(LEFT(L27,2)="高新"),"奎文",IF(LEFT(L27,2)="峡山","坊子",IF(LEFT(L27,2)="滨海","寒亭",LEFT(L27,2)))) -> 寿光 | S27: =TEXT(B27,"mmdd") -> 0703
A28: SD-057-240703-045693-6451 | B28: 2024-07-03 19:02:45 | C28: 潍坊 | D28: 普通区域-奎文区-府佑居-19558555993-100M-宽带上网投诉-次数0-20240703190118X478903156 | E28: 2024-07-04 19:00:00 | F28: 20240703190118X478903156 | G28: 流程受理流水号：20240703185954195585559931183092 客户号码:19558555993 客户姓名:张** 投诉地市:潍坊 来话流水:2024070318581418720879651 宽带账号:19558555993 宽带账号归属地市:潍坊 宽带账号归属区县:奎文区 故障地址:潍坊奎文区高新城区金马路府佑居25号楼********* 联系电话:19558555993 联系人:先生/女士 工单紧急程度:一般 是否有升级投诉倾向:否 是否重复投诉:否 是否携转意向:否 是否投诉倾向:否 是否智能网关:智能网关 当前是否在线:是 接入方式:FTTH 端到端诊断结果:客户侧设备问题（新增） 是否质差终端:无质差信息 光功率:-16.02 故障大类:宽带/电视 故障细类:宽带网速慢/卡顿 携转原因: 故障时间:2024-07-03 19:00:38 网站/APP/游戏名称:电脑游戏 具体故障现象:网速慢卡顿， 客户其他诉求: | H28: 2024-07-03 19:06:33 | I28: 家宽业务->网络质量->家庭宽带->全局流转->功能使用->部分视频无法播放->全局流转 | J28: 李先圣 | K28: 15706307393 | L28: 奎文区 | M28: 家客铁通潍坊奎文-健康街城区装维组 | N28: 用户感觉网速慢，但测速达标 | O28: dw3_jk_lixiansheng | P28: 2024-07-03 19:06:58 | Q28: SD-851-302211-9443-10331 | R28: =IF(OR(LEFT(L28,2)="高新"),"奎文",IF(LEFT(L28,2)="峡山","坊子",IF(LEFT(L28,2)="滨海","寒亭",LEFT(L28,2)))) -> 奎文 | S28: =TEXT(B28,"mmdd") -> 0703
A29: SD-057-240703-130278-6806 | B29: 2024-07-03 19:21:50 | C29: 潍坊 | D29: 普通区域-昌邑市-政亨小区3-18866730028-1000M-业务受理宽带-次数0-202407030000673728 | E29: 2024-07-04 18:00:00 | F29: 202407030000673728 | G29: 202407030000673728#导航立单,用户所在位置有群障,已向客户播报,客户要求装维回访.此工单为群障修复工单,根据群障全量闭环管理要求,为确保客户网络通畅,请装维人员跟进修复网络问题,谢谢.联系电话：18866730028 | H29: 2024-07-03 19:40:57 | I29: 业务受理->线上义诊->家庭业务->全局流转->功能使用->群障弹窗->全局流转 | J29: 徐瑞鹏 | K29: 15706307210 | L29: 昌邑市 | M29: 家客铁通潍坊昌邑-柳疃乡镇装维组 | N29: 更换皮线或网线 | O29: dw3_jk_xuruipeng | P29: 2024-07-03 19:41:40 | Q29: SD-851-267886-3747-7240 | R29: =IF(OR(LEFT(L29,2)="高新"),"奎文",IF(LEFT(L29,2)="峡山","坊子",IF(LEFT(L29,2)="滨海","寒亭",LEFT(L29,2)))) -> 昌邑 | S29: =TEXT(B29,"mmdd") -> 0703
